Workbook

Sheet Instructions
B1: Tasks
A3: 1. | B3: Generate a random sample of 5000 values drawn from an Exponential random variable, X with parameter, l = 0.2. (a) Calculate the sample mean and standard deviation of X. Comment on your answers. (b) What values would you expect for the sample mean and standard deviation if l was increased to 0.25?
A5: 2. | B5: Produce a histogram of the data generated in task 1. Comment on its shape in worksheet Task 2.
A7: 3. | B7: Use the data from task 1 to estimate the probabilities P(X > x + h | X > x) and P(X > h) for three pairs of non-negative values of x and h of your choice. For each pair of values compare the conditional and unconditional probabilites. Explain your findings in worksheet Task 3.
A9: 4. | B9: Examine the effect of traffic intensity, by showing that as the service rate approaches the arrival rate, the expected time in the queue appears to increase without bound
B11: a. Complete the data table in worksheet Task 4a.
B12: b. Vary the arrival and service rates, and give a brief summary of your findings in worksheet Task 4b.
A14: 5. | B14: Would you rather go to a system with one fast server or a system with several slow servers?
B15: This question is addressed using the Task 5 worksheet. We consider two equivalent models
B16: in the sense that the traffic intensity, defined by r =l/ (sm), is exactly the same.
B17: Compare the summary measures for the two systems and decide under which conditions a customer would prefer a fast single server system to a system with multiple slow servers.

Sheet Task 1
B2: l | C2: 0.25 | E2: Sample mean | F2: =IFERROR(AVERAGE(C7:C5006),"Not defined") -> 3.9069381 | M2: minimum | N2: =MIN(C7:C5006) -> 0.001158793
E4: Sample SD | F4: =IFERROR(_xlfn.STDEV.S(C7:C5006),"Not defined") -> 3.9218815 | M4: maximum | N4: =MAX(C7:C5006) -> 34.628901
C6: Sample values
B7: 1 | C7: =-(1/$C$2)*LN(RAND()) -> 11.290836 | E7: The sample mean and sample standard deviation are almost equal. This is to be expected as the mean and standard deviation of an Exponential variable are known to be equal. Also, they are close to the value of the reciprocal of lambda. Again, this is to be expected as it is a property of the Exponential.
B8: =B7+1 -> 2 | C8: =-(1/$C$2)*LN(RAND()) -> 0.3058987
B9: =B8+1 -> 3 | C9: =-(1/$C$2)*LN(RAND()) -> 4.5808168
B10: =B9+1 -> 4 | C10: =-(1/$C$2)*LN(RAND()) -> 1.8525109
B11: =B10+1 -> 5 | C11: =-(1/$C$2)*LN(RAND()) -> 0.73203145
B12: =B11+1 -> 6 | C12: =-(1/$C$2)*LN(RAND()) -> 0.18906782
B13: =B12+1 -> 7 | C13: =-(1/$C$2)*LN(RAND()) -> 1.2752504
B14: =B13+1 -> 8 | C14: =-(1/$C$2)*LN(RAND()) -> 4.8711269 | E14: If l is 0.25, then we expect the mean and standard deviation to be close to the reciprocal of l, 4. You can easily check this by setting the value of l in cell C2 to 0.25
B15: =B14+1 -> 9 | C15: =-(1/$C$2)*LN(RAND()) -> 0.9580335
B16: =B15+1 -> 10 | C16: =-(1/$C$2)*LN(RAND()) -> 1.3315462
B17: =B16+1 -> 11 | C17: =-(1/$C$2)*LN(RAND()) -> 4.7727127
B18: =B17+1 -> 12 | C18: =-(1/$C$2)*LN(RAND()) -> 5.6887634
B19: =B18+1 -> 13 | C19: =-(1/$C$2)*LN(RAND()) -> 0.37275274
B20: =B19+1 -> 14 | C20: =-(1/$C$2)*LN(RAND()) -> 1.0894319
B21: =B20+1 -> 15 | C21: =-(1/$C$2)*LN(RAND()) -> 3.9301695
B22: =B21+1 -> 16 | C22: =-(1/$C$2)*LN(RAND()) -> 1.2420634
B23: =B22+1 -> 17 | C23: =-(1/$C$2)*LN(RAND()) -> 1.2435626
B24: =B23+1 -> 18 | C24: =-(1/$C$2)*LN(RAND()) -> 1.4224173
B25: =B24+1 -> 19 | C25: =-(1/$C$2)*LN(RAND()) -> 2.5273591
B26: =B25+1 -> 20 | C26: =-(1/$C$2)*LN(RAND()) -> 0.12269062
... B5006: =B5005+1 -> 5000 | C5006: =-(1/$C$2)*LN(RAND()) -> 0.59187575

Sheet Task 2
B2: Bin | C2: Bin | D2: Frequency
B3: 2 | D3: {=FREQUENCY('Task 1'!C7:C5006,'Task 2'!B3:B22)} -> 2049
B4: =B3+2 -> 4 | D4: 1144
B5: =B4+2 -> 6 | D5: 722
B6: =B5+2 -> 8 | D6: 437 | O6: We expect to see the histogram decaying exponentially,* with a long tail to the right. Because a histogram is based on intervals (defined by the right-hand endpoints of the bins) the distribution appears as a "step function." This is an approximation to the continuous curve we expect to see for a continuous random variable.
B7: =B6+2 -> 10 | D7: 251
B8: =B7+2 -> 12 | D8: 138
B9: =B8+2 -> 14 | D9: 112
B10: =B9+2 -> 16 | D10: 68
B11: =B10+2 -> 18 | D11: 37 | O11: * | P11: Exponential decay means that the value decreases by a fixed proportion of the value. In other words, the curve decreases more sharply to begin with, and the amount of decrease becomes less and less as we move further along the curve.
B12: =B11+2 -> 20 | D12: 15
B13: =B12+2 -> 22 | D13: 15
B14: =B13+2 -> 24 | D14: 5
B15: =B14+2 -> 26 | D15: 2
B16: =B15+2 -> 28 | D16: 2
B17: =B16+2 -> 30 | D17: 1
B18: 32 | D18: 1
B19: 34 | D19: 0
B20: 36 | D20: 1
B21: =B20+2 -> 38 | D21: 0
B22: =B21+2 -> 40 | D22: 0 | E22: Exponential distribution, f(x)
B23: more | D23: 0
E24: 0.2
D27: 20 | E27: f(x) | F27: Magnitude of the change in f(x) in a small interval of time (0.1), divided by f(x), is constant
D28: 22 | E28: =E$24*EXP(-E$24*D28) -> 0.002455468
D29: 24 | E29: =E$24*EXP(-E$24*D29) -> 0.0016459494 | F29: =((E28-E29)/(D29-D28))/E28 -> 0.16483998
D30: 26 | E30: =E$24*EXP(-E$24*D30) -> 0.0011033129 | F30: =((E29-E30)/(D30-D29))/E29 -> 0.16483998
D31: 28 | E31: =E$24*EXP(-E$24*D31) -> 0.00073957274 | F31: =((E30-E31)/(D31-D30))/E30 -> 0.16483998
D32: 30 | E32: =E$24*EXP(-E$24*D32) -> 0.00049575044 | F32: =((E31-E32)/(D32-D31))/E31 -> 0.16483998
D33: =D32+0.1 -> 30.1 | E33: =E$24*EXP(-E$24*D33) -> 0.00048593392 | F33: =((E32-E33)/(D33-D32))/E32 -> 0.19801327
D34: =D33+0.1 -> 30.2 | E34: =E$24*EXP(-E$24*D34) -> 0.00047631178 | F34: =((E33-E34)/(D34-D33))/E33 -> 0.19801327
D35: =D34+0.1 -> 30.3 | E35: =E$24*EXP(-E$24*D35) -> 0.00046688018 | F35: =((E34-E35)/(D35-D34))/E34 -> 0.19801327
D36: =D35+0.1 -> 30.4 | E36: =E$24*EXP(-E$24*D36) -> 0.00045763533 | F36: =((E35-E36)/(D36-D35))/E35 -> 0.19801327
D37: =D36+0.1 -> 30.5 | E37: =E$24*EXP(-E$24*D37) -> 0.00044857354 | F37: =((E36-E37)/(D37-D36))/E36 -> 0.19801327
D38: =D37+0.1 -> 30.6 | E38: =E$24*EXP(-E$24*D38) -> 0.00043969119 | F38: =((E37-E38)/(D38-D37))/E37 -> 0.19801327
D39: =D38+0.1 -> 30.7 | E39: =E$24*EXP(-E$24*D39) -> 0.00043098472 | F39: =((E38-E39)/(D39-D38))/E38 -> 0.19801327
D40: =D39+0.1 -> 30.8 | E40: =E$24*EXP(-E$24*D40) -> 0.00042245065 | F40: =((E39-E40)/(D40-D39))/E39 -> 0.19801327
D41: =D40+0.1 -> 30.9 | E41: =E$24*EXP(-E$24*D41) -> 0.00041408557 | F41: =((E40-E41)/(D41-D40))/E40 -> 0.19801327
D42: =D41+0.1 -> 31 | E42: =E$24*EXP(-E$24*D42) -> 0.00040588613 | F42: =((E41-E42)/(D42-D41))/E41 -> 0.19801327
D43: =D42+0.1 -> 31.1 | E43: =E$24*EXP(-E$24*D43) -> 0.00039784904 | F43: =((E42-E43)/(D43-D42))/E42 -> 0.19801327
...

Sheet Task 3
B2: The table below illustrates the memoryless property of the Exponential distribution
B5: x | C5: h | D5: Pr(X > x + h| X > x) | E5: Pr(X > h)
B6: 0 | C6: 3 | D6: =COUNTIF('Task 1'!$C$7:$C$5006,">"&(B6+C6))/COUNTIF('Task 1'!$C$7:$C$5006,">"&B6) -> 0.458 | E6: =COUNTIF('Task 1'!$C$7:$C$5006,">"&C6)/5000 -> 0.458 | G6: =COUNTIF('Task 1'!$C$7:$C$5006,">"&(B6+C6)) -> 2290 | H6: =COUNTIF('Task 1'!$C$7:$C$5006,">"&B6) -> 5000 | I6: =G6/H6 -> 0.458
B7: 1 | C7: 3 | D7: =COUNTIF('Task 1'!$C$7:$C$5006,">"&(B7+C7))/COUNTIF('Task 1'!$C$7:$C$5006,">"&B7) -> 0.46813472 | E7: =COUNTIF('Task 1'!$C$7:$C$5006,">"&C7)/5000 -> 0.458 | G7: =COUNTIF('Task 1'!$C$7:$C$5006,">"&(B7+C7)) -> 1807 | H7: =COUNTIF('Task 1'!$C$7:$C$5006,">"&B7) -> 3860 | I7: =G7/H7 -> 0.46813472
B8: 2 | C8: 3 | D8: =COUNTIF('Task 1'!$C$7:$C$5006,">"&(B8+C8))/COUNTIF('Task 1'!$C$7:$C$5006,">"&B8) -> 0.47848187 | E8: =COUNTIF('Task 1'!$C$7:$C$5006,">"&C8)/5000 -> 0.458 | G8: =COUNTIF('Task 1'!$C$7:$C$5006,">"&(B8+C8)) -> 1412 | H8: =COUNTIF('Task 1'!$C$7:$C$5006,">"&B8) -> 2951 | I8: =G8/H8 -> 0.47848187
B10: For any pair (x, h) we observe that the estimated conditional and unconditional probabilities are much the same. This is simply a reflection of the memoryless property.
B14: Suppose that service time has an Exponential distribution, and imagine that you are currently being served. Then the probability that the service continues for at least another h minutes is the same, irrespective of how long the service has already taken

Sheet Task 4a
A1: M/M/1 queue
E2: The table and chart show that as the service rate approaches to arrival rate, the expected time in the queue appears to increase without bound | AD2: =60/2 -> 30
A3: Inputs (customers/minute) | AD3: =60/1.5 -> 40
A4: Arrival rate, l | B4: 0.5
A5: Service rate, m | B5: 0.5
A7: Outputs
A8: Mean time between arrivals =1/λ | B8: =1/B4 -> 2
A9: Mean time per service =1/µ | B9: =1/B5 -> 2
A10: Traffic intensity, r =λ/µ | B10: =B9/B8 -> 1
A12: Summary measures
A13: Expected no. customers in system, L [ L = ρ/(1-ρ) ] | B13: =B10/(1-B10) -> #DIV/0!
A14: Expected no. of customers in queue, LQ [Lq = λ * WQ] | B14: =B4*B16 -> #DIV/0!
A15: Expected time in system (in minutes), W (W = L / λ) | B15: =B13/B4 -> #DIV/0!
A16: Expected time in queue (in minutes), WQ | B16: =B15-1/B5 -> #DIV/0!
A17: Server utilisation, U | B17: =B10 -> 1
E19: Distribution of number of customers, n in the system | H19: Data table for expected time in queue by service rate | K19: Distribution of time, t (in minutes) in queue*
E21: n | F21: Pr(n in system) | H21: Service rate | I21: Queue time | K21: t | L21: Pr(wait > t)
E22: 0 | F22: =(1-$B$10)*$B$10^E22 -> 0 | I22: =B16 -> #DIV/0! | K22: 2 | L22: =$B$10*EXP(-$B$5*(1-$B$10)*K22) -> 1
E23: =E22+1 -> 1 | F23: =(1-$B$10)*$B$10^E23 -> 0 | H23: 0.505 | I23: 198.0198
E24: =E23+1 -> 2 | F24: =(1-$B$10)*$B$10^E24 -> 0 | H24: =H23+0.005 -> 0.51 | I24: 98.039216 | K24: *Formula is given in Text p. 681: Pr(Time in queue > t) = 1-re-m(1-r)t.
E25: =E24+1 -> 3 | F25: =(1-$B$10)*$B$10^E25 -> 0 | H25: =H24+0.005 -> 0.515 | I25: 64.724919
E26: =E25+1 -> 4 | F26: =(1-$B$10)*$B$10^E26 -> 0 | H26: =H25+0.005 -> 0.52 | I26: 48.076923
E27: =E26+1 -> 5 | F27: =(1-$B$10)*$B$10^E27 -> 0 | H27: =H26+0.005 -> 0.525 | I27: 38.095238
E28: =E27+1 -> 6 | F28: =(1-$B$10)*$B$10^E28 -> 0 | H28: =H27+0.005 -> 0.53 | I28: 31.446541
E29: =E28+1 -> 7 | F29: =(1-$B$10)*$B$10^E29 -> 0 | H29: =H28+0.005 -> 0.535 | I29: 26.70227
E30: =E29+1 -> 8 | F30: =(1-$B$10)*$B$10^E30 -> 0 | H30: =H29+0.005 -> 0.54 | I30: 23.148148
E31: =E30+1 -> 9 | F31: =(1-$B$10)*$B$10^E31 -> 0 | H31: =H30+0.005 -> 0.545 | I31: 20.38736
E32: =E31+1 -> 10 | F32: =(1-$B$10)*$B$10^E32 -> 0 | H32: =H31+0.005 -> 0.55 | I32: 18.181818
E33: =E32+1 -> 11 | F33: =(1-$B$10)*$B$10^E33 -> 0 | H33: =H32+0.005 -> 0.555 | I33: 16.380016
E34: =E33+1 -> 12 | F34: =(1-$B$10)*$B$10^E34 -> 0 | H34: =H33+0.005 -> 0.56 | I34: 14.880952
E35: =E34+1 -> 13 | F35: =(1-$B$10)*$B$10^E35 -> 0 | H35: =H34+0.005 -> 0.565 | I35: 13.614704
E36: =E35+1 -> 14 | F36: =(1-$B$10)*$B$10^E36 -> 0 | H36: =H35+0.005 -> 0.57 | I36: 12.531328
... E42: =E41+1 -> 20 | F42: =(1-$B$10)*$B$10^E42 -> 0 | H42: =H41+0.005 -> 0.6 | I42: 8.3333333
E43: =E42+1 -> 21 | F43: =(1-$B$10)*$B$10^E43 -> 0
E44: =E43+1 -> 22 | F44: =(1-$B$10)*$B$10^E44 -> 0

Sheet Task 4b
A1: M/M/1 queue
A3: Inputs (customers/minute) | B3: Defined
A4: Arrival rate, l | B4: 0.5 | O4: By varying the service rate, and letting it approach the arrival rate from above, the expected time in the queue appears to increase without bound. For example, fixing the arrival rate at 0.5, and decreasing the service rate, the chart shows that the average time arrivals spend in the system increase, and the spikes, where some customers wait much longer than the rest get larger and larger. When the service rate equals 0.5 we can see a dramatic change in behaviour, depending on the estimated mean time between arrivals and mean time per service. If the estimated average time between arrivals exceeds the estimated average time per service by a small amount, the chart shows long sojourns away from zero over time but a tendency to eventually return over and over to near zero wait time. But if the estimated average time between arrivals is less than or equal to the estimated average time per service, the chart shows a rapid growth in the length of the queue, with no sign that it will return to near zero.
A5: Service rate, m | B5: =0.45 -> 0.45
A7: Outputs | C7: Estimated*
A8: Mean time between arrivals =1/λ | B8: =1/B4 -> 2 | C8: =AVERAGE(F$28:F$5027) -> 2.0068637
A9: Mean time per service =1/µ | B9: =1/B5 -> 2.2222222 | C9: =AVERAGE(I$28:I$5027) -> 2.2692532
A10: Traffic intensity, r =λ/µ | B10: =B9/B8 -> 1.1111111 | C10: =C9/C8 -> 1.130746
A12: Summary measures | C12: Estimated
A13: Expected no. customers in system, L | B13: =IFERROR(B10/(1-B10),"Not defined") -> -10 | C13: =AVERAGE(Q$28:Q$5027) -> 316.9884
A14: Expected no. of customers in queue, LQ | B14: =IFERROR(B4*B17,"Not defined") -> -11.111111 | C14: =C13-C15 -> 315.9942
A15: Expected no. in service, LS | B15: =IFERROR(B13-B14,"Not defined") -> 1.1111111 | C15: =AVERAGE(P$28:P$5027) -> 0.9942
A16: Expected time in system (in minutes), W | B16: =IFERROR(B13/B4,"Not defined") -> -20 | C16: =AVERAGE(M$28:M$5027) -> 722.94955
A17: Expected time in queue (in minutes), WQ | B17: =IFERROR(B16-1/B5,"Not defined") -> -22.222222 | C17: =C16-AVERAGE(I$28:I$5027) -> 720.6803
A18: Server utilisation,** U | B18: =B10 -> 1.1111111 | C18: =COUNTIF(P$28:P$5027,">0")/5000 -> 0.9942
A20: *Estimates are derived from the simulation data below (n = 5,000)
A22: **Note: for an M/M/1 queue, server utilisation is always the same as the expected number in service
F25: Inter-arrival times | G25: Actual arrival times | L25: No. left in queue when service ends | M25: Time this arrival was in system
I26: Service times | J26: Service time starts | K26: Service time ends | O26: Random times | P26: No. in | Q26: No. in
H27: Arrival # | P27: service | Q27: system
E28: 1 | F28: =-(1/B$4)*LN(RAND()) -> 4.8804117 | G28: =F28 -> 4.8804117 | H28: =E28 -> 1 | I28: =-(1/B$5)*LN(RAND()) -> 1.8803502 | J28: =G28 -> 4.8804117 | K28: =J28+I28 -> 6.7607619 | L28: =COUNTIF(G$28:G$5027,"<"&K28)-H28 -> 2 | M28: =K28-G28 -> 1.8803502 | O28: =K$5027*RAND() -> 5314.4715 | P28: =COUNTIF(J$28:J$5027,"<"&O28)-COUNTIF(K$28:K$5027,"<"&O28) -> 1 | Q28: =COUNTIF(G$28:G$5027,"<"&O28)-COUNTIF(K$28:K$5027,"<"&O28) -> 316
E29: =E28+1 -> 2 | F29: =-(1/B$4)*LN(RAND()) -> 1.2740415 | G29: =G28+F29 -> 6.1544532 | H29: =E29 -> 2 | I29: =-(1/B$5)*LN(RAND()) -> 2.3401435 | J29: =MAX(G29,K28) -> 6.7607619 | K29: =J29+I29 -> 9.1009054 | L29: =COUNTIF(G$28:G$5027,"<"&K29)-H29 -> 5 | M29: =K29-G29 -> 2.9464522 | O29: =K$5027*RAND() -> 3111.1033 | P29: =COUNTIF(J$28:J$5027,"<"&O29)-COUNTIF(K$28:K$5027,"<"&O29) -> 1 | Q29: =COUNTIF(G$28:G$5027,"<"&O29)-COUNTIF(K$28:K$5027,"<"&O29) -> 239
E30: =E29+1 -> 3 | F30: =-(1/B$4)*LN(RAND()) -> 0.33777515 | G30: =G29+F30 -> 6.4922283 | H30: =E30 -> 3 | I30: =-(1/B$5)*LN(RAND()) -> 1.5384945 | J30: =MAX(G30,K29) -> 9.1009054 | K30: =J30+I30 -> 10.6394 | L30: =COUNTIF(G$28:G$5027,"<"&K30)-H30 -> 4 | M30: =K30-G30 -> 4.1471715 | O30: =K$5027*RAND() -> 3021.4297 | P30: =COUNTIF(J$28:J$5027,"<"&O30)-COUNTIF(K$28:K$5027,"<"&O30) -> 1 | Q30: =COUNTIF(G$28:G$5027,"<"&O30)-COUNTIF(K$28:K$5027,"<"&O30) -> 229
E31: =E30+1 -> 4 | F31: =-(1/B$4)*LN(RAND()) -> 0.56219951 | G31: =G30+F31 -> 7.0544278 | H31: =E31 -> 4 | I31: =-(1/B$5)*LN(RAND()) -> 8.1592989 | J31: =MAX(G31,K30) -> 10.6394 | K31: =J31+I31 -> 18.798699 | L31: =COUNTIF(G$28:G$5027,"<"&K31)-H31 -> 6 | M31: =K31-G31 -> 11.744271 | O31: =K$5027*RAND() -> 1850.9658 | P31: =COUNTIF(J$28:J$5027,"<"&O31)-COUNTIF(K$28:K$5027,"<"&O31) -> 1 | Q31: =COUNTIF(G$28:G$5027,"<"&O31)-COUNTIF(K$28:K$5027,"<"&O31) -> 132
E32: =E31+1 -> 5 | F32: =-(1/B$4)*LN(RAND()) -> 0.77180566 | G32: =G31+F32 -> 7.8262335 | H32: =E32 -> 5 | I32: =-(1/B$5)*LN(RAND()) -> 0.95322265 | J32: =MAX(G32,K31) -> 18.798699 | K32: =J32+I32 -> 19.751921 | L32: =COUNTIF(G$28:G$5027,"<"&K32)-H32 -> 5 | M32: =K32-G32 -> 11.925688 | O32: =K$5027*RAND() -> 11217.724 | P32: =COUNTIF(J$28:J$5027,"<"&O32)-COUNTIF(K$28:K$5027,"<"&O32) -> 1 | Q32: =COUNTIF(G$28:G$5027,"<"&O32)-COUNTIF(K$28:K$5027,"<"&O32) -> 61
E33: =E32+1 -> 6 | F33: =-(1/B$4)*LN(RAND()) -> 0.02358869 | G33: =G32+F33 -> 7.8498222 | H33: =E33 -> 6 | I33: =-(1/B$5)*LN(RAND()) -> 0.24874863 | J33: =MAX(G33,K32) -> 19.751921 | K33: =J33+I33 -> 20.00067 | L33: =COUNTIF(G$28:G$5027,"<"&K33)-H33 -> 4 | M33: =K33-G33 -> 12.150848 | O33: =K$5027*RAND() -> 8323.9546 | P33: =COUNTIF(J$28:J$5027,"<"&O33)-COUNTIF(K$28:K$5027,"<"&O33) -> 1 | Q33: =COUNTIF(G$28:G$5027,"<"&O33)-COUNTIF(K$28:K$5027,"<"&O33) -> 538
E34: =E33+1 -> 7 | F34: =-(1/B$4)*LN(RAND()) -> 0.24403294 | G34: =G33+F34 -> 8.0938551 | H34: =E34 -> 7 | I34: =-(1/B$5)*LN(RAND()) -> 0.18786496 | J34: =MAX(G34,K33) -> 20.00067 | K34: =J34+I34 -> 20.188535 | L34: =COUNTIF(G$28:G$5027,"<"&K34)-H34 -> 3 | M34: =K34-G34 -> 12.09468 | O34: =K$5027*RAND() -> 5218.31 | P34: =COUNTIF(J$28:J$5027,"<"&O34)-COUNTIF(K$28:K$5027,"<"&O34) -> 1 | Q34: =COUNTIF(G$28:G$5027,"<"&O34)-COUNTIF(K$28:K$5027,"<"&O34) -> 334
E35: =E34+1 -> 8 | F35: =-(1/B$4)*LN(RAND()) -> 2.9157994 | G35: =G34+F35 -> 11.009655 | H35: =E35 -> 8 | I35: =-(1/B$5)*LN(RAND()) -> 0.2118018 | J35: =MAX(G35,K34) -> 20.188535 | K35: =J35+I35 -> 20.400337 | L35: =COUNTIF(G$28:G$5027,"<"&K35)-H35 -> 2 | M35: =K35-G35 -> 9.3906822 | O35: =K$5027*RAND() -> 6562.653 | P35: =COUNTIF(J$28:J$5027,"<"&O35)-COUNTIF(K$28:K$5027,"<"&O35) -> 1 | Q35: =COUNTIF(G$28:G$5027,"<"&O35)-COUNTIF(K$28:K$5027,"<"&O35) -> 393
E36: =E35+1 -> 9 | F36: =-(1/B$4)*LN(RAND()) -> 1.1703428 | G36: =G35+F36 -> 12.179997 | H36: =E36 -> 9 | I36: =-(1/B$5)*LN(RAND()) -> 3.7849481 | J36: =MAX(G36,K35) -> 20.400337 | K36: =J36+I36 -> 24.185285 | L36: =COUNTIF(G$28:G$5027,"<"&K36)-H36 -> 3 | M36: =K36-G36 -> 12.005288 | O36: =K$5027*RAND() -> 167.23818 | P36: =COUNTIF(J$28:J$5027,"<"&O36)-COUNTIF(K$28:K$5027,"<"&O36) -> 0 | Q36: =COUNTIF(G$28:G$5027,"<"&O36)-COUNTIF(K$28:K$5027,"<"&O36) -> 0
E37: =E36+1 -> 10 | F37: =-(1/B$4)*LN(RAND()) -> 0.41502534 | G37: =G36+F37 -> 12.595023 | H37: =E37 -> 10 | I37: =-(1/B$5)*LN(RAND()) -> 1.2367272 | J37: =MAX(G37,K36) -> 24.185285 | K37: =J37+I37 -> 25.422012 | L37: =COUNTIF(G$28:G$5027,"<"&K37)-H37 -> 2 | M37: =K37-G37 -> 12.826989 | O37: =K$5027*RAND() -> 6163.4043 | P37: =COUNTIF(J$28:J$5027,"<"&O37)-COUNTIF(K$28:K$5027,"<"&O37) -> 1 | Q37: =COUNTIF(G$28:G$5027,"<"&O37)-COUNTIF(K$28:K$5027,"<"&O37) -> 379
E38: =E37+1 -> 11 | F38: =-(1/B$4)*LN(RAND()) -> 9.4748748 | G38: =G37+F38 -> 22.069897 | H38: =E38 -> 11 | I38: =-(1/B$5)*LN(RAND()) -> 2.066755 | J38: =MAX(G38,K37) -> 25.422012 | K38: =J38+I38 -> 27.488767 | L38: =COUNTIF(G$28:G$5027,"<"&K38)-H38 -> 1 | M38: =K38-G38 -> 5.4188696 | O38: =K$5027*RAND() -> 9381.068 | P38: =COUNTIF(J$28:J$5027,"<"&O38)-COUNTIF(K$28:K$5027,"<"&O38) -> 1 | Q38: =COUNTIF(G$28:G$5027,"<"&O38)-COUNTIF(K$28:K$5027,"<"&O38) -> 570
E39: =E38+1 -> 12 | F39: =-(1/B$4)*LN(RAND()) -> 0.95616219 | G39: =G38+F39 -> 23.02606 | H39: =E39 -> 12 | I39: =-(1/B$5)*LN(RAND()) -> 0.071600852 | J39: =MAX(G39,K38) -> 27.488767 | K39: =J39+I39 -> 27.560368 | L39: =COUNTIF(G$28:G$5027,"<"&K39)-H39 -> 0 | M39: =K39-G39 -> 4.5343082 | O39: =K$5027*RAND() -> 4168.6355 | P39: =COUNTIF(J$28:J$5027,"<"&O39)-COUNTIF(K$28:K$5027,"<"&O39) -> 1 | Q39: =COUNTIF(G$28:G$5027,"<"&O39)-COUNTIF(K$28:K$5027,"<"&O39) -> 318
E40: =E39+1 -> 13 | F40: =-(1/B$4)*LN(RAND()) -> 6.5747514 | G40: =G39+F40 -> 29.600811 | H40: =E40 -> 13 | I40: =-(1/B$5)*LN(RAND()) -> 1.8364837 | J40: =MAX(G40,K39) -> 29.600811 | K40: =J40+I40 -> 31.437295 | L40: =COUNTIF(G$28:G$5027,"<"&K40)-H40 -> 0 | M40: =K40-G40 -> 1.8364837 | O40: =K$5027*RAND() -> 9838.9821 | P40: =COUNTIF(J$28:J$5027,"<"&O40)-COUNTIF(K$28:K$5027,"<"&O40) -> 1 | Q40: =COUNTIF(G$28:G$5027,"<"&O40)-COUNTIF(K$28:K$5027,"<"&O40) -> 569
... E5027: =E5026+1 -> 5000 | F5027: =-(1/B$4)*LN(RAND()) -> 0.1936375 | G5027: =G5026+F5027 -> 10034.319 | H5027: =E5027 -> 5000 | I5027: =-(1/B$5)*LN(RAND()) -> 1.8592676 | J5027: =MAX(G5027,K5026) -> 11395.187 | K5027: =J5027+I5027 -> 11397.047 | L5027: =COUNTIF(G$28:G$5027,"<"&K5027)-H5027 -> 0 | M5027: =K5027-G5027 -> 1362.728 | O5027: =K$5027*RAND() -> 8549.8502 | P5027: =COUNTIF(J$28:J$5027,"<"&O5027)-COUNTIF(K$28:K$5027,"<"&O5027) -> 1 | Q5027: =COUNTIF(G$28:G$5027,"<"&O5027)-COUNTIF(K$28:K$5027,"<"&O5027) -> 527

Sheet Task 5
A1: M/M/1 queue | D1: M/M/5 queue*
A3: Inputs (customers/hour) | D3: Inputs (customers/hour)
A4: Arrival rate, l | B4: 25 | D4: Arrival rate, l | E4: 25 | G4: Comparison
A5: Service rate, m | B5: 30 | D5: Service rate, m | E5: 6 | G5: M/M/1 has a smaller L
G6: M/M/1 has a larger LQ
A7: Outputs | D7: Outputs | G7: M/M/1 has a smaller W
A8: Mean time between arrivals (in hours) | B8: =1/B4 -> 0.04 | D8: Mean time between arrivals (in hours) | E8: =1/E4 -> 0.04 | G8: M/M/1 has a larger WQ
A9: Mean time per service (in hours) | B9: =1/B5 -> 0.033333333 | D9: Mean time per service (in hours) | E9: =1/E5 -> 0.16666667 | G9: M/M/1 has a smaller percentage of customers who don't have to wait for service (16.7% vs 38.0%)
A10: Traffic intensity, r | B10: =B9/B8 -> 0.83333333 | D10: Traffic intensity, r | E10: =E4/(5*E5) -> 0.83333333
A12: Summary measures | D12: Summary measures
A13: Pr(System is empty) | B13: =(1-B10) -> 0.16666667 | D13: Pr(System is empty) | E13: =(1+((5*E10)+((5*E10)^2)/2+((5*E10)^3)/6+((5*E10)^4)/24)+((5*E10)^5)/(120*(1-E10)))^(-1) -> 0.0098759976
A14: Pr(Server is busy) | B14: =1-B13 -> 0.83333333 | D14: Pr(All servers are busy) | E14: =((5*E10)^5)*E13/(120*(1-E10)) -> 0.62014717
A15: Expected no. customers in system, L | B15: =B10/(1-B10) -> 5 | D15: Expected no. customers in system, L | E15: =E4*E17 -> 7.2674025
A16: Expected no. of customers in queue, LQ | B16: =B4*B18 -> 4.1666667 | D16: Expected no. of customers in queue, LQ | E16: =E14*(E10/(1-E10)) -> 3.1007359
A17: Expected time in system (in hours), W | B17: =B15/B4 -> 0.2 | D17: Expected time in system (in hours), W | E17: =E18+E9 -> 0.2906961
A18: Expected time in queue (in hours), WQ | B18: =B17-1/B5 -> 0.16666667 | C18: =B17-B18 -> 0.033333333 | D18: Expected time in queue (in hours), WQ | E18: =E16/E4 -> 0.12402943
A19: Server utilisation, U | B19: =B10 -> 0.83333333
A20: Percentage who don't wait in queue** | B20: =1-B14 -> 0.16666667 | D20: Percentage who don't wait in queue** | E20: =1-E14 -> 0.37985283
D21: *Formulas are given on p. 685 of textbook
D22: **A customer can enter service immediately, i.e., doesn't have to wait, only if not all servers are busy when they arrive.
A24: =60/25 -> 2.4

Sheet class example
A1: M/M/1 queue
A3: Inputs (customers/minute)
A4: Arrival rate, l | B4: 0.95
A5: Service rate, m | B5: 1
A7: Outputs
A8: Mean time between arrivals | B8: =1/B4 -> 1.0526316 | D8: 1.3333333
A9: Mean time per service | B9: =1/B5 -> 1 | D9: 1
A10: Traffic intensity, r | B10: =B4/B5 -> 0.95 | D10: 0.75
A12: Summary measures
A13: Expected no. customers in system, L | B13: =B10/(1-B10) -> 19 | D13: 3
A14: Expected no. of customers in queue, LQ | B14: =B4*B16 -> 18.05 | D14: 2.25
A15: Expected time in system (in minutes), W | B15: =B13/B4 -> 20 | D15: 4
A16: Expected time in queue (in minutes), WQ | B16: =B15-1/B5 -> 19 | D16: 3
A17: Server utilisation, U | B17: =B10 -> 0.95 | D17: 0.75
