Workbook
Name Contribution_margin_per_unit: [1]Model!$C$4
Name Contribution_margin_per_unit: [1]Model!$C$4
Name Contribution_margin_per_unit: [1]Model!$C$4
Name Contribution_margin_per_unit: [1]Model!$C$4
Name Contribution_margin_per_unit: Model!$C$4
Name Cost_of_parts_per_unit: [1]Model!$H$5
Name Cost_of_parts_per_unit: [1]Model!$H$5
Name Cost_of_parts_per_unit: [1]Model!$H$5
Name Cost_of_parts_per_unit: [1]Model!$H$5
Name Cost_of_parts_per_unit: Model!$H$5
Name Demand: [1]Model!$H$6
Name Demand: [1]Model!$H$6
Name Demand: [1]Model!$H$6
Name Demand: [1]Model!$H$6
Name Demand: Model!$H$6
Name Direct_labour_cost_per_unit: [1]Model!$H$4
Name Direct_labour_cost_per_unit: [1]Model!$H$4
Name Direct_labour_cost_per_unit: [1]Model!$H$4
Name Direct_labour_cost_per_unit: [1]Model!$H$4
Name Direct_labour_cost_per_unit: Model!$H$4
Name First_year_profit: [1]Model!$C$6
Name First_year_profit: [1]Model!$C$6
Name First_year_profit: [1]Model!$C$6
Name First_year_profit: [1]Model!$C$6
Name First_year_profit: Model!$C$6
Name Selling_price_per_unit: [1]Model!$H$10
Name Selling_price_per_unit: [1]Model!$H$10
Name Selling_price_per_unit: [1]Model!$H$10
Name Selling_price_per_unit: [1]Model!$H$10
Name Selling_price_per_unit: Model!$H$10

Sheet Instructions
B2: Tasks
B4: The purpose of this seminar is to run many simulations trials (i.e. replications) so we can analyse the output
B5: and perform a risk analysis.
B7: (Note that you should not expect to get exactly the same answers to those given in the Solutions spreadsheet.)
A9: 1a | B9: Using the Data Table, simulate 1,000 replications of the variables listed in the table in columns B:G of the Simulated Output worksheet. Then do the same for columns N:S.
B12: Creating a data table for columns B:G
B13: Step 1: Set each of the cells C5:G5 equal to the corresponding cell in the Model worksheet
B14: Step 2: Select the table range B5:G1005
B15: Step 3: Select the DATA tab in the ribbon
B16: Step 4: Click What-If Analysis in the Data Tools group and select Data Table
B17: Step 5: In the Data Table dialog box, leave the Row input cell blank
B18: and enter any empty cell in the spreadsheet (e.g. A1) into the Column input cell box
B19: Step 6: Click OK
E24: <- an empty cell
A29: 1b | B29: Now complete the tables headed 'Tracking convergence of output means' in the Simulated output
B30: worksheet and add a chart for each of the columns of output means. What can you conclude?
B32: Notice that each time you press F9 the tables recalculate and the charts are revised.
B33: To stop this from happening, save your simulated output as values (copy > paste as values)
A35: 2 | B35: In the Output Summary worksheet summarise the simulation output and create a histogram
B36: for each variable of interest.
B38: The data analysis toolbox (Data > Data Analysis) can be used to produce descriptive statistics.
B39: Alternatively, there are built-in formulas for the more important summary statistics, such as
B40: mean, standard deviation, minimum and maximum.
B42: Determine the probability of loss using the COUNTIF built-in function.
B44: Use the mean, standard deviation, and sample size (i.e number of simulation trials) to produce
B45: upper and lower 95% confidence limits (UCL and LCL) on the mean.
B47: The data analysis toolbox can also be used to produce a histogram.
B48: The minimum and maximum values will help you to decide on your bins.
B49: Note that for continuous variables the histogram should not have any gaps between the bars.
A51: 3 | B51: Risk Analysis worksheet
B52: In this worksheet you should try to identify what might be the main drivers of the key output variable.
B53: Complete the tables provided in the worksheet using Excel built in functions, COUNTIF, MAX and IF.
B54: The formulas used for finding maximum values involve an array of cells satisfying a condition/s. These formulas must be entered by placing the cursor at the end of the formula and pressing Cntl+Shift+Enter.

Sheet Manager Page
B2: Key output | D2: Profit
B5: Key inputs | D5: Management decision variable
D6: Selling price per unit
D8: Uncertain inputs subject to random variation
D9: Cost of direct labour
D10: Cost of parts
D11: Demand
D13: Fixed inputs
D14: Administrative costs
D15: Advertising costs

Sheet Conceptual Model
A2: Key output | C2: Profit
A5: Key inputs | C5: Management decision variable
C6: Selling price per unit
C8: Uncertain inputs subject to random variation
C9: Cost of direct labour
C10: Cost of parts
C11: Demand
C13: Fixed inputs
C14: Administrative costs
C15: Advertising costs

Sheet Distributions
B2: PROBABILITY DISTRIBUTIONS
B5: Direct labour cost per unit | F5: Random number range | M5: Cost of parts per unit: Uniform | T5: Demand: Normal
D7: Cumulative | F7: Lower | G7: Upper | N7: Lower | O7: Upper | V7: Standard
B8: Cost | C8: Probability | D8: probability | F8: limit | G8: limit | H8: Demand | N8: limit | O8: limit | U8: Mean | V8: deviation
B9: 43 | C9: 0.1 | D9: =SUM(C$9:C9) -> 0.1 | F9: 0 | G9: =D9 -> 0.1 | H9: =B9 -> 43 | M9: Uniform | N9: 80 | O9: 100 | T9: Price $249 | U9: 15000 | V9: 4500
B10: 44 | C10: 0.2 | D10: =SUM(C$9:C10) -> 0.3 | F10: =G9 -> 0.1 | G10: =F10+C10 -> 0.3 | H10: =B10 -> 44 | T10: Price $299 | U10: 11000 | V10: 4500
B11: 45 | C11: 0.4 | D11: =SUM(C$9:C11) -> 0.7 | F11: =G10 -> 0.3 | G11: =F11+C11 -> 0.7 | H11: =B11 -> 45
B12: 46 | C12: 0.2 | D12: =SUM(C$9:C12) -> 0.9 | F12: =G11 -> 0.7 | G12: =F12+C12 -> 0.9 | H12: =B12 -> 46
B13: 47 | C13: 0.1 | D13: =SUM(C$9:C13) -> 1 | F13: =G12 -> 0.9 | G13: =F13+C13 -> 1 | H13: =B13 -> 47

Sheet Model
B2: COMPUTED VALUES AND OUTPUT | G2: INPUTS
G3: Stochastic inputs
B4: Contribution margin per unit | C4: =H10-H4-H5 -> 174.03523 | G4: Direct labour cost per unit | H4: =VLOOKUP(RAND(),Distributions!F9:H13,3) -> 44 | I4: Given distribution
G5: Cost of parts per unit | H5: =Distributions!N9+(Distributions!O9-Distributions!N9)*RAND() -> 80.964766 | I5: Uniform distribution
B6: First-year profit | C6: =(C4*H6-(H14+H15)*1000000) -> -847370.01 | G6: Demand | H6: =IF(Selling_price_per_unit=249,MAX(0,_xlfn.NORM.INV(RAND(),Distributions!U9,Distributions!V9)),MAX(0,_xlfn.NORM.INV(RAND(),Distributions!U10,Distributions!V10))) -> 877.00629 | I6: Normal distribution*
G9: Decision variables
G10: Selling price per unit | H10: 299
G13: Fixed inputs
G14: Administrative costs ($M) | H14: 0.35
G15: Advertising costs ($M) | H15: 0.65
G17: Notes:
G18: * Should be a non-negative integer. Can do this by using ROUND built-in formula, but this complication is unnecessary for decision making

Sheet Simulated Output
B2: SIMULATION OF 1,000 TRIALS AT PRICE $249 | I2: TRACKING CONVERGENCE OF OUTPUT MEANS
B4: Simulation trial | C4: Direct labour cost per unit | D4: Parts cost per unit | E4: Demand | F4: Contribution margin per unit ($) | G4: First year Profit | I4: Mean contribution margin per unit ($) | J4: Mean First year Profit
C5: =Direct_labour_cost_per_unit -> 44 | D5: =Cost_of_parts_per_unit -> 80.964766 | E5: =Demand -> 877.00629 | F5: =Contribution_margin_per_unit -> 174.03523 | G5: =First_year_profit -> -847370.01
B6: 1 | C6: 47 | D6: 92.819149 | E6: 12074.882 | F6: 159.18085 | G6: 922090.05 | I6: =AVERAGE(F$6:F6) -> 159.18085 | J6: =AVERAGE(G$6:G6) -> 922090.05
B7: 2 | C7: 45 | D7: 80.906796 | E7: 5274.3238 | F7: 173.0932 | G7: -87050.399 | I7: =AVERAGE(F$6:F7) -> 166.13703 | J7: =AVERAGE(G$6:G7) -> 417519.83
B8: 3 | C8: 46 | D8: 82.599783 | E8: 9051.229 | F8: 170.40022 | G8: 542331.39 | I8: =AVERAGE(F$6:F8) -> 167.55809 | J8: =AVERAGE(G$6:G8) -> 459123.68
B9: 4 | C9: 43 | D9: 93.296176 | E9: 13262.578 | F9: 162.70382 | G9: 1157872.1 | I9: =AVERAGE(F$6:F9) -> 166.34452 | J9: =AVERAGE(G$6:G9) -> 633810.79
B10: 5 | C10: 45 | D10: 80.090203 | E10: 18136.779 | F10: 173.9098 | G10: 2154163.5 | I10: =AVERAGE(F$6:F10) -> 167.85758 | J10: =AVERAGE(G$6:G10) -> 937881.34
B11: 6 | C11: 46 | D11: 83.721803 | E11: 14655.848 | F11: 169.2782 | G11: 1480915.6 | I11: =AVERAGE(F$6:F11) -> 168.09435 | J11: =AVERAGE(G$6:G11) -> 1028387
B12: 7 | C12: 46 | D12: 96.548392 | E12: 11913.332 | F12: 156.45161 | G12: 863859.94 | I12: =AVERAGE(F$6:F12) -> 166.4311 | J12: =AVERAGE(G$6:G12) -> 1004883.2
B13: 8 | C13: 47 | D13: 87.988506 | E13: 10575.81 | F13: 164.01149 | G13: 734554.36 | I13: =AVERAGE(F$6:F13) -> 166.12865 | J13: =AVERAGE(G$6:G13) -> 971092.07
B14: 9 | C14: 44 | D14: 82.998819 | E14: 16727.913 | F14: 172.00118 | G14: 1877220.7 | I14: =AVERAGE(F$6:F14) -> 166.78115 | J14: =AVERAGE(G$6:G14) -> 1071773
B15: 10 | C15: 45 | D15: 88.563572 | E15: 11640.713 | F15: 165.43643 | G15: 925797.97 | I15: =AVERAGE(F$6:F15) -> 166.64668 | J15: =AVERAGE(G$6:G15) -> 1057175.5
B16: 11 | C16: 45 | D16: 99.616089 | E16: 7529.1581 | F16: 154.38391 | G16: 162380.87 | I16: =AVERAGE(F$6:F16) -> 165.53188 | J16: =AVERAGE(G$6:G16) -> 975830.56
B17: 12 | C17: 47 | D17: 94.685517 | E17: 14601.291 | F17: 157.31448 | G17: 1296994.6 | I17: =AVERAGE(F$6:F17) -> 164.8471 | J17: =AVERAGE(G$6:G17) -> 1002594.2
... B1005: 1000 | C1005: 46 | D1005: 96.153017 | E1005: 12706.21 | F1005: 156.84698 | G1005: 992930.73 | I1005: =AVERAGE(F$6:F1005) -> 163.86845 | J1005: =AVERAGE(G$6:G1005) -> 815196.04

Sheet Simulated Output-constant value
B2: SIMULATION OF 1,000 TRIALS AT PRICE $249 | I2: TRACKING CONVERGENCE OF OUTPUT MEANS | N2: SIMULATION OF 1,000 TRIALS AT PRICE $299 | U2: TRACKING CONVERGENCE OF OUTPUT MEANS
B4: Simulation trial | C4: Direct labour cost per unit | D4: Parts cost per unit | E4: Demand | F4: Contribution margin per unit ($) | G4: First year Profit | I4: Mean contribution margin per unit ($) | J4: Mean First year Profit | N4: Simulation trial | O4: Direct labour cost per unit | P4: Parts cost per unit | Q4: Demand | R4: Contribution margin per unit ($) | S4: First year Profit | U4: Mean contribution margin per unit ($) | V4: Mean First year Profit
C5: =Direct_labour_cost_per_unit -> 44 | D5: =Cost_of_parts_per_unit -> 80.964766 | E5: =Demand -> 877.00629 | F5: =Contribution_margin_per_unit -> 174.03523 | G5: =First_year_profit -> -847370.01 | O5: =Direct_labour_cost_per_unit -> 44 | P5: =Cost_of_parts_per_unit -> 80.964766 | Q5: =Demand -> 877.00629 | R5: =Contribution_margin_per_unit -> 174.03523 | S5: =First_year_profit -> -847370.01
B6: 1 | C6: 46 | D6: 99.179698 | E6: 16938.672 | F6: 103.8203 | G6: 758578.09 | I6: =AVERAGE(F$6:F6) -> 103.8203 | J6: =AVERAGE(G$6:G6) -> 758578.09 | N6: 1 | O6: 43 | P6: 92.870767 | Q6: 8101.5521 | R6: 163.12923 | S6: 321599.97 | U6: =AVERAGE(R$6:R6) -> 163.12923 | V6: =AVERAGE(S$6:S6) -> 321599.97
B7: 2 | C7: 45 | D7: 95.656907 | E7: 9739.7283 | F7: 108.34309 | G7: 55232.294 | I7: =AVERAGE(F$6:F7) -> 106.0817 | J7: =AVERAGE(G$6:G7) -> 406905.19 | N7: 2 | O7: 45 | P7: 91.63089 | Q7: 14775.647 | R7: 162.36911 | S7: 1399108.6 | U7: =AVERAGE(R$6:R7) -> 162.74917 | V7: =AVERAGE(S$6:S7) -> 860354.31
B8: 3 | C8: 43 | D8: 97.188983 | E8: 15736 | F8: 108.81102 | G8: 712250.16 | I8: =AVERAGE(F$6:F8) -> 106.99147 | J8: =AVERAGE(G$6:G8) -> 508686.85 | N8: 3 | O8: 45 | P8: 95.03487 | Q8: 17072.89 | R8: 158.96513 | S8: 1713994.1 | U8: =AVERAGE(R$6:R8) -> 161.48782 | V8: =AVERAGE(S$6:S8) -> 1144900.9
B9: 4 | C9: 46 | D9: 91.705789 | E9: 15620.592 | F9: 111.29421 | G9: 738481.44 | I9: =AVERAGE(F$6:F9) -> 108.06716 | J9: =AVERAGE(G$6:G9) -> 566135.5 | N9: 4 | O9: 45 | P9: 82.796528 | Q9: 16252.584 | R9: 171.20347 | S9: 1782498.9 | U9: =AVERAGE(R$6:R9) -> 163.91674 | V9: =AVERAGE(S$6:S9) -> 1304300.4
B10: 5 | C10: 45 | D10: 89.974603 | E10: 15826.88 | F10: 114.0254 | G10: 804666.29 | I10: =AVERAGE(F$6:F10) -> 109.2588 | J10: =AVERAGE(G$6:G10) -> 613841.66 | N10: 5 | O10: 43 | P10: 95.78587 | Q10: 16377.129 | R10: 160.21413 | S10: 1623847.4 | U10: =AVERAGE(R$6:R10) -> 163.17621 | V10: =AVERAGE(S$6:S10) -> 1368209.8
B11: 6 | C11: 45 | D11: 89.951245 | E11: 14265.438 | F11: 114.04876 | G11: 626955.43 | I11: =AVERAGE(F$6:F11) -> 110.05713 | J11: =AVERAGE(G$6:G11) -> 616027.29 | N11: 6 | O11: 44 | P11: 99.237473 | Q11: 13612.613 | R11: 155.76253 | S11: 1120335.1 | U11: =AVERAGE(R$6:R11) -> 161.9406 | V11: =AVERAGE(S$6:S11) -> 1326897.4
B12: 7 | C12: 44 | D12: 83.619785 | E12: 17345.84 | F12: 121.38021 | G12: 1105441.8 | I12: =AVERAGE(F$6:F12) -> 111.67471 | J12: =AVERAGE(G$6:G12) -> 685943.65 | N12: 7 | O12: 47 | P12: 93.737508 | Q12: 7758.2962 | R12: 158.26249 | S12: 227847.29 | U12: =AVERAGE(R$6:R12) -> 161.41516 | V12: =AVERAGE(S$6:S12) -> 1169890.2
B13: 8 | C13: 44 | D13: 95.851351 | E13: 16736.848 | F13: 109.14865 | G13: 826804.36 | I13: =AVERAGE(F$6:F13) -> 111.35896 | J13: =AVERAGE(G$6:G13) -> 703551.23 | N13: 8 | O13: 46 | P13: 97.824325 | Q13: 9166.9727 | R13: 155.17568 | S13: 422491.17 | U13: =AVERAGE(R$6:R13) -> 160.63522 | V13: =AVERAGE(S$6:S13) -> 1076465.3
B14: 9 | C14: 45 | D14: 96.10166 | E14: 15755.935 | F14: 107.89834 | G14: 700039.2 | I14: =AVERAGE(F$6:F14) -> 110.97444 | J14: =AVERAGE(G$6:G14) -> 703161.01 | N14: 9 | O14: 45 | P14: 86.704679 | Q14: 10983.358 | R14: 167.29532 | S14: 837464.33 | U14: =AVERAGE(R$6:R14) -> 161.37523 | V14: =AVERAGE(S$6:S14) -> 1049909.7
B15: 10 | C15: 45 | D15: 97.94816 | E15: 12687.313 | F15: 106.05184 | G15: 345512.87 | I15: =AVERAGE(F$6:F15) -> 110.48218 | J15: =AVERAGE(G$6:G15) -> 667396.19 | N15: 10 | O15: 45 | P15: 88.075403 | Q15: 17069.033 | R15: 165.9246 | S15: 1832172.4 | U15: =AVERAGE(R$6:R15) -> 161.83017 | V15: =AVERAGE(S$6:S15) -> 1128135.9
B16: 11 | C16: 45 | D16: 88.713933 | E16: 8103.6905 | F16: 115.28607 | G16: -65757.398 | I16: =AVERAGE(F$6:F16) -> 110.9189 | J16: =AVERAGE(G$6:G16) -> 600745.87 | N16: 11 | O16: 45 | P16: 84.52096 | Q16: 6747.7338 | R16: 169.47904 | S16: 143599.45 | U16: =AVERAGE(R$6:R16) -> 162.52552 | V16: =AVERAGE(S$6:S16) -> 1038632.6
B17: 12 | C17: 46 | D17: 87.425217 | E17: 18804.089 | F17: 115.57478 | G17: 1173278.5 | I17: =AVERAGE(F$6:F17) -> 111.30689 | J17: =AVERAGE(G$6:G17) -> 648456.92 | N17: 12 | O17: 45 | P17: 99.655609 | Q17: 2800.9857 | R17: 154.34439 | S17: -567683.56 | U17: =AVERAGE(R$6:R17) -> 161.84376 | V17: =AVERAGE(S$6:S17) -> 904772.93
... B1005: 1000 | C1005: 45 | D1005: 92.810261 | E1005: 9756.9213 | F1005: 111.18974 | G1005: 84869.536 | I1005: =AVERAGE(F$6:F1005) -> 113.78341 | J1005: =AVERAGE(G$6:G1005) -> 718929 | N1005: 1000 | O1005: 44 | P1005: 80.622097 | Q1005: 7448.7543 | R1005: 174.3779 | S1005: 298898.15 | U1005: =AVERAGE(R$6:R1005) -> 163.93789 | V1005: =AVERAGE(S$6:S1005) -> 816465.48

Sheet Output Summary
B2: DESCRIPTIVE STATISTICS (based on SIMULATED OUTPUT -constant values)
B3: Remember to first save your simulated output as values
C7: First Year Profit ($'000) when Selling Price is
C9: 249 | D9: 299
B10: Mean | C10: =AVERAGE('Simulated Output-constant value'!G$6:G$1005)/1000 -> 718.929 | D10: =AVERAGE('Simulated Output-constant value'!S$6:S$1005)/1000 -> 816.46548
B11: Standard Deviation | C11: =_xlfn.STDEV.S('Simulated Output-constant value'!G$6:G$1005)/1000 -> 527.03429 | D11: =_xlfn.STDEV.S('Simulated Output-constant value'!S$6:S$1005)/1000 -> 725.21791
B12: Minimum | C12: =MIN('Simulated Output-constant value'!G$6:G$1005)/1000 -> -733.29714 | D12: =MIN('Simulated Output-constant value'!S$6:S$1005)/1000 -> -1000
B13: Maximum | C13: =MAX('Simulated Output-constant value'!G$6:G$1005)/1000 -> 2336.7944 | D13: =MAX('Simulated Output-constant value'!S$6:S$1005)/1000 -> 3471.6163
B14: Probability of loss | C14: =COUNTIF('Simulated Output-constant value'!G$6:G$1005,"<0")/1000 -> 0.093 | D14: =COUNTIF('Simulated Output-constant value'!S$6:S$1005,"<0")/1000 -> 0.123
B16: 95% Confidence limits for the mean
B18: UCL | C18: =C$10+_xlfn.T.INV.2T(0.05,1000-1)*C$11/SQRT(1000) -> 751.63394 | D18: =D$10+_xlfn.T.INV.2T(0.05,1000-1)*D$11/SQRT(1000) -> 861.46865
B19: LCL | C19: =C$10-_xlfn.T.INV.2T(0.05,1000-1)*C$11/SQRT(1000) -> 686.22405 | D19: =D$10-_xlfn.T.INV.2T(0.05,1000-1)*D$11/SQRT(1000) -> 771.46231
B22: Lower Quartile | C22: =QUARTILE('Simulated Output-constant value'!$G$6:$G$1005,1) -> 346698.18 | D22: =QUARTILE('Simulated Output-constant value'!$S$6:$S$1005,1) -> 330721.19
B23: Upper Quartile | C23: =QUARTILE('Simulated Output-constant value'!$G$6:$G$1005,3) -> 1067438.4 | D23: =QUARTILE('Simulated Output-constant value'!$S$6:$S$1005,3) -> 1269816.1
B24: IQR | C24: =C23-C22 -> 720740.22 | D24: =D23-D22 -> 939094.96
B25: 90th Percentile | C25: =PERCENTILE('Simulated Output-constant value'!$G$6:$G$1005,0.9) -> 1416025.5 | D25: =PERCENTILE('Simulated Output-constant value'!$S$6:$S$1005,0.9) -> 1774759.6
B26: 10th Percentile | C26: =PERCENTILE('Simulated Output-constant value'!$G$6:$G$1005,0.1) -> 29350.457 | D26: =PERCENTILE('Simulated Output-constant value'!$S$6:$S$1005,0.1) -> -107132.59
A30: Formula for calculating confidence interval for a mean
C33: where tn-1 = | D33: =_xlfn.T.INV.2T(0.05,$J$58-1) -> 1.9623415
B44: Selling Price is $249 | E44: Selling Price is $249 | I44: Selling Price is $249 | P44: Selling Price is $299 | S44: Selling Price is $299 | W44: Selling Price is $299
B45: Bin | C45: Frequency | E45: Bins ($M) | F45: Frequency | G45: % Frequency | P45: Bin | Q45: Frequency | S45: Bins ($M) | T45: Frequency | U45: % Frequency
B46: -1000000 | C46: 0 | E46: =B48/1000000 -> -0.5 | F46: =C48 -> 8 | G46: =F46/F$59 -> 0.008 | I46: Mean | J46: 718929 | P46: -1000000 | Q46: 3 | S46: =P46/1000000 -> -1 | T46: =Q46 -> 3 | U46: =T46/T$65 -> 0.003 | W46: Mean | X46: 816465.48
B47: -750000 | C47: 0 | E47: =B49/1000000 -> -0.25 | F47: =C49 -> 18 | G47: =F47/F$59 -> 0.018 | I47: Standard Error | J47: 16666.288 | P47: -750000 | Q47: 11 | S47: =P47/1000000 -> -0.75 | T47: =Q47 -> 11 | U47: =T47/T$65 -> 0.011 | W47: Standard Error | X47: 22933.404
B48: -500000 | C48: 8 | E48: =B50/1000000 -> 0 | F48: =C50 -> 67 | G48: =F48/F$59 -> 0.067 | I48: Median | J48: 724278.72 | P48: -500000 | Q48: 23 | S48: =P48/1000000 -> -0.5 | T48: =Q48 -> 23 | U48: =T48/T$65 -> 0.023 | W48: Median | X48: 797823.09
B49: -250000 | C49: 18 | E49: =B51/1000000 -> 0.25 | F49: =C51 -> 109 | G49: =F49/F$59 -> 0.109 | I49: Mode | J49: #N/A | P49: -250000 | Q49: 36 | S49: =P49/1000000 -> -0.25 | T49: =Q49 -> 36 | U49: =T49/T$65 -> 0.036 | W49: Mode | X49: -1000000
B50: 0 | C50: 67 | E50: =B52/1000000 -> 0.5 | F50: =C52 -> 139 | G50: =F50/F$59 -> 0.139 | I50: Standard Deviation | J50: 527034.29 | P50: 0 | Q50: 50 | S50: =P50/1000000 -> 0 | T50: =Q50 -> 50 | U50: =T50/T$65 -> 0.05 | W50: Standard Deviation | X50: 725217.91
B51: 250000 | C51: 109 | E51: =B53/1000000 -> 0.75 | F51: =C53 -> 185 | G51: =F51/F$59 -> 0.185 | I51: Sample Variance | J51: 2.7776514e+11 | P51: 250000 | Q51: 93 | S51: =P51/1000000 -> 0.25 | T51: =Q51 -> 93 | U51: =T51/T$65 -> 0.093 | W51: Sample Variance | X51: 5.2594102e+11
B52: 500000 | C52: 139 | E52: =B54/1000000 -> 1 | F52: =C54 -> 180 | G52: =F52/F$59 -> 0.18 | I52: Kurtosis | J52: -0.30302004 | P52: 500000 | Q52: 113 | S52: =P52/1000000 -> 0.5 | T52: =Q52 -> 113 | U52: =T52/T$65 -> 0.113 | W52: Kurtosis | X52: -0.07812015
B53: 750000 | C53: 185 | E53: =B55/1000000 -> 1.25 | F53: =C55 -> 128 | G53: =F53/F$59 -> 0.128 | I53: Skewness | J53: 0.073381826 | P53: 750000 | Q53: 131 | S53: =P53/1000000 -> 0.75 | T53: =Q53 -> 131 | U53: =T53/T$65 -> 0.131 | W53: Skewness | X53: 0.10700134
B54: 1000000 | C54: 180 | E54: =B56/1000000 -> 1.5 | F54: =C56 -> 95 | G54: =F54/F$59 -> 0.095 | I54: Range | J54: 3070091.5 | P54: 1000000 | Q54: 157 | S54: =P54/1000000 -> 1 | T54: =Q54 -> 157 | U54: =T54/T$65 -> 0.157 | W54: Range | X54: 4471616.3
B55: 1250000 | C55: 128 | E55: =B57/1000000 -> 1.75 | F55: =C57 -> 44 | G55: =F55/F$59 -> 0.044 | I55: Minimum | J55: -733297.14 | P55: 1250000 | Q55: 124 | S55: =P55/1000000 -> 1.25 | T55: =Q55 -> 124 | U55: =T55/T$65 -> 0.124 | W55: Minimum | X55: -1000000
B56: 1500000 | C56: 95 | E56: =B58/1000000 -> 2 | F56: =C58 -> 20 | G56: =F56/F$59 -> 0.02 | I56: Maximum | J56: 2336794.4 | P56: 1500000 | Q56: 83 | S56: =P56/1000000 -> 1.5 | T56: =Q56 -> 83 | U56: =T56/T$65 -> 0.083 | W56: Maximum | X56: 3471616.3
B57: 1750000 | C57: 44 | E57: =B59/1000000 -> 2.25 | F57: =C59 -> 6 | G57: =F57/F$59 -> 0.006 | I57: Sum | J57: 7.18929e+08 | P57: 1750000 | Q57: 69 | S57: =P57/1000000 -> 1.75 | T57: =Q57 -> 69 | U57: =T57/T$65 -> 0.069 | W57: Sum | X57: 8.1646548e+08
B58: 2000000 | C58: 20 | E58: =B60/1000000 -> 2.5 | F58: =C60 -> 1 | G58: =F58/F$59 -> 0.001 | I58: Count | J58: 1000 | P58: 2000000 | Q58: 42 | S58: =P58/1000000 -> 2 | T58: =Q58 -> 42 | U58: =T58/T$65 -> 0.042 | W58: Count | X58: 1000
B59: 2250000 | C59: 6 | E59: Total | F59: =SUM(F46:F58) -> 1000 | G59: =F59/F$59 -> 1 | P59: 2250000 | Q59: 35 | S59: =P59/1000000 -> 2.25 | T59: =Q59 -> 35 | U59: =T59/T$65 -> 0.035
B60: 2500000 | C60: 1 | P60: 2500000 | Q60: 24 | S60: =P60/1000000 -> 2.5 | T60: =Q60 -> 24 | U60: =T60/T$65 -> 0.024
B61: 2750000 | C61: 0 | P61: 2750000 | Q61: 4 | S61: =P61/1000000 -> 2.75 | T61: =Q61 -> 4 | U61: =T61/T$65 -> 0.004
B62: 3000000 | C62: 0 | P62: 3000000 | Q62: 1 | S62: =P62/1000000 -> 3 | T62: =Q62 -> 1 | U62: =T62/T$65 -> 0.001
B63: 3250000 | C63: 0 | P63: 3250000 | Q63: 0 | S63: =P63/1000000 -> 3.25 | T63: =Q63 -> 0 | U63: =T63/T$65 -> 0
B64: 3500000 | C64: 0 | P64: 3500000 | Q64: 1 | S64: =P64/1000000 -> 3.5 | T64: =Q64 -> 1 | U64: =T64/T$65 -> 0.001
...

Sheet Risk Analysis
I1: RISK PROFILING (Based on SIMULATED OUTPUT-on constant values)
C3: First Year Profit intervals when Selling Price is $249 | M3: First Year Profit intervals when Selling Price is $299
C5: -$1M to -$0.5M | D5: -$0.5M to $0 | E5: $0 to $1M | F5: $1M to $2M | G5: Over $2M | H5: Total | M5: -$1M to -$0.5M | N5: -$0.5M to $0 | O5: $0 to $1M | P5: $1M to $2M | Q5: Over $2M | R5: Total
B6: Probability | C6: =COUNTIF('Simulated Output-constant value'!G6:G1005, "<-500000")/1000 -> 0.008 | D6: =COUNTIFS('Simulated Output-constant value'!G6:G1005,">-500000",'Simulated Output-constant value'!G6:G1005,"<0")/1000 -> 0.085 | E6: =COUNTIFS('Simulated Output-constant value'!$G6:$G1005,">0",'Simulated Output-constant value'!$G6:$G1005,"<1000000")/1000 -> 0.613 | F6: =COUNTIFS('Simulated Output-constant value'!$G6:$G1005,">1000000",'Simulated Output-constant value'!$G6:$G1005,"<2000000")/1000 -> 0.287 | G6: =COUNTIF('Simulated Output-constant value'!$G6:$G1005,">2000000")/1000 -> 0.007 | H6: =SUM(C6:G6) -> 1 | L6: Probability | M6: =COUNTIF('Simulated Output-constant value'!$S6:$S1005,"<-500000")/1000 -> 0.037 | N6: =COUNTIFS('Simulated Output-constant value'!$S6:$S1005,">-500000",'Simulated Output-constant value'!$S6:$S1005,"<0")/1000 -> 0.086 | O6: =COUNTIFS('Simulated Output-constant value'!$S6:$S1005,">0",'Simulated Output-constant value'!$S6:$S1005,"<1000000")/1000 -> 0.494 | P6: =COUNTIFS('Simulated Output-constant value'!$S6:$S1005,">1000000",'Simulated Output-constant value'!$S6:$S1005,"<2000000")/1000 -> 0.318 | Q6: =COUNTIF('Simulated Output-constant value'!$S6:$S1005,">2000000")/1000 -> 0.065 | R6: =SUM(M6:Q6) -> 1
B7: Max demand | C7: =_xlfn.MAXIFS('Simulated Output-constant value'!$E$6:$E$1005, 'Simulated Output-constant value'!$G$6:$G$1005, "<-500000") -> 4698.3183 | D7: =_xlfn.MAXIFS('Simulated Output-constant value'!$E$6:$E$1005,'Simulated Output-constant value'!$G$6:$G$1005, ">-500000", 'Simulated Output-constant value'!$G$6:$G$1005, "<0") -> 9534.0957 | E7: =_xlfn.MAXIFS('Simulated Output-constant value'!$E$6:$E$1005,'Simulated Output-constant value'!$G$6:$G$1005, ">0", 'Simulated Output-constant value'!$G$6:$G$1005, "<1000000") -> 19113.391 | F7: =_xlfn.MAXIFS('Simulated Output-constant value'!$E$6:$E$1005,'Simulated Output-constant value'!$G$6:$G$1005, ">1000000", 'Simulated Output-constant value'!$G$6:$G$1005, "<2000000") -> 27168.749 | L7: Max demand | M7: =_xlfn.MAXIFS('Simulated Output-constant value'!$Q$6:$Q$1005, 'Simulated Output-constant value'!$S$6:$S$1005, "<-500000") -> 2946.528 | N7: =_xlfn.MAXIFS('Simulated Output-constant value'!$Q$6:$Q$1005,'Simulated Output-constant value'!$S$6:$S$1005, ">-500000", 'Simulated Output-constant value'!$S$6:$S$1005, "<0") -> 6343.7845 | O7: =_xlfn.MAXIFS('Simulated Output-constant value'!$Q$6:$Q$1005,'Simulated Output-constant value'!$S$6:$S$1005, ">0", 'Simulated Output-constant value'!$S$6:$S$1005, "<1000000") -> 12993.878 | P7: =_xlfn.MAXIFS('Simulated Output-constant value'!$Q$6:$Q$1005,'Simulated Output-constant value'!$S$6:$S$1005, ">1000000", 'Simulated Output-constant value'!$S$6:$S$1005, "<2000000") -> 18756.597
B15: Interpretation based on when selling price is $249 | L15: Interpretation based on when selling price is $299

Sheet Class-Ex1
A2: Units Sold | B2: No. of Days | C2: Relative Frequency | D2: Cumulative Relative Frequency | E2: Interval of Random Numbers*
A3: 0 | B3: 54 | C3: =B3/$B$9 -> 0.18 | D3: =C3 -> 0.18 | E3: 0.00-0.18
A4: 1 | B4: 117 | C4: =B4/$B$9 -> 0.39 | D4: =D3+C4 -> 0.57 | E4: 0.18-0.57
A5: 2 | B5: 72 | C5: =B5/$B$9 -> 0.24 | D5: =D4+C5 -> 0.81 | E5: 0.57-0.81
A6: 3 | B6: 42 | C6: =B6/$B$9 -> 0.14 | D6: =D5+C6 -> 0.95 | E6: 0.81-0.95
A7: 4 | B7: 12 | C7: =B7/$B$9 -> 0.04 | D7: =D6+C7 -> 0.99 | E7: 0.95-0.99
A8: 5 | B8: 3 | C8: =B8/$B$9 -> 0.01 | D8: =D7+C8 -> 1 | E8: 0.99-1.00
B9: =SUM(B3:B8) -> 300 | C9: =SUM(C3:C8) -> 1

Sheet Class-Ex 2 
A2: Units Sold | B2: No. of Times | C2: Relative frequesncy / Probability (a) | D2: Cumulative Relative Frequency | E2: Interval of Random Numbers*
A3: 30 | B3: 8 | C3: =B3/50 -> 0.16 | D3: =C3 -> 0.16 | E3: 0.000-0.160
A4: 40 | B4: 12 | C4: =B4/50 -> 0.24 | D4: =D3+C4 -> 0.4 | E4: 0.160-0.400
A5: 50 | B5: 15 | C5: =B5/50 -> 0.3 | D5: =D4+C5 -> 0.7 | E5: 0.400-0.700
A6: 60 | B6: 10 | C6: =B6/50 -> 0.2 | D6: =D5+C6 -> 0.9 | E6: 0.700-0.900
A7: 70 | B7: 5 | C7: =B7/50 -> 0.1 | D7: =D6+C7 -> 1 | E7: 0.900-1.000
B8: =SUM(B3:B7) -> 50 | C8: =SUM(C3:C7) -> 1
A11: Random Numbers | B11: Units Sold | D11: Units Sold | E11: Relative frequesncy / Probability
A12: 0.123 | B12: 30 | D12: 30 | E12: 0.16 | F12: =D12*E12 -> 4.8
A13: 0.963 | B13: 70 | D13: 40 | E13: 0.24 | F13: =D13*E13 -> 9.6
A14: 0.531 | B14: 50 | D14: 50 | E14: 0.3 | F14: =D14*E14 -> 15
A15: 0.809 | B15: 60 | D15: 60 | E15: 0.2 | F15: =D15*E15 -> 12
A16: 0.95 | B16: 70 | D16: 70 | E16: 0.1 | F16: =D16*E16 -> 7
A17: 0.102 | B17: 30 | E17: =SUM(E12:E16) -> 1 | F17: =SUM(F12:F16) -> 48.4
A18: 0.403 | B18: 50
A19: 0.458 | B19: 50
A20: 0.777 | B20: 60
A21: 0.291 | B21: 40
A22: total | B22: =SUM(B12:B21) -> 510
A23: Average | B23: =B22/10 -> 51

Sheet Class-Ex3
A2: Sales Category ($’000) | B2: No. of Weeks Sold | C2: Relative Frequency | D2: Cumulative Relative Frequency | E2: Interval of Random Numbers*
A3: 5-10 | B3: 5 | C3: =B3/26 -> 0.19230769 | D3: =C3 -> 0.19230769 | E3: 0.00-0.19
A4: 11-20 | B4: 7 | C4: =B4/26 -> 0.26923077 | D4: =D3+C4 -> 0.46153846 | E4: 0.19-0.46
A5: 21-30 | B5: 8 | C5: =B5/26 -> 0.30769231 | D5: =D4+C5 -> 0.76923077 | E5: 0.46-0.77
A6: 31-40 | B6: 6 | C6: =B6/26 -> 0.23076923 | D6: =D5+C6 -> 1 | E6: 0.77-1.00
B7: =SUM(B3:B6) -> 26 | C7: =SUM(C3:C6) -> 1
A10: Week | B10: Random Number | C10: Sales Category | D10: Sales Category Average
A11: 1 | B11: 0.63 | C11: 21-30 | D11: 25.5
A12: 2 | B12: 0.13 | C12: 5-10 | D12: 7.5
A13: 3 | B13: 0.67 | C13: 21-30 | D13: 25.5
A14: 4 | B14: 0.5 | C14: 21-30 | D14: 25.5
A15: 5 | B15: 0.71 | C15: 21-30 | D15: 25.5
A16: total | D16: =SUM(D11:D15) -> 109.5
A17: Average | D17: =D16/5 -> 21.9
D18: =D17*1000 -> 21900

Sheet Revision Ex 1
A2: No. of A/C failures per month (x) | B2: No. of apartment buildings | C2: Relative frequesncy / Probability (a) | D2: Cumulative Relative Frequency | E2: Interval of Random Numbers*
A3: 30 | B3: 8 | C3: =B3/50 -> 0.16 | D3: =C3 -> 0.16 | E3: 0.000-0.160
A4: 40 | B4: 12 | C4: =B4/50 -> 0.24 | D4: =D3+C4 -> 0.4 | E4: 0.160-0.400
A5: 50 | B5: 15 | C5: =B5/50 -> 0.3 | D5: =D4+C5 -> 0.7 | E5: 0.400-0.700
A6: 60 | B6: 10 | C6: =B6/50 -> 0.2 | D6: =D5+C6 -> 0.9 | E6: 0.700-0.900
A7: 70 | B7: 5 | C7: =B7/50 -> 0.1 | D7: =D6+C7 -> 1 | E7: 0.900-1.000
B8: =SUM(B3:B7) -> 50 | C8: =SUM(C3:C7) -> 1
A11: Random Numbers | B11: No. of A/C failures per month (b) | D11: No. of A/C failures per month (x) | E11: Relative frequesncy / Probability
A12: 0.123 | B12: 30 | D12: 0 | E12: 0.1 | F12: =D12*E12 -> 0
A13: 0.963 | B13: 70 | D13: 1 | E13: 0.17 | F13: =D13*E13 -> 0.17
A14: 0.531 | B14: 50 | D14: 2 | E14: 0.21 | F14: =D14*E14 -> 0.42
A15: 0.809 | B15: 60 | D15: 3 | E15: 0.28 | F15: =D15*E15 -> 0.84
A16: 0.95 | B16: 70 | D16: 4 | E16: 0.16 | F16: =D16*E16 -> 0.64
A17: 0.102 | B17: 30 | D17: 5 | E17: 0.07 | F17: =D17*E17 -> 0.35
A18: 0.403 | B18: 50 | D18: 6 | E18: 0.01 | F18: =D18*E18 -> 0.06
A19: 0.458 | B19: 50 | E19: =SUM(E12:E18) -> 1 | F19: =SUM(F12:F18) -> 2.48
A20: 0.777 | B20: 60
A21: 0.291 | B21: 40
A22: total | B22: =SUM(B12:B21) -> 510
A23: Average ( c ) | B23: =B22/10 -> 51
