Workbook
Name Number_to_produce: #REF!
Name Selected_hospital: #REF!
Name Unit_costs_of_inputs: #REF!
Name Unit_prices_of_outputs: #REF!

Sheet Instructions
B1: Tasks
B3: In this seminar we will only focus on the four Portfolio model worksheets numbered 0-3.
B4: The other worksheets are included as additional resources to support the Topic 3 lecture notes
A6: 1. | B6: Portfolio model worksheet 0. Data
B7: We have collected monthly stock prices of nine stocks over 4 years (actually 49 months)
B8: Notice that the monthly prices are listed from latest to earliest month.
B10: The first thing we do with these prices is to turn them into returns (there are 48 for each stock)
B11: Next we extract the key statistics for the returns - means and covariances
B13: We average the returns for each stock to estimate the means (see table below the returns)
B15: The covariances can be found by using the Data Analysis tookbox.
B16: If the Data Analysis tookbox is not listed under the Data tab, you will have to add it in as follows: File > Options > Add-ins > Go > Tick Analysis Toolpak and click OK
B18: Excel doesn't print out the full square table of covariances, so we need to
B19: complete the missing "upper triangle" part
B20: This is done in three steps
B21: 1) Select the cells of the table (the square block including the blank cells).
B22: 2) Copy and Paste Special Transpose into some empty space.
... B27: We are now ready to use the means and covariances in our analysis!
A29: 2. | B29: Portfolio model worksheet 1. Minimise risk
B30: This was covered in class for the case of 3 stocks. We repeat it here for the nine stocks under consideration
B31: The aim is to find a set of portfolio weights that minimise risk subject to a minimum expected return of 1%.
A33: 3. | B33: Portfolio model worksheet 2. Maximise return
B34: This is where we maximise return for a given level of risk.
B35: The aim is to find a set of portfolio weights that maximise the portfolio return subject to having a risk that is no greater than 3%.
A37: 4. | B37: Portfolio model worksheet 3. Maximise the Sharpe Ratio
B38: This is where we maximise the Sharpe Ratio = the ratio of the return above the risk free rate of 1.5% divided by the amount of risk assumed
B39: There are no constraints on the expected return or the level of risk assumed.

Sheet 0. Data
B3: STOCK VALUES EACH MONTH - RAW DATA | K3: MONTHLY RETURNS
A4: Date | B4: BHP | C4: RIO | D4: Wesfarmers | E4: Woolworth | F4: NAB | G4: CBA | H4: Westpac | I4: ANZ | J4: Telstra | K4: BHP | L4: RIO | M4: Wesfarmers | N4: Woolworth | O4: NAB | P4: CBA | Q4: Westpac | R4: ANZ | S4: Telstra
A5: 41640 | B5: 35.93 | C5: 63.51 | D5: 43.43 | E5: 34.36 | F5: 34.24 | G5: 76.19 | H5: 31.71 | I5: 30.97 | J5: 5.22
A6: 41610 | B6: 37.99 | C6: 68.18 | D6: 44.04 | E6: 33.85 | F6: 34.83 | G6: 77.8 | H6: 32.38 | I6: 32.23 | J6: 5.25
A7: 41579 | B7: 37.39 | C7: 66.06 | D7: 42.92 | E7: 33.69 | F7: 34.58 | G7: 77.82 | H7: 32.88 | I7: 31.9 | J7: 5.06
A8: 41548 | B8: 37.66 | C8: 63.99 | D8: 44.06 | E8: 34.9 | F8: 34.36 | G8: 76.08 | H8: 33.41 | I8: 33.84 | J8: 5.18
A9: 41519 | B9: 35.74 | C9: 61.74 | D9: 42.17 | E9: 35 | F9: 33.39 | G9: 71.21 | H9: 31.89 | I9: 30.78 | J9: 4.97
A10: 41487 | B10: 35.11 | C10: 58.3 | D10: 41.69 | E10: 34.95 | F10: 31.57 | G10: 72.84 | H10: 30.58 | I10: 29.69 | J10: 4.9
A11: 41456 | B11: 34.02 | C11: 57.51 | D11: 40.55 | E11: 32.65 | F11: 30.39 | G11: 72.19 | H11: 30.1 | I11: 29.76 | J11: 4.85
A12: 41428 | B12: 30.81 | C12: 52.37 | D12: 39.59 | E12: 32.15 | F12: 28.88 | G12: 67.29 | H12: 28.14 | I12: 28.58 | J12: 4.64
A13: 41395 | B13: 34.25 | C13: 55.18 | D13: 39.23 | E13: 32.33 | F13: 28.22 | G13: 65.04 | H13: 27.71 | I13: 27.54 | J13: 4.61
A14: 41365 | B14: 32.11 | C14: 55.8 | D14: 43.36 | E14: 35.68 | F14: 32.07 | G14: 71.45 | H14: 32.07 | I14: 31.1 | J14: 4.84
A15: 41334 | B15: 32.17 | C15: 57.2 | D15: 40.19 | E15: 33.11 | F15: 29.09 | G15: 66.15 | H15: 29.19 | I15: 27.87 | J15: 4.39
A16: 41306 | B16: 35.84 | C16: 66.08 | D16: 41.02 | E16: 33.64 | F16: 28.49 | G16: 65.43 | H16: 29.2 | I16: 28.05 | J16: 4.46
... A53: 40182 | B53: 35.2 | C53: 63.55 | D53: 23.52 | E53: 21.54 | F53: 20.29 | G53: 42.05 | H53: 18.58 | I53: 17.81 | J53: 2.41
K55: BHP | L55: RIO | M55: Wesfarmers | N55: Woolworth | O55: NAB | P55: CBA | Q55: Westpac | R55: ANZ | S55: Telstra
J56: Average Return over 48 months

Sheet 1. Minimise risk
B1: PORTFOLIO OPTIMISATION MODELS
C3: INPUTS
C5: Stock | D5: 1 | E5: 2 | F5: 3 | G5: 4 | H5: 5 | I5: 6 | J5: 7 | K5: 8 | L5: 9
C6: Mean
C8: Cov | D8: 1 | E8: 2 | F8: 3 | G8: 4 | H8: 5 | I8: 6 | J8: 7 | K8: 8 | L8: 9
C9: 1
C10: 2
C11: 3
C12: 4
C13: 5
C14: 6
C15: 7
C16: 8
C17: 9
B19: DECISION VARIABLES
D20: stock 1 | E20: stock 2 | F20: stock 3 | G20: stock 4 | H20: stock 5 | I20: stock 6 | J20: stock 7 | K20: stock 8 | L20: stock 9
C21: Investment weights | D21: 0 | E21: 0 | F21: 0 | G21: 0 | H21: 0 | I21: 0 | J21: 0 | K21: 0 | L21: 0
B23: CALCULATED VARIABLES
D25: =D21 -> 0 | E25: =E21 -> 0 | F25: =F21 -> 0 | G25: =G21 -> 0 | H25: =H21 -> 0 | I25: =I21 -> 0 | J25: =J21 -> 0 | K25: =K21 -> 0 | L25: =L21 -> 0
C26: Cov | D26: 1 | E26: 2 | F26: 3 | G26: 4 | H26: 5 | I26: 6 | J26: 7 | K26: 8 | L26: 9
B27: =D21 -> 0 | C27: 1 | D27: =D9 -> 0 | E27: =E9 -> 0 | F27: =F9 -> 0 | G27: =G9 -> 0 | H27: =H9 -> 0 | I27: =I9 -> 0 | J27: =J9 -> 0 | K27: =K9 -> 0 | L27: =L9 -> 0
B28: =E21 -> 0 | C28: 2 | D28: =D10 -> 0 | E28: =E10 -> 0 | F28: =F10 -> 0 | G28: =G10 -> 0 | H28: =H10 -> 0 | I28: =I10 -> 0 | J28: =J10 -> 0 | K28: =K10 -> 0 | L28: =L10 -> 0
B29: =F21 -> 0 | C29: 3 | D29: =D11 -> 0 | E29: =E11 -> 0 | F29: =F11 -> 0 | G29: =G11 -> 0 | H29: =H11 -> 0 | I29: =I11 -> 0 | J29: =J11 -> 0 | K29: =K11 -> 0 | L29: =L11 -> 0
B30: =G21 -> 0 | C30: 4 | D30: =D12 -> 0 | E30: =E12 -> 0 | F30: =F12 -> 0 | G30: =G12 -> 0 | H30: =H12 -> 0 | I30: =I12 -> 0 | J30: =J12 -> 0 | K30: =K12 -> 0 | L30: =L12 -> 0
B31: =H21 -> 0 | C31: 5 | D31: =D13 -> 0 | E31: =E13 -> 0 | F31: =F13 -> 0 | G31: =G13 -> 0 | H31: =H13 -> 0 | I31: =I13 -> 0 | J31: =J13 -> 0 | K31: =K13 -> 0 | L31: =L13 -> 0
B32: =I21 -> 0 | C32: 6 | D32: =D14 -> 0 | E32: =E14 -> 0 | F32: =F14 -> 0 | G32: =G14 -> 0 | H32: =H14 -> 0 | I32: =I14 -> 0 | J32: =J14 -> 0 | K32: =K14 -> 0 | L32: =L14 -> 0
B33: =J21 -> 0 | C33: 7 | D33: =D15 -> 0 | E33: =E15 -> 0 | F33: =F15 -> 0 | G33: =G15 -> 0 | H33: =H15 -> 0 | I33: =I15 -> 0 | J33: =J15 -> 0 | K33: =K15 -> 0 | L33: =L15 -> 0
B34: =K21 -> 0 | C34: 8 | D34: =D16 -> 0 | E34: =E16 -> 0 | F34: =F16 -> 0 | G34: =G16 -> 0 | H34: =H16 -> 0 | I34: =I16 -> 0 | J34: =J16 -> 0 | K34: =K16 -> 0 | L34: =L16 -> 0
B35: =L21 -> 0 | C35: 9 | D35: =D17 -> 0 | E35: =E17 -> 0 | F35: =F17 -> 0 | G35: =G17 -> 0 | H35: =H17 -> 0 | I35: =I17 -> 0 | J35: =J17 -> 0 | K35: =K17 -> 0 | L35: =L17 -> 0
C37: Portfolio variance terms | D37: 1 | E37: 2 | F37: 3 | G37: 4 | H37: 5 | I37: 6 | J37: 7 | K37: 8 | L37: 9
C38: 1 | D38: =$B27*D$25*D27 -> 0 | E38: =$B27*E$25*E27 -> 0 | F38: =$B27*F$25*F27 -> 0 | G38: =$B27*G$25*G27 -> 0 | H38: =$B27*H$25*H27 -> 0 | I38: =$B27*I$25*I27 -> 0 | J38: =$B27*J$25*J27 -> 0 | K38: =$B27*K$25*K27 -> 0 | L38: =$B27*L$25*L27 -> 0
C39: 2 | D39: =$B28*D$25*D28 -> 0 | E39: =$B28*E$25*E28 -> 0 | F39: =$B28*F$25*F28 -> 0 | G39: =$B28*G$25*G28 -> 0 | H39: =$B28*H$25*H28 -> 0 | I39: =$B28*I$25*I28 -> 0 | J39: =$B28*J$25*J28 -> 0 | K39: =$B28*K$25*K28 -> 0 | L39: =$B28*L$25*L28 -> 0
C40: 3 | D40: =$B29*D$25*D29 -> 0 | E40: =$B29*E$25*E29 -> 0 | F40: =$B29*F$25*F29 -> 0 | G40: =$B29*G$25*G29 -> 0 | H40: =$B29*H$25*H29 -> 0 | I40: =$B29*I$25*I29 -> 0 | J40: =$B29*J$25*J29 -> 0 | K40: =$B29*K$25*K29 -> 0 | L40: =$B29*L$25*L29 -> 0
C41: 4 | D41: =$B30*D$25*D30 -> 0 | E41: =$B30*E$25*E30 -> 0 | F41: =$B30*F$25*F30 -> 0 | G41: =$B30*G$25*G30 -> 0 | H41: =$B30*H$25*H30 -> 0 | I41: =$B30*I$25*I30 -> 0 | J41: =$B30*J$25*J30 -> 0 | K41: =$B30*K$25*K30 -> 0 | L41: =$B30*L$25*L30 -> 0
C42: 5 | D42: =$B31*D$25*D31 -> 0 | E42: =$B31*E$25*E31 -> 0 | F42: =$B31*F$25*F31 -> 0 | G42: =$B31*G$25*G31 -> 0 | H42: =$B31*H$25*H31 -> 0 | I42: =$B31*I$25*I31 -> 0 | J42: =$B31*J$25*J31 -> 0 | K42: =$B31*K$25*K31 -> 0 | L42: =$B31*L$25*L31 -> 0
C43: 6 | D43: =$B32*D$25*D32 -> 0 | E43: =$B32*E$25*E32 -> 0 | F43: =$B32*F$25*F32 -> 0 | G43: =$B32*G$25*G32 -> 0 | H43: =$B32*H$25*H32 -> 0 | I43: =$B32*I$25*I32 -> 0 | J43: =$B32*J$25*J32 -> 0 | K43: =$B32*K$25*K32 -> 0 | L43: =$B32*L$25*L32 -> 0
C44: 7 | D44: =$B33*D$25*D33 -> 0 | E44: =$B33*E$25*E33 -> 0 | F44: =$B33*F$25*F33 -> 0 | G44: =$B33*G$25*G33 -> 0 | H44: =$B33*H$25*H33 -> 0 | I44: =$B33*I$25*I33 -> 0 | J44: =$B33*J$25*J33 -> 0 | K44: =$B33*K$25*K33 -> 0 | L44: =$B33*L$25*L33 -> 0
C45: 8 | D45: =$B34*D$25*D34 -> 0 | E45: =$B34*E$25*E34 -> 0 | F45: =$B34*F$25*F34 -> 0 | G45: =$B34*G$25*G34 -> 0 | H45: =$B34*H$25*H34 -> 0 | I45: =$B34*I$25*I34 -> 0 | J45: =$B34*J$25*J34 -> 0 | K45: =$B34*K$25*K34 -> 0 | L45: =$B34*L$25*L34 -> 0
C46: 9 | D46: =$B35*D$25*D35 -> 0 | E46: =$B35*E$25*E35 -> 0 | F46: =$B35*F$25*F35 -> 0 | G46: =$B35*G$25*G35 -> 0 | H46: =$B35*H$25*H35 -> 0 | I46: =$B35*I$25*I35 -> 0 | J46: =$B35*J$25*J35 -> 0 | K46: =$B35*K$25*K35 -> 0 | L46: =$B35*L$25*L35 -> 0
C48: Average portfolio return | D48: =SUMPRODUCT(D6:L6,D21:L21) -> 0
...

Sheet 2. Maximise return
B1: PORTFOLIO OPTIMISATION MODELS
C3: INPUTS
C5: Stock | D5: 1 | E5: 2 | F5: 3 | G5: 4 | H5: 5 | I5: 6 | J5: 7 | K5: 8 | L5: 9
C6: Mean | D6: ='1. Minimise risk'!D6 -> 0 | E6: ='1. Minimise risk'!E6 -> 0 | F6: ='1. Minimise risk'!F6 -> 0 | G6: ='1. Minimise risk'!G6 -> 0 | H6: ='1. Minimise risk'!H6 -> 0 | I6: ='1. Minimise risk'!I6 -> 0 | J6: ='1. Minimise risk'!J6 -> 0 | K6: ='1. Minimise risk'!K6 -> 0 | L6: ='1. Minimise risk'!L6 -> 0
C8: Cov | D8: 1 | E8: 2 | F8: 3 | G8: 4 | H8: 5 | I8: 6 | J8: 7 | K8: 8 | L8: 9
C9: 1 | D9: ='1. Minimise risk'!D9 -> 0 | E9: ='1. Minimise risk'!E9 -> 0 | F9: ='1. Minimise risk'!F9 -> 0 | G9: ='1. Minimise risk'!G9 -> 0 | H9: ='1. Minimise risk'!H9 -> 0 | I9: ='1. Minimise risk'!I9 -> 0 | J9: ='1. Minimise risk'!J9 -> 0 | K9: ='1. Minimise risk'!K9 -> 0 | L9: ='1. Minimise risk'!L9 -> 0
C10: 2 | D10: ='1. Minimise risk'!D10 -> 0 | E10: ='1. Minimise risk'!E10 -> 0 | F10: ='1. Minimise risk'!F10 -> 0 | G10: ='1. Minimise risk'!G10 -> 0 | H10: ='1. Minimise risk'!H10 -> 0 | I10: ='1. Minimise risk'!I10 -> 0 | J10: ='1. Minimise risk'!J10 -> 0 | K10: ='1. Minimise risk'!K10 -> 0 | L10: ='1. Minimise risk'!L10 -> 0
C11: 3 | D11: ='1. Minimise risk'!D11 -> 0 | E11: ='1. Minimise risk'!E11 -> 0 | F11: ='1. Minimise risk'!F11 -> 0 | G11: ='1. Minimise risk'!G11 -> 0 | H11: ='1. Minimise risk'!H11 -> 0 | I11: ='1. Minimise risk'!I11 -> 0 | J11: ='1. Minimise risk'!J11 -> 0 | K11: ='1. Minimise risk'!K11 -> 0 | L11: ='1. Minimise risk'!L11 -> 0
C12: 4 | D12: ='1. Minimise risk'!D12 -> 0 | E12: ='1. Minimise risk'!E12 -> 0 | F12: ='1. Minimise risk'!F12 -> 0 | G12: ='1. Minimise risk'!G12 -> 0 | H12: ='1. Minimise risk'!H12 -> 0 | I12: ='1. Minimise risk'!I12 -> 0 | J12: ='1. Minimise risk'!J12 -> 0 | K12: ='1. Minimise risk'!K12 -> 0 | L12: ='1. Minimise risk'!L12 -> 0
C13: 5 | D13: ='1. Minimise risk'!D13 -> 0 | E13: ='1. Minimise risk'!E13 -> 0 | F13: ='1. Minimise risk'!F13 -> 0 | G13: ='1. Minimise risk'!G13 -> 0 | H13: ='1. Minimise risk'!H13 -> 0 | I13: ='1. Minimise risk'!I13 -> 0 | J13: ='1. Minimise risk'!J13 -> 0 | K13: ='1. Minimise risk'!K13 -> 0 | L13: ='1. Minimise risk'!L13 -> 0
C14: 6 | D14: ='1. Minimise risk'!D14 -> 0 | E14: ='1. Minimise risk'!E14 -> 0 | F14: ='1. Minimise risk'!F14 -> 0 | G14: ='1. Minimise risk'!G14 -> 0 | H14: ='1. Minimise risk'!H14 -> 0 | I14: ='1. Minimise risk'!I14 -> 0 | J14: ='1. Minimise risk'!J14 -> 0 | K14: ='1. Minimise risk'!K14 -> 0 | L14: ='1. Minimise risk'!L14 -> 0
C15: 7 | D15: ='1. Minimise risk'!D15 -> 0 | E15: ='1. Minimise risk'!E15 -> 0 | F15: ='1. Minimise risk'!F15 -> 0 | G15: ='1. Minimise risk'!G15 -> 0 | H15: ='1. Minimise risk'!H15 -> 0 | I15: ='1. Minimise risk'!I15 -> 0 | J15: ='1. Minimise risk'!J15 -> 0 | K15: ='1. Minimise risk'!K15 -> 0 | L15: ='1. Minimise risk'!L15 -> 0
C16: 8 | D16: ='1. Minimise risk'!D16 -> 0 | E16: ='1. Minimise risk'!E16 -> 0 | F16: ='1. Minimise risk'!F16 -> 0 | G16: ='1. Minimise risk'!G16 -> 0 | H16: ='1. Minimise risk'!H16 -> 0 | I16: ='1. Minimise risk'!I16 -> 0 | J16: ='1. Minimise risk'!J16 -> 0 | K16: ='1. Minimise risk'!K16 -> 0 | L16: ='1. Minimise risk'!L16 -> 0
C17: 9 | D17: ='1. Minimise risk'!D17 -> 0 | E17: ='1. Minimise risk'!E17 -> 0 | F17: ='1. Minimise risk'!F17 -> 0 | G17: ='1. Minimise risk'!G17 -> 0 | H17: ='1. Minimise risk'!H17 -> 0 | I17: ='1. Minimise risk'!I17 -> 0 | J17: ='1. Minimise risk'!J17 -> 0 | K17: ='1. Minimise risk'!K17 -> 0 | L17: ='1. Minimise risk'!L17 -> 0
B19: DECISION VARIABLES
D20: stock 1 | E20: stock 2 | F20: stock 3 | G20: stock 4 | H20: stock 5 | I20: stock 6 | J20: stock 7 | K20: stock 8 | L20: stock 9
C21: Investment weights | D21: 0 | E21: 0 | F21: 0 | G21: 0 | H21: 0 | I21: 0 | J21: 0 | K21: 0 | L21: 0
B23: CALCULATED VARIABLES
D25: =D21 -> 0 | E25: =E21 -> 0 | F25: =F21 -> 0 | G25: =G21 -> 0 | H25: =H21 -> 0 | I25: =I21 -> 0 | J25: =J21 -> 0 | K25: =K21 -> 0 | L25: =L21 -> 0
C26: Cov | D26: 1 | E26: 2 | F26: 3 | G26: 4 | H26: 5 | I26: 6 | J26: 7 | K26: 8 | L26: 9
B27: =D21 -> 0 | C27: 1 | D27: =D9 -> 0 | E27: =E9 -> 0 | F27: =F9 -> 0 | G27: =G9 -> 0 | H27: =H9 -> 0 | I27: =I9 -> 0 | J27: =J9 -> 0 | K27: =K9 -> 0 | L27: =L9 -> 0
B28: =E21 -> 0 | C28: 2 | D28: =D10 -> 0 | E28: =E10 -> 0 | F28: =F10 -> 0 | G28: =G10 -> 0 | H28: =H10 -> 0 | I28: =I10 -> 0 | J28: =J10 -> 0 | K28: =K10 -> 0 | L28: =L10 -> 0
B29: =F21 -> 0 | C29: 3 | D29: =D11 -> 0 | E29: =E11 -> 0 | F29: =F11 -> 0 | G29: =G11 -> 0 | H29: =H11 -> 0 | I29: =I11 -> 0 | J29: =J11 -> 0 | K29: =K11 -> 0 | L29: =L11 -> 0
B30: =G21 -> 0 | C30: 4 | D30: =D12 -> 0 | E30: =E12 -> 0 | F30: =F12 -> 0 | G30: =G12 -> 0 | H30: =H12 -> 0 | I30: =I12 -> 0 | J30: =J12 -> 0 | K30: =K12 -> 0 | L30: =L12 -> 0
B31: =H21 -> 0 | C31: 5 | D31: =D13 -> 0 | E31: =E13 -> 0 | F31: =F13 -> 0 | G31: =G13 -> 0 | H31: =H13 -> 0 | I31: =I13 -> 0 | J31: =J13 -> 0 | K31: =K13 -> 0 | L31: =L13 -> 0
B32: =I21 -> 0 | C32: 6 | D32: =D14 -> 0 | E32: =E14 -> 0 | F32: =F14 -> 0 | G32: =G14 -> 0 | H32: =H14 -> 0 | I32: =I14 -> 0 | J32: =J14 -> 0 | K32: =K14 -> 0 | L32: =L14 -> 0
B33: =J21 -> 0 | C33: 7 | D33: =D15 -> 0 | E33: =E15 -> 0 | F33: =F15 -> 0 | G33: =G15 -> 0 | H33: =H15 -> 0 | I33: =I15 -> 0 | J33: =J15 -> 0 | K33: =K15 -> 0 | L33: =L15 -> 0
B34: =K21 -> 0 | C34: 8 | D34: =D16 -> 0 | E34: =E16 -> 0 | F34: =F16 -> 0 | G34: =G16 -> 0 | H34: =H16 -> 0 | I34: =I16 -> 0 | J34: =J16 -> 0 | K34: =K16 -> 0 | L34: =L16 -> 0
B35: =L21 -> 0 | C35: 9 | D35: =D17 -> 0 | E35: =E17 -> 0 | F35: =F17 -> 0 | G35: =G17 -> 0 | H35: =H17 -> 0 | I35: =I17 -> 0 | J35: =J17 -> 0 | K35: =K17 -> 0 | L35: =L17 -> 0
C37: Portfolio variance terms | D37: 1 | E37: 2 | F37: 3 | G37: 4 | H37: 5 | I37: 6 | J37: 7 | K37: 8 | L37: 9
C38: 1 | D38: =$B27*D$25*D27 -> 0 | E38: =$B27*E$25*E27 -> 0 | F38: =$B27*F$25*F27 -> 0 | G38: =$B27*G$25*G27 -> 0 | H38: =$B27*H$25*H27 -> 0 | I38: =$B27*I$25*I27 -> 0 | J38: =$B27*J$25*J27 -> 0 | K38: =$B27*K$25*K27 -> 0 | L38: =$B27*L$25*L27 -> 0
C39: 2 | D39: =$B28*D$25*D28 -> 0 | E39: =$B28*E$25*E28 -> 0 | F39: =$B28*F$25*F28 -> 0 | G39: =$B28*G$25*G28 -> 0 | H39: =$B28*H$25*H28 -> 0 | I39: =$B28*I$25*I28 -> 0 | J39: =$B28*J$25*J28 -> 0 | K39: =$B28*K$25*K28 -> 0 | L39: =$B28*L$25*L28 -> 0
C40: 3 | D40: =$B29*D$25*D29 -> 0 | E40: =$B29*E$25*E29 -> 0 | F40: =$B29*F$25*F29 -> 0 | G40: =$B29*G$25*G29 -> 0 | H40: =$B29*H$25*H29 -> 0 | I40: =$B29*I$25*I29 -> 0 | J40: =$B29*J$25*J29 -> 0 | K40: =$B29*K$25*K29 -> 0 | L40: =$B29*L$25*L29 -> 0
C41: 4 | D41: =$B30*D$25*D30 -> 0 | E41: =$B30*E$25*E30 -> 0 | F41: =$B30*F$25*F30 -> 0 | G41: =$B30*G$25*G30 -> 0 | H41: =$B30*H$25*H30 -> 0 | I41: =$B30*I$25*I30 -> 0 | J41: =$B30*J$25*J30 -> 0 | K41: =$B30*K$25*K30 -> 0 | L41: =$B30*L$25*L30 -> 0
C42: 5 | D42: =$B31*D$25*D31 -> 0 | E42: =$B31*E$25*E31 -> 0 | F42: =$B31*F$25*F31 -> 0 | G42: =$B31*G$25*G31 -> 0 | H42: =$B31*H$25*H31 -> 0 | I42: =$B31*I$25*I31 -> 0 | J42: =$B31*J$25*J31 -> 0 | K42: =$B31*K$25*K31 -> 0 | L42: =$B31*L$25*L31 -> 0
C43: 6 | D43: =$B32*D$25*D32 -> 0 | E43: =$B32*E$25*E32 -> 0 | F43: =$B32*F$25*F32 -> 0 | G43: =$B32*G$25*G32 -> 0 | H43: =$B32*H$25*H32 -> 0 | I43: =$B32*I$25*I32 -> 0 | J43: =$B32*J$25*J32 -> 0 | K43: =$B32*K$25*K32 -> 0 | L43: =$B32*L$25*L32 -> 0
C44: 7 | D44: =$B33*D$25*D33 -> 0 | E44: =$B33*E$25*E33 -> 0 | F44: =$B33*F$25*F33 -> 0 | G44: =$B33*G$25*G33 -> 0 | H44: =$B33*H$25*H33 -> 0 | I44: =$B33*I$25*I33 -> 0 | J44: =$B33*J$25*J33 -> 0 | K44: =$B33*K$25*K33 -> 0 | L44: =$B33*L$25*L33 -> 0
C45: 8 | D45: =$B34*D$25*D34 -> 0 | E45: =$B34*E$25*E34 -> 0 | F45: =$B34*F$25*F34 -> 0 | G45: =$B34*G$25*G34 -> 0 | H45: =$B34*H$25*H34 -> 0 | I45: =$B34*I$25*I34 -> 0 | J45: =$B34*J$25*J34 -> 0 | K45: =$B34*K$25*K34 -> 0 | L45: =$B34*L$25*L34 -> 0
C46: 9 | D46: =$B35*D$25*D35 -> 0 | E46: =$B35*E$25*E35 -> 0 | F46: =$B35*F$25*F35 -> 0 | G46: =$B35*G$25*G35 -> 0 | H46: =$B35*H$25*H35 -> 0 | I46: =$B35*I$25*I35 -> 0 | J46: =$B35*J$25*J35 -> 0 | K46: =$B35*K$25*K35 -> 0 | L46: =$B35*L$25*L35 -> 0
B48: Standard deviation of portfolio return | D48: =SQRT(SUM(D38:L46)) -> 0
...

Sheet 3. Maximise Sharpe
B1: PORTFOLIO OPTIMISATION MODELS
C3: INPUTS
C5: Stock | D5: 1 | E5: 2 | F5: 3 | G5: 4 | H5: 5 | I5: 6 | J5: 7 | K5: 8 | L5: 9
C6: Mean | D6: ='1. Minimise risk'!D6 -> 0 | E6: ='1. Minimise risk'!E6 -> 0 | F6: ='1. Minimise risk'!F6 -> 0 | G6: ='1. Minimise risk'!G6 -> 0 | H6: ='1. Minimise risk'!H6 -> 0 | I6: ='1. Minimise risk'!I6 -> 0 | J6: ='1. Minimise risk'!J6 -> 0 | K6: ='1. Minimise risk'!K6 -> 0 | L6: ='1. Minimise risk'!L6 -> 0
C8: Cov | D8: 1 | E8: 2 | F8: 3 | G8: 4 | H8: 5 | I8: 6 | J8: 7 | K8: 8 | L8: 9
C9: 1 | D9: ='1. Minimise risk'!D9 -> 0 | E9: ='1. Minimise risk'!E9 -> 0 | F9: ='1. Minimise risk'!F9 -> 0 | G9: ='1. Minimise risk'!G9 -> 0 | H9: ='1. Minimise risk'!H9 -> 0 | I9: ='1. Minimise risk'!I9 -> 0 | J9: ='1. Minimise risk'!J9 -> 0 | K9: ='1. Minimise risk'!K9 -> 0 | L9: ='1. Minimise risk'!L9 -> 0
C10: 2 | D10: ='1. Minimise risk'!D10 -> 0 | E10: ='1. Minimise risk'!E10 -> 0 | F10: ='1. Minimise risk'!F10 -> 0 | G10: ='1. Minimise risk'!G10 -> 0 | H10: ='1. Minimise risk'!H10 -> 0 | I10: ='1. Minimise risk'!I10 -> 0 | J10: ='1. Minimise risk'!J10 -> 0 | K10: ='1. Minimise risk'!K10 -> 0 | L10: ='1. Minimise risk'!L10 -> 0
C11: 3 | D11: ='1. Minimise risk'!D11 -> 0 | E11: ='1. Minimise risk'!E11 -> 0 | F11: ='1. Minimise risk'!F11 -> 0 | G11: ='1. Minimise risk'!G11 -> 0 | H11: ='1. Minimise risk'!H11 -> 0 | I11: ='1. Minimise risk'!I11 -> 0 | J11: ='1. Minimise risk'!J11 -> 0 | K11: ='1. Minimise risk'!K11 -> 0 | L11: ='1. Minimise risk'!L11 -> 0
C12: 4 | D12: ='1. Minimise risk'!D12 -> 0 | E12: ='1. Minimise risk'!E12 -> 0 | F12: ='1. Minimise risk'!F12 -> 0 | G12: ='1. Minimise risk'!G12 -> 0 | H12: ='1. Minimise risk'!H12 -> 0 | I12: ='1. Minimise risk'!I12 -> 0 | J12: ='1. Minimise risk'!J12 -> 0 | K12: ='1. Minimise risk'!K12 -> 0 | L12: ='1. Minimise risk'!L12 -> 0
C13: 5 | D13: ='1. Minimise risk'!D13 -> 0 | E13: ='1. Minimise risk'!E13 -> 0 | F13: ='1. Minimise risk'!F13 -> 0 | G13: ='1. Minimise risk'!G13 -> 0 | H13: ='1. Minimise risk'!H13 -> 0 | I13: ='1. Minimise risk'!I13 -> 0 | J13: ='1. Minimise risk'!J13 -> 0 | K13: ='1. Minimise risk'!K13 -> 0 | L13: ='1. Minimise risk'!L13 -> 0
C14: 6 | D14: ='1. Minimise risk'!D14 -> 0 | E14: ='1. Minimise risk'!E14 -> 0 | F14: ='1. Minimise risk'!F14 -> 0 | G14: ='1. Minimise risk'!G14 -> 0 | H14: ='1. Minimise risk'!H14 -> 0 | I14: ='1. Minimise risk'!I14 -> 0 | J14: ='1. Minimise risk'!J14 -> 0 | K14: ='1. Minimise risk'!K14 -> 0 | L14: ='1. Minimise risk'!L14 -> 0
C15: 7 | D15: ='1. Minimise risk'!D15 -> 0 | E15: ='1. Minimise risk'!E15 -> 0 | F15: ='1. Minimise risk'!F15 -> 0 | G15: ='1. Minimise risk'!G15 -> 0 | H15: ='1. Minimise risk'!H15 -> 0 | I15: ='1. Minimise risk'!I15 -> 0 | J15: ='1. Minimise risk'!J15 -> 0 | K15: ='1. Minimise risk'!K15 -> 0 | L15: ='1. Minimise risk'!L15 -> 0
C16: 8 | D16: ='1. Minimise risk'!D16 -> 0 | E16: ='1. Minimise risk'!E16 -> 0 | F16: ='1. Minimise risk'!F16 -> 0 | G16: ='1. Minimise risk'!G16 -> 0 | H16: ='1. Minimise risk'!H16 -> 0 | I16: ='1. Minimise risk'!I16 -> 0 | J16: ='1. Minimise risk'!J16 -> 0 | K16: ='1. Minimise risk'!K16 -> 0 | L16: ='1. Minimise risk'!L16 -> 0
C17: 9 | D17: ='1. Minimise risk'!D17 -> 0 | E17: ='1. Minimise risk'!E17 -> 0 | F17: ='1. Minimise risk'!F17 -> 0 | G17: ='1. Minimise risk'!G17 -> 0 | H17: ='1. Minimise risk'!H17 -> 0 | I17: ='1. Minimise risk'!I17 -> 0 | J17: ='1. Minimise risk'!J17 -> 0 | K17: ='1. Minimise risk'!K17 -> 0 | L17: ='1. Minimise risk'!L17 -> 0
B19: DECISION VARIABLES
D20: stock 1 | E20: stock 2 | F20: stock 3 | G20: stock 4 | H20: stock 5 | I20: stock 6 | J20: stock 7 | K20: stock 8 | L20: stock 9
C21: Investment weights | D21: 0 | E21: 0 | F21: 0 | G21: 0 | H21: 0 | I21: 0 | J21: 0 | K21: 0 | L21: 0
B23: CALCULATED VARIABLES
D25: =D21 -> 0 | E25: =E21 -> 0 | F25: =F21 -> 0 | G25: =G21 -> 0 | H25: =H21 -> 0 | I25: =I21 -> 0 | J25: =J21 -> 0 | K25: =K21 -> 0 | L25: =L21 -> 0
C26: Cov | D26: 1 | E26: 2 | F26: 3 | G26: 4 | H26: 5 | I26: 6 | J26: 7 | K26: 8 | L26: 9
B27: =D21 -> 0 | C27: 1 | D27: =D9 -> 0 | E27: =E9 -> 0 | F27: =F9 -> 0 | G27: =G9 -> 0 | H27: =H9 -> 0 | I27: =I9 -> 0 | J27: =J9 -> 0 | K27: =K9 -> 0 | L27: =L9 -> 0
B28: =E21 -> 0 | C28: 2 | D28: =D10 -> 0 | E28: =E10 -> 0 | F28: =F10 -> 0 | G28: =G10 -> 0 | H28: =H10 -> 0 | I28: =I10 -> 0 | J28: =J10 -> 0 | K28: =K10 -> 0 | L28: =L10 -> 0
B29: =F21 -> 0 | C29: 3 | D29: =D11 -> 0 | E29: =E11 -> 0 | F29: =F11 -> 0 | G29: =G11 -> 0 | H29: =H11 -> 0 | I29: =I11 -> 0 | J29: =J11 -> 0 | K29: =K11 -> 0 | L29: =L11 -> 0
B30: =G21 -> 0 | C30: 4 | D30: =D12 -> 0 | E30: =E12 -> 0 | F30: =F12 -> 0 | G30: =G12 -> 0 | H30: =H12 -> 0 | I30: =I12 -> 0 | J30: =J12 -> 0 | K30: =K12 -> 0 | L30: =L12 -> 0
B31: =H21 -> 0 | C31: 5 | D31: =D13 -> 0 | E31: =E13 -> 0 | F31: =F13 -> 0 | G31: =G13 -> 0 | H31: =H13 -> 0 | I31: =I13 -> 0 | J31: =J13 -> 0 | K31: =K13 -> 0 | L31: =L13 -> 0
B32: =I21 -> 0 | C32: 6 | D32: =D14 -> 0 | E32: =E14 -> 0 | F32: =F14 -> 0 | G32: =G14 -> 0 | H32: =H14 -> 0 | I32: =I14 -> 0 | J32: =J14 -> 0 | K32: =K14 -> 0 | L32: =L14 -> 0
B33: =J21 -> 0 | C33: 7 | D33: =D15 -> 0 | E33: =E15 -> 0 | F33: =F15 -> 0 | G33: =G15 -> 0 | H33: =H15 -> 0 | I33: =I15 -> 0 | J33: =J15 -> 0 | K33: =K15 -> 0 | L33: =L15 -> 0
B34: =K21 -> 0 | C34: 8 | D34: =D16 -> 0 | E34: =E16 -> 0 | F34: =F16 -> 0 | G34: =G16 -> 0 | H34: =H16 -> 0 | I34: =I16 -> 0 | J34: =J16 -> 0 | K34: =K16 -> 0 | L34: =L16 -> 0
B35: =L21 -> 0 | C35: 9 | D35: =D17 -> 0 | E35: =E17 -> 0 | F35: =F17 -> 0 | G35: =G17 -> 0 | H35: =H17 -> 0 | I35: =I17 -> 0 | J35: =J17 -> 0 | K35: =K17 -> 0 | L35: =L17 -> 0
C37: Portfolio variance terms | D37: 1 | E37: 2 | F37: 3 | G37: 4 | H37: 5 | I37: 6 | J37: 7 | K37: 8 | L37: 9
C38: 1 | D38: =$B27*D$25*D27 -> 0 | E38: =$B27*E$25*E27 -> 0 | F38: =$B27*F$25*F27 -> 0 | G38: =$B27*G$25*G27 -> 0 | H38: =$B27*H$25*H27 -> 0 | I38: =$B27*I$25*I27 -> 0 | J38: =$B27*J$25*J27 -> 0 | K38: =$B27*K$25*K27 -> 0 | L38: =$B27*L$25*L27 -> 0
C39: 2 | D39: =$B28*D$25*D28 -> 0 | E39: =$B28*E$25*E28 -> 0 | F39: =$B28*F$25*F28 -> 0 | G39: =$B28*G$25*G28 -> 0 | H39: =$B28*H$25*H28 -> 0 | I39: =$B28*I$25*I28 -> 0 | J39: =$B28*J$25*J28 -> 0 | K39: =$B28*K$25*K28 -> 0 | L39: =$B28*L$25*L28 -> 0
C40: 3 | D40: =$B29*D$25*D29 -> 0 | E40: =$B29*E$25*E29 -> 0 | F40: =$B29*F$25*F29 -> 0 | G40: =$B29*G$25*G29 -> 0 | H40: =$B29*H$25*H29 -> 0 | I40: =$B29*I$25*I29 -> 0 | J40: =$B29*J$25*J29 -> 0 | K40: =$B29*K$25*K29 -> 0 | L40: =$B29*L$25*L29 -> 0
C41: 4 | D41: =$B30*D$25*D30 -> 0 | E41: =$B30*E$25*E30 -> 0 | F41: =$B30*F$25*F30 -> 0 | G41: =$B30*G$25*G30 -> 0 | H41: =$B30*H$25*H30 -> 0 | I41: =$B30*I$25*I30 -> 0 | J41: =$B30*J$25*J30 -> 0 | K41: =$B30*K$25*K30 -> 0 | L41: =$B30*L$25*L30 -> 0
C42: 5 | D42: =$B31*D$25*D31 -> 0 | E42: =$B31*E$25*E31 -> 0 | F42: =$B31*F$25*F31 -> 0 | G42: =$B31*G$25*G31 -> 0 | H42: =$B31*H$25*H31 -> 0 | I42: =$B31*I$25*I31 -> 0 | J42: =$B31*J$25*J31 -> 0 | K42: =$B31*K$25*K31 -> 0 | L42: =$B31*L$25*L31 -> 0
C43: 6 | D43: =$B32*D$25*D32 -> 0 | E43: =$B32*E$25*E32 -> 0 | F43: =$B32*F$25*F32 -> 0 | G43: =$B32*G$25*G32 -> 0 | H43: =$B32*H$25*H32 -> 0 | I43: =$B32*I$25*I32 -> 0 | J43: =$B32*J$25*J32 -> 0 | K43: =$B32*K$25*K32 -> 0 | L43: =$B32*L$25*L32 -> 0
C44: 7 | D44: =$B33*D$25*D33 -> 0 | E44: =$B33*E$25*E33 -> 0 | F44: =$B33*F$25*F33 -> 0 | G44: =$B33*G$25*G33 -> 0 | H44: =$B33*H$25*H33 -> 0 | I44: =$B33*I$25*I33 -> 0 | J44: =$B33*J$25*J33 -> 0 | K44: =$B33*K$25*K33 -> 0 | L44: =$B33*L$25*L33 -> 0
C45: 8 | D45: =$B34*D$25*D34 -> 0 | E45: =$B34*E$25*E34 -> 0 | F45: =$B34*F$25*F34 -> 0 | G45: =$B34*G$25*G34 -> 0 | H45: =$B34*H$25*H34 -> 0 | I45: =$B34*I$25*I34 -> 0 | J45: =$B34*J$25*J34 -> 0 | K45: =$B34*K$25*K34 -> 0 | L45: =$B34*L$25*L34 -> 0
C46: 9 | D46: =$B35*D$25*D35 -> 0 | E46: =$B35*E$25*E35 -> 0 | F46: =$B35*F$25*F35 -> 0 | G46: =$B35*G$25*G35 -> 0 | H46: =$B35*H$25*H35 -> 0 | I46: =$B35*I$25*I35 -> 0 | J46: =$B35*J$25*J35 -> 0 | K46: =$B35*K$25*K35 -> 0 | L46: =$B35*L$25*L35 -> 0
B48: Standard deviation of portfolio return | D48: =SQRT(SUM(D38:L46)) -> 0
...

Sheet Constant elasticity 
B1: FINDING PARAMETERS IN A CONSTANT ELASTICITY DEMAND FUNCTION
B3: INPUT
C5: Price | D5: Demand
C6: 70 | D6: 400
C7: 80 | D7: 300 | J7: Price | K7: Demand
J8: 70 | K8: =$C$11*J8^$C$12 -> 0
B9: DECISION VARIABLES | J9: 72 | K9: =$C$11*J9^$C$12 -> 0
J10: 74 | K10: =$C$11*J10^$C$12 -> 0
B11: a | J11: 76 | K11: =$C$11*J11^$C$12 -> 0
B12: b | J12: 78 | K12: =$C$11*J12^$C$12 -> 0
J13: 80 | K13: =$C$11*J13^$C$12 -> 0
B14: CALCULATED VARIABLE | J14: 82 | K14: =$C$11*J14^$C$12 -> 0
J15: 84 | K15: =$C$11*J15^$C$12 -> 0
E16: Predicted demand | J16: 86 | K16: =$C$11*J16^$C$12 -> 0
C17: Price | D17: Demand | J17: 88 | K17: =$C$11*J17^$C$12 -> 0
C18: =C6 -> 70 | D18: =D6 -> 400 | E18: =C$11*C18^C$12 -> 0 | J18: 90 | K18: =$C$11*J18^$C$12 -> 0
C19: =C7 -> 80 | D19: =D7 -> 300 | E19: =C$11*C19^C$12 -> 0
B21: OBJECTIVE FUNCTION
C23: Minimise the sum of squared differences

Sheet Pricing model
B1: PRICING MODELS
B3: INPUT
B5: Cost per unit | D5: 50
B6: Parameter values
C7: a
C8: b
B10: DECISION VARIABLE
C12: Price
B14: OBJECTIVE FUNCTION
C16: Maximise profit
B18: CONSTRAINT
D19: LHS | F19: RHS
E20: ≥ | F20: 0 | H20: (non-zero profit constraint)

Sheet Modified Exp
B1: FINDING PARAMETERS VALUES IN A MODIFIED EXPONENTIAL RESPONSE FUNCTION
B3: INPUT
K4: Predicted
C5: # ads | D5: # exposures | J5: # ads | K5: # exposures
C6: 1 | D6: 4.7 | J6: 0 | K6: =$C$14*(1-EXP(-$C$15*J6)) -> 0
C7: 8 | D7: 22.1 | J7: 20 | K7: =$C$14*(1-EXP(-$C$15*J7)) -> 47.174343
C8: 20 | D8: 48.7 | J8: 40 | K8: =$C$14*(1-EXP(-$C$15*J8)) -> 79.992763
C9: 50 | D9: 90.3 | J9: 60 | K9: =$C$14*(1-EXP(-$C$15*J9)) -> 102.824
C10: 100 | D10: 130.5 | J10: 80 | K10: =$C$14*(1-EXP(-$C$15*J10)) -> 118.70732
J11: 100 | K11: =$C$14*(1-EXP(-$C$15*J11)) -> 129.75709
B12: DECISION VARIABLES | J12: 120 | K12: =$C$14*(1-EXP(-$C$15*J12)) -> 137.44423
J13: 140 | K13: =$C$14*(1-EXP(-$C$15*J13)) -> 142.79204
B14: a | C14: 155.01745 | J14: 160 | K14: =$C$14*(1-EXP(-$C$15*J14)) -> 146.51243
B15: b | C15: 0.018143012 | J15: 180 | K15: =$C$14*(1-EXP(-$C$15*J15)) -> 149.10065
J16: 200 | K16: =$C$14*(1-EXP(-$C$15*J16)) -> 150.90123
B18: CALCULATED VARIABLE
E19: Predicted # exposures
C20: # ads | D20: # exposures
C21: =C6 -> 1 | D21: =D6 -> 4.7 | E21: =$C$14*(1-EXP(-$C$15*C21)) -> 2.7871236
C22: =C7 -> 8 | D22: =D7 -> 22.1 | E22: =$C$14*(1-EXP(-$C$15*C22)) -> 20.943221
C23: =C8 -> 20 | D23: =D8 -> 48.7 | E23: =$C$14*(1-EXP(-$C$15*C23)) -> 47.174343
C24: =C9 -> 50 | D24: =D9 -> 90.3 | E24: =$C$14*(1-EXP(-$C$15*C24)) -> 92.441119
C25: =C10 -> 100 | D25: =D10 -> 130.5 | E25: =$C$14*(1-EXP(-$C$15*C25)) -> 129.75709
B27: OBJECTIVE FUNCTION
B29: Minimise the sum of squared differences | D29: =SUMXMY2(D21:D25,E21:E25) -> 12.461176
B32: CONSTRAINTS
D33: LHS | F33: RHS
D34: =C14 -> 155.01745 | E34: ≥ | F34: 130 | H34: Lower bound on a
D35: =C14 -> 155.01745 | E35: ≤ | F35: 260 | H35: Upper bound on a
D36: =C15 -> 0.018143012 | E36: ≥ | F36: 0.0001 | H36: Lower bound on b
D37: =C15 -> 0.018143012 | E37: ≤ | F37: 1 | H37: Upper bound on b

Sheet Ad model
B1: ADVERTISING SELECTION WITH NONLINEAR CONSTRAINTS
B3: INPUTS
B4: Constant (a) in response function
B6: Segments | C6: A | D6: B | E6: C | G6: Min exposures
B7: Women 18-35 | C7: 105.803 | D7: 40.113 | E7: 66.998 | G7: 60
B8: Women 36-55 | C8: 71.784 | D8: 26.534 | E8: 46.146 | G8: 60
B9: Women >55 | C9: 56.828 | D9: 17.209 | E9: 8.887 | G9: 28
B11: Coefficient (b) of exponent in response function
B12: Segments | C12: A | D12: B | E12: C
B13: Women 18-35 | C13: 0.035 | D13: 0.063 | E13: 0.069
B14: Women 36-55 | C14: 0.089 | D14: 0.057 | E14: 0.061
B15: Women >55 | C15: 0.01 | D15: 0.033 | E15: 0.078
B17: Cost per ad | C17: 140 | D17: 100 | E17: 80
B19: DECISION VARIABLES
C20: A | D20: B | E20: C
B21: No. ads
B23: CALCULATED VARIABLES
B25: Exposures to each group from each show
B26: Segments | C26: A | D26: B | E26: C
B27: Women 18-35 | C27: =C7*(1-EXP(-C13*C$21)) -> 0 | D27: =D7*(1-EXP(-D13*D$21)) -> 0 | E27: =E7*(1-EXP(-E13*E$21)) -> 0
B28: Women 36-55 | C28: =C8*(1-EXP(-C14*C$21)) -> 0 | D28: =D8*(1-EXP(-D14*D$21)) -> 0 | E28: =E8*(1-EXP(-E14*E$21)) -> 0
B29: Women >55 | C29: =C9*(1-EXP(-C15*C$21)) -> 0 | D29: =D9*(1-EXP(-D15*D$21)) -> 0 | E29: =E9*(1-EXP(-E15*E$21)) -> 0
B31: OBJECTIVE FUNCTION
B32: Total cost ($'000)
B34: CONSTRAINTS
B35: Segments | C35: LHS | E35: RHS
B36: Women 18-35 | C36: =SUM(C27:E27) -> 0 | D36: ≥ | E36: =G7 -> 60
B37: Women 36-55 | C37: =SUM(C28:E28) -> 0 | D37: ≥ | E37: =G8 -> 60
B38: Women >55 | C38: =SUM(C29:E29) -> 0 | D38: ≥ | E38: =G9 -> 28

Sheet Location model
B1: FACILITY LOCATION MODELS
B3: INPUTS
B5: Customer | C5: X-coordinate | D5: Y-coordinate | E5: Shipments per year | M5: x-coordinate | N5: y-coordinate
B6: 1 | C6: 5 | D6: 10 | E6: 200 | L6: Customer 1 | M6: =C6 -> 5 | N6: =D6 -> 10
B7: 2 | C7: 10 | D7: 5 | E7: 150 | L7: Customer 2 | M7: =C7 -> 10 | N7: =D7 -> 5
B8: 3 | C8: 0 | D8: 12 | E8: 200 | L8: Customer 3 | M8: =C8 -> 0 | N8: =D8 -> 12
B9: 4 | C9: 12 | D9: 0 | E9: 300 | L9: Customer 4 | M9: =C9 -> 12 | N9: =D9 -> 0
L10: Warehouse | M10: =C14 -> 9.3141693 | N10: =D14 -> 5.0287012
B11: DECISION VARIABLES
C13: X-coordinate | D13: Y-coordinate
B14: Warehouse | C14: 9.3141693 | D14: 5.0287012
B16: CALCULATED VARIABLES
B18: Customer | C18: Distance from warehouse
B19: 1 | C19: =SQRT(SUMXMY2(C6:D6,C$14:D$14)) -> 6.5822389
B20: 2 | C20: =SQRT(SUMXMY2(C7:D7,C$14:D$14)) -> 0.68643098
B21: 3 | C21: =SQRT(SUMXMY2(C8:D8,C$14:D$14)) -> 11.63412
B22: 4 | C22: =SQRT(SUMXMY2(C9:D9,C$14:D$14)) -> 5.7010107
B24: OBJECTIVE FUNCTION
B26: Annual distance

Sheet Portfolio model
B1: PORTFOLIO OPTIMISATION MODELS
B3: INPUTS
B5: Stock | C5: 1 | D5: 2 | E5: 3
B6: Mean | C6: 0.14 | D6: 0.11 | E6: 0.1
B8: Cov | C8: 1 | D8: 2 | E8: 3
B9: 1 | C9: 0.04 | D9: 0.018 | E9: 0.0064
B10: 2 | C10: 0.018 | D10: 0.0225 | E10: 0.0084
B11: 3 | C11: 0.0064 | D11: 0.0084 | E11: 0.0064
B13: DECISION VARIABLES
C14: stock 1 | D14: stock 2 | E14: stock 3
B15: Investment weights | C15: 0.49999999 | D15: 0 | E15: 0.50000001
B17: CALCULATED VARIABLES
D19: =C15 -> 0.49999999 | E19: =D15 -> 0 | F19: =E15 -> 0.50000001
C20: Cov | D20: 1 | E20: 2 | F20: 3
B21: =C15 -> 0.49999999 | C21: 1 | D21: 0.04 | E21: 0.018 | F21: 0.0064
B22: =D15 -> 0 | C22: 2 | D22: 0.018 | E22: 0.0225 | F22: 0.0084
B23: =E15 -> 0.50000001 | C23: 3 | D23: 0.0064 | E23: 0.0084 | F23: 0.0064
C25: Portfolio variance terms | D25: 1 | E25: 2 | F25: 3
C26: 1 | D26: =$B21*D$19*D21 -> 0.0099999995 | E26: =$B21*E$19*E21 -> 0 | F26: =$B21*F$19*F21 -> 0.0016
C27: 2 | D27: =$B22*D$19*D22 -> 0 | E27: =$B22*E$19*E22 -> 0 | F27: =$B22*F$19*F22 -> 0
C28: 3 | D28: =$B23*D$19*D23 -> 0.0016 | E28: =$B23*E$19*E23 -> 0 | F28: =$B23*F$19*F23 -> 0.0016000001
C30: Average portfolio return | D30: =SUMPRODUCT(C6:E6,C15:E15) -> 0.12
B32: OBJECTIVE FUNCTION
B34: Standard deviation of portfolio return | D34: =SQRT(SUM(D26:F28)) -> 0.12165525
B37: CONSTRAINTS
B38: LHS | D38: RHS
B39: =D30 -> 0.12 | C39: ≥ | D39: 0.12 | F39: (Minimum expected return of 12%)
B41: =SUM(C15:E15) -> 1 | C41: = | D41: 1 | F41: (Portfolio = 100% of total investment)
