Workbook
Name Number_to_produce: #REF!
Name Selected_hospital: #REF!
Name Unit_costs_of_inputs: #REF!
Name Unit_prices_of_outputs: #REF!

Sheet Instructions
B1: Tasks
B3: In this seminar we will only focus on the four Portfolio model worksheets numbered 0-3.
B4: The other worksheets are included as additional resources to support the Topic 3 lecture notes
A6: 1. | B6: Portfolio model worksheet 0. Data
B7: We have collected monthly stock prices of nine stocks over 4 years (actually 49 months)
B8: Notice that the monthly prices are listed from latest to earliest month.
B10: The first thing we do with these prices is to turn them into returns (there are 48 for each stock)
B11: Next we extract the key statistics for the returns - means and covariances
B13: We average the returns for each stock to estimate the means (see table below the returns)
B15: The covariances can be found by using the Data Analysis tookbox.
B16: If the Data Analysis tookbox is not listed under the Data tab, you will have to add it in as follows: File > Options > Add-ins > Go > Tick Analysis Toolpak and click OK
B18: Excel doesn't print out the full square table of covariances, so we need to
B19: complete the missing "upper triangle" part
B20: This is done in three steps
B21: 1) Select the cells of the table (the square block including the blank cells).
B22: 2) Copy and Paste Special Transpose into some empty space.
... B27: We are now ready to use the means and covariances in our analysis!
A29: 2. | B29: Portfolio model worksheet 1. Minimise risk
B30: This was covered in class for the case of 3 stocks. We repeat it here for the nine stocks under consideration
B31: The aim is to find a set of portfolio weights that minimise risk subject to a minimum expected return of 1%.
A33: 3. | B33: Portfolio model worksheet 2. Maximise return
B34: This is where we maximise return for a given level of risk.
B35: The aim is to find a set of portfolio weights that maximise the portfolio return subject to having a risk that is no greater than 3%.
A37: 4. | B37: Portfolio model worksheet 3. Maximise the Sharpe Ratio
B38: This is where we maximise the Sharpe Ratio = the ratio of the return above the risk free rate of 1.5% divided by the amount of risk assumed
B39: There are no constraints on the expected return or the level of risk assumed.

Sheet 0. Data
B3: STOCK VALUES EACH MONTH - RAW DATA | K3: MONTHLY RETURNS
A4: Date | B4: BHP | C4: RIO | D4: Wesfarmers | E4: Woolworth | F4: NAB | G4: CBA | H4: Westpac | I4: ANZ | J4: Telstra | K4: BHP | L4: RIO | M4: Wesfarmers | N4: Woolworth | O4: NAB | P4: CBA | Q4: Westpac | R4: ANZ | S4: Telstra
A5: 41640 | B5: 35.93 | C5: 63.51 | D5: 43.43 | E5: 34.36 | F5: 34.24 | G5: 76.19 | H5: 31.71 | I5: 30.97 | J5: 5.22 | K5: =(B5-B6)/B6 -> -0.054224796 | L5: =(C5-C6)/C6 -> -0.06849516 | M5: =(D5-D6)/D6 -> -0.013851045 | N5: =(E5-E6)/E6 -> 0.01506647 | O5: =(F5-F6)/F6 -> -0.01693942 | P5: =(G5-G6)/G6 -> -0.020694087 | Q5: =(H5-H6)/H6 -> -0.020691785 | R5: =(I5-I6)/I6 -> -0.039094012 | S5: =(J5-J6)/J6 -> -0.0057142857
A6: 41610 | B6: 37.99 | C6: 68.18 | D6: 44.04 | E6: 33.85 | F6: 34.83 | G6: 77.8 | H6: 32.38 | I6: 32.23 | J6: 5.25 | K6: =(B6-B7)/B7 -> 0.016047071 | L6: =(C6-C7)/C7 -> 0.032092038 | M6: =(D6-D7)/D7 -> 0.026095061 | N6: =(E6-E7)/E7 -> 0.0047491837 | O6: =(F6-F7)/F7 -> 0.0072296125 | P6: =(G6-G7)/G7 -> -0.00025700334 | Q6: =(H6-H7)/H7 -> -0.015206813 | R6: =(I6-I7)/I7 -> 0.010344828 | S6: =(J6-J7)/J7 -> 0.037549407
A7: 41579 | B7: 37.39 | C7: 66.06 | D7: 42.92 | E7: 33.69 | F7: 34.58 | G7: 77.82 | H7: 32.88 | I7: 31.9 | J7: 5.06 | K7: =(B7-B8)/B8 -> -0.0071694105 | L7: =(C7-C8)/C8 -> 0.032348805 | M7: =(D7-D8)/D8 -> -0.025873808 | N7: =(E7-E8)/E8 -> -0.034670487 | O7: =(F7-F8)/F8 -> 0.0064027939 | P7: =(G7-G8)/G8 -> 0.022870662 | Q7: =(H7-H8)/H8 -> -0.015863514 | R7: =(I7-I8)/I8 -> -0.057328605 | S7: =(J7-J8)/J8 -> -0.023166023
A8: 41548 | B8: 37.66 | C8: 63.99 | D8: 44.06 | E8: 34.9 | F8: 34.36 | G8: 76.08 | H8: 33.41 | I8: 33.84 | J8: 5.18 | K8: =(B8-B9)/B9 -> 0.053721321 | L8: =(C8-C9)/C9 -> 0.036443149 | M8: =(D8-D9)/D9 -> 0.044818591 | N8: =(E8-E9)/E9 -> -0.0028571429 | O8: =(F8-F9)/F9 -> 0.029050614 | P8: =(G8-G9)/G9 -> 0.068389271 | Q8: =(H8-H9)/H9 -> 0.047663844 | R8: =(I8-I9)/I9 -> 0.099415205 | S8: =(J8-J9)/J9 -> 0.042253521
A9: 41519 | B9: 35.74 | C9: 61.74 | D9: 42.17 | E9: 35 | F9: 33.39 | G9: 71.21 | H9: 31.89 | I9: 30.78 | J9: 4.97 | K9: =(B9-B10)/B10 -> 0.017943606 | L9: =(C9-C10)/C10 -> 0.059005146 | M9: =(D9-D10)/D10 -> 0.011513552 | N9: =(E9-E10)/E10 -> 0.0014306152 | O9: =(F9-F10)/F10 -> 0.057649667 | P9: =(G9-G10)/G10 -> -0.022377814 | Q9: =(H9-H10)/H10 -> 0.042838457 | R9: =(I9-I10)/I10 -> 0.036712698 | S9: =(J9-J10)/J10 -> 0.014285714
A10: 41487 | B10: 35.11 | C10: 58.3 | D10: 41.69 | E10: 34.95 | F10: 31.57 | G10: 72.84 | H10: 30.58 | I10: 29.69 | J10: 4.9 | K10: =(B10-B11)/B11 -> 0.032039976 | L10: =(C10-C11)/C11 -> 0.013736741 | M10: =(D10-D11)/D11 -> 0.02811344 | N10: =(E10-E11)/E11 -> 0.070444104 | O10: =(F10-F11)/F11 -> 0.038828562 | P10: =(G10-G11)/G11 -> 0.0090040172 | Q10: =(H10-H11)/H11 -> 0.015946844 | R10: =(I10-I11)/I11 -> -0.0023521505 | S10: =(J10-J11)/J11 -> 0.010309278 | V10: BHP | W10: RIO | X10: Wesfarmers | Y10: Woolworth | Z10: NAB | AA10: CBA | AB10: Westpac | AC10: ANZ | AD10: Telstra
A11: 41456 | B11: 34.02 | C11: 57.51 | D11: 40.55 | E11: 32.65 | F11: 30.39 | G11: 72.19 | H11: 30.1 | I11: 29.76 | J11: 4.85 | K11: =(B11-B12)/B12 -> 0.10418695 | L11: =(C11-C12)/C12 -> 0.098147795 | M11: =(D11-D12)/D12 -> 0.024248548 | N11: =(E11-E12)/E12 -> 0.0155521 | O11: =(F11-F12)/F12 -> 0.052285319 | P11: =(G11-G12)/G12 -> 0.072819141 | Q11: =(H11-H12)/H12 -> 0.069651741 | R11: =(I11-I12)/I12 -> 0.041287614 | S11: =(J11-J12)/J12 -> 0.045258621 | U11: BHP | V11: =VARP('0. Data'!$K$5:$K$52) -> 0.0030746779
A12: 41428 | B12: 30.81 | C12: 52.37 | D12: 39.59 | E12: 32.15 | F12: 28.88 | G12: 67.29 | H12: 28.14 | I12: 28.58 | J12: 4.64 | K12: =(B12-B13)/B13 -> -0.10043796 | L12: =(C12-C13)/C13 -> -0.050924248 | M12: =(D12-D13)/D13 -> 0.0091766505 | N12: =(E12-E13)/E13 -> -0.0055675843 | O12: =(F12-F13)/F13 -> 0.023387668 | P12: =(G12-G13)/G13 -> 0.034594096 | Q12: =(H12-H13)/H13 -> 0.015517864 | R12: =(I12-I13)/I13 -> 0.037763253 | S12: =(J12-J13)/J13 -> 0.0065075922 | U12: RIO | V12: 0.0033155393 | W12: =VARP('0. Data'!$L$5:$L$52) -> 0.0046651225
A13: 41395 | B13: 34.25 | C13: 55.18 | D13: 39.23 | E13: 32.33 | F13: 28.22 | G13: 65.04 | H13: 27.71 | I13: 27.54 | J13: 4.61 | K13: =(B13-B14)/B14 -> 0.066645905 | L13: =(C13-C14)/C14 -> -0.011111111 | M13: =(D13-D14)/D14 -> -0.095249077 | N13: =(E13-E14)/E14 -> -0.093890135 | O13: =(F13-F14)/F14 -> -0.12004989 | P13: =(G13-G14)/G14 -> -0.089713086 | Q13: =(H13-H14)/H14 -> -0.1359526 | R13: =(I13-I14)/I14 -> -0.11446945 | S13: =(J13-J14)/J14 -> -0.047520661 | U13: Wesfarmers | V13: 0.00061220991 | W13: 0.00070842477 | X13: =VARP('0. Data'!$M$5:$M$52) -> 0.0024609128
A14: 41365 | B14: 32.11 | C14: 55.8 | D14: 43.36 | E14: 35.68 | F14: 32.07 | G14: 71.45 | H14: 32.07 | I14: 31.1 | J14: 4.84 | K14: =(B14-B15)/B15 -> -0.0018650917 | L14: =(C14-C15)/C15 -> -0.024475524 | M14: =(D14-D15)/D15 -> 0.078875342 | N14: =(E14-E15)/E15 -> 0.077620054 | O14: =(F14-F15)/F15 -> 0.1024407 | P14: =(G14-G15)/G15 -> 0.080120937 | Q14: =(H14-H15)/H15 -> 0.098663926 | R14: =(I14-I15)/I15 -> 0.11589523 | S14: =(J14-J15)/J15 -> 0.10250569 | U14: Woolworth | V14: -0.00017213058 | W14: 4.9754646e-05 | X14: 0.00085114121 | Y14: =VARP('0. Data'!$N$5:$N$52) -> 0.0015983073
A15: 41334 | B15: 32.17 | C15: 57.2 | D15: 40.19 | E15: 33.11 | F15: 29.09 | G15: 66.15 | H15: 29.19 | I15: 27.87 | J15: 4.39 | K15: =(B15-B16)/B16 -> -0.10239955 | L15: =(C15-C16)/C16 -> -0.13438257 | M15: =(D15-D16)/D16 -> -0.020234032 | N15: =(E15-E16)/E16 -> -0.015755054 | O15: =(F15-F16)/F16 -> 0.021060021 | P15: =(G15-G16)/G16 -> 0.011004127 | Q15: =(H15-H16)/H16 -> -0.00034246575 | R15: =(I15-I16)/I16 -> -0.0064171123 | S15: =(J15-J16)/J16 -> -0.015695067 | U15: NAB | V15: 0.0013224223 | W15: 0.0017195254 | X15: 0.0012701524 | Y15: 0.00073257556 | Z15: =VARP('0. Data'!$O$5:$O$52) -> 0.0031031979
A16: 41306 | B16: 35.84 | C16: 66.08 | D16: 41.02 | E16: 33.64 | F16: 28.49 | G16: 65.43 | H16: 29.2 | I16: 28.05 | J16: 4.46 | K16: =(B16-B17)/B17 -> -0.011037528 | L16: =(C16-C17)/C17 -> 0.010397554 | M16: =(D16-D17)/D17 -> 0.11225597 | N16: =(E16-E17)/E17 -> 0.11835106 | O16: =(F16-F17)/F17 -> 0.10383572 | P16: =(G16-G17)/G17 -> 0.069816874 | Q16: =(H16-H17)/H17 -> 0.09733183 | R16: =(I16-I17)/I17 -> 0.080508475 | S16: =(J16-J17)/J17 -> 0.02764977 | U16: CBA | V16: 0.001026195 | W16: 0.0012619543 | X16: 0.0011609457 | Y16: 0.00043191191 | Z16: 0.0020477872 | AA16: =VARP('0. Data'!$P$5:$P$52) -> 0.0021824376
A17: 41275 | B17: 36.24 | C17: 65.4 | D17: 36.88 | E17: 30.08 | F17: 25.81 | G17: 61.16 | H17: 26.61 | I17: 25.96 | J17: 4.34 | K17: =(B17-B18)/B18 -> 0.010315026 | L17: =(C17-C18)/C18 -> 0.0052259453 | M17: =(D17-D18)/D18 -> 0.020475927 | N17: =(E17-E18)/E18 -> 0.065155807 | O17: =(F17-F18)/F18 -> 0.094571671 | P17: =(G17-G18)/G18 -> 0.036610169 | Q17: =(H17-H18)/H18 -> 0.076891947 | R17: =(I17-I18)/I18 -> 0.060890887 | S17: =(J17-J18)/J18 -> 0.053398058 | U17: Westpac | V17: 0.0015652824 | W17: 0.0017138759 | X17: 0.0020398319 | Y17: 0.00080664985 | Z17: 0.0028478908 | AA17: 0.0023458031 | AB17: =VARP('0. Data'!$Q$5:$Q$52) -> 0.00367788
A18: 41246 | B18: 35.87 | C18: 65.06 | D18: 36.14 | E18: 28.24 | F18: 23.58 | G18: 59 | H18: 24.71 | I18: 24.47 | J18: 4.12 | K18: =(B18-B19)/B19 -> 0.078796992 | L18: =(C18-C19)/C19 -> 0.12366149 | M18: =(D18-D19)/D19 -> 0.036420992 | N18: =(E18-E19)/E19 -> 0.0014184397 | O18: =(F18-F19)/F19 -> 0.028795812 | P18: =(G18-G19)/G19 -> 0.041666667 | Q18: =(H18-H19)/H19 -> 0.02107438 | R18: =(I18-I19)/I19 -> 0.028583438 | S18: =(J18-J19)/J19 -> 0.014778325 | U18: ANZ | V18: 0.0014013364 | W18: 0.0017771976 | X18: 0.0017683433 | Y18: 0.00089101512 | Z18: 0.00241692 | AA18: 0.0018602274 | AB18: 0.0027340303 | AC18: =VARP('0. Data'!$R$5:$R$52) -> 0.0028401712
A19: 41214 | B19: 33.25 | C19: 57.9 | D19: 34.87 | E19: 28.2 | F19: 22.92 | G19: 56.64 | H19: 24.2 | I19: 23.79 | J19: 4.06 | K19: =(B19-B20)/B20 -> 0.0042283298 | L19: =(C19-C20)/C20 -> 0.031717748 | M19: =(D19-D20)/D20 -> 0.022580645 | N19: =(E19-E20)/E20 -> 0.0057061341 | O19: =(F19-F20)/F20 -> -0.022601279 | P19: =(G19-G20)/G20 -> 0.033576642 | Q19: =(H19-H20)/H20 -> 0.033304868 | R19: =(I19-I20)/I20 -> -0.0124533 | S19: =(J19-J20)/J20 -> 0.041025641 | U19: Telstra | V19: 0.00012122474 | W19: -0.00025088371 | X19: -6.9123552e-05 | Y19: 8.5979034e-05 | Z19: 0.0007454689 | AA19: 0.00057397731 | AB19: 0.00053933216 | AC19: 0.00040914466 | AD19: =VARP('0. Data'!$S$5:$S$52) -> 0.0017741515
A20: 41183 | B20: 33.11 | C20: 56.12 | D20: 34.1 | E20: 28.04 | F20: 23.45 | G20: 54.8 | H20: 23.42 | I20: 24.09 | J20: 3.9 | K20: =(B20-B21)/B21 -> 0.036631183 | L20: =(C20-C21)/C21 -> 0.067123027 | M20: =(D20-D21)/D21 -> 0.014880952 | N20: =(E20-E21)/E21 -> 0.022611233 | O20: =(F20-F21)/F21 -> 0.011647972 | P20: =(G20-G21)/G21 -> 0.035525321 | Q20: =(H20-H21)/H21 -> 0.026292726 | R20: =(I20-I21)/I21 -> 0.028169014 | S20: =(J20-J21)/J21 -> 0.054054054
A21: 41155 | B21: 31.94 | C21: 52.59 | D21: 33.6 | E21: 27.42 | F21: 23.18 | G21: 52.92 | H21: 22.82 | I21: 23.43 | J21: 3.7 | K21: =(B21-B22)/B22 -> 0.057615894 | L21: =(C21-C22)/C22 -> 0.083659592 | M21: =(D21-D22)/D22 -> -0.0076786769 | N21: =(E21-E22)/E22 -> -0.0068815647 | O21: =(F21-F22)/F22 -> 0.011343805 | P21: =(G21-G22)/G22 -> 0.018867925 | Q21: =(H21-H22)/H22 -> 0.0035180299 | R21: =(I21-I22)/I22 -> -0.0025542784 | S21: =(J21-J22)/J22 -> 0.019283747
A22: 41122 | B22: 30.2 | C22: 48.53 | D22: 33.86 | E22: 27.61 | F22: 22.92 | G22: 51.94 | H22: 22.74 | I22: 23.49 | J22: 3.63 | K22: =(B22-B23)/B23 -> -0.0042861853 | L22: =(C22-C23)/C23 -> -0.063127413 | M22: =(D22-D23)/D23 -> 0.088745981 | N22: =(E22-E23)/E23 -> 0.036800601 | O22: =(F22-F23)/F23 -> 0.0092470277 | P22: =(G22-G23)/G23 -> -0.014795144 | Q22: =(H22-H23)/H23 -> 0.067605634 | R22: =(I22-I23)/I23 -> 0.054308797 | S22: =(J22-J23)/J23 -> -0.0027472527
A23: 41092 | B23: 30.33 | C23: 51.8 | D23: 31.1 | E23: 26.63 | F23: 22.71 | G23: 52.72 | H23: 21.3 | I23: 22.28 | J23: 3.64 | K23: =(B23-B24)/B24 -> 0.015060241 | L23: =(C23-C24)/C24 -> -0.058353027 | M23: =(D23-D24)/D24 -> 0.090080617 | N23: =(E23-E24)/E24 -> 0.066052842 | O23: =(F23-F24)/F24 -> 0.061214953 | P23: =(G23-G24)/G24 -> 0.083436087 | Q23: =(H23-H24)/H24 -> 0.097938144 | R23: =(I23-I24)/I24 -> 0.068585132 | S23: =(J23-J24)/J24 -> 0.083333333
A24: 41061 | B24: 29.88 | C24: 55.01 | D24: 28.53 | E24: 24.98 | F24: 21.4 | G24: 48.66 | H24: 19.4 | I24: 20.85 | J24: 3.36 | K24: =(B24-B25)/B25 -> -0.016134343 | L24: =(C24-C25)/C25 -> -0.0063222543 | M24: =(D24-D25)/D25 -> 0.023681378 | N24: =(E24-E25)/E25 -> 0.013798701 | O24: =(F24-F25)/F25 -> 0.046966732 | P24: =(G24-G25)/G25 -> 0.074884029 | Q24: =(H24-H25)/H25 -> 0.041331186 | R24: =(I24-I25)/I25 -> 0.054095046 | S24: =(J24-J25)/J25 -> 0.040247678
A25: 41030 | B25: 30.37 | C25: 55.36 | D25: 27.87 | E25: 24.64 | F25: 20.44 | G25: 45.27 | H25: 18.63 | I25: 19.78 | J25: 3.23 | K25: =(B25-B26)/B26 -> -0.10068108 | L25: =(C25-C26)/C26 -> -0.14303406 | M25: =(D25-D26)/D26 -> -0.035640138 | N25: =(E25-E26)/E26 -> 0.019023987 | O25: =(F25-F26)/F26 -> -0.073855913 | P25: =(G25-G26)/G26 -> -0.049349013 | Q25: =(H25-H26)/H26 -> -0.074055666 | R25: =(I25-I26)/I26 -> -0.10050023 | S25: =(J25-J26)/J26 -> 0.0031055901
A26: 41001 | B26: 33.77 | C26: 64.6 | D26: 28.9 | E26: 24.18 | F26: 22.07 | G26: 47.62 | H26: 20.12 | I26: 21.99 | J26: 3.22 | K26: =(B26-B27)/B27 -> 0.027068127 | L26: =(C26-C27)/C27 -> 0.014447236 | M26: =(D26-D27)/D27 -> 0.0087260035 | N26: =(E26-E27)/E27 -> -0.0012391574 | O26: =(F26-F27)/F27 -> 0.025557621 | P26: =(G26-G27)/G27 -> 0.037246787 | Q26: =(H26-H27)/H27 -> 0.03871967 | R26: =(I26-I27)/I27 -> 0.028050491 | S26: =(J26-J27)/J27 -> 0.076923077
A27: 40969 | B27: 32.88 | C27: 63.68 | D27: 28.65 | E27: 24.21 | F27: 21.52 | G27: 45.91 | H27: 19.37 | I27: 21.39 | J27: 2.99 | K27: =(B27-B28)/B28 -> -0.041399417 | L27: =(C27-C28)/C28 -> -0.03030303 | M27: =(D27-D28)/D28 -> 0.031688873 | N27: =(E27-E28)/E28 -> 0.05078125 | O27: =(F27-F28)/F28 -> 0.03911154 | P27: =(G27-G28)/G28 -> 0.013689556 | Q27: =(H27-H28)/H28 -> 0.047027027 | R27: =(I27-I28)/I28 -> 0.059960357 | S27: =(J27-J28)/J28 -> -0.0033333333
A28: 40940 | B28: 34.3 | C28: 65.67 | D28: 27.77 | E28: 23.04 | F28: 20.71 | G28: 45.29 | H28: 18.5 | I28: 20.18 | J28: 3 | K28: =(B28-B29)/B29 -> -0.02307035 | L28: =(C28-C29)/C29 -> -0.012481203 | M28: =(D28-D29)/D29 -> -0.01699115 | N28: =(E28-E29)/E29 -> 0.020824103 | O28: =(F28-F29)/F29 -> -0.0076665069 | P28: =(G28-G29)/G29 -> 0.0033229951 | Q28: =(H28-H29)/H29 -> -0.011752137 | R28: =(I28-I29)/I29 -> 0.024885729 | S28: =(J28-J29)/J29 -> 0.034482759
A29: 40910 | B29: 35.11 | C29: 66.5 | D29: 28.25 | E29: 22.57 | F29: 20.87 | G29: 45.14 | H29: 18.72 | I29: 19.69 | J29: 2.9 | K29: =(B29-B30)/B30 -> 0.089019851 | L29: =(C29-C30)/C30 -> 0.14694722 | M29: =(D29-D30)/D30 -> 0.027272727 | N29: =(E29-E30)/E30 -> -0.012253829 | O29: =(F29-F30)/F30 -> 0.021037182 | P29: =(G29-G30)/G30 -> 0.029183767 | Q29: =(H29-H30)/H30 -> 0.057627119 | R29: =(I29-I30)/I30 -> 0.042902542 | S29: =(J29-J30)/J30 -> 0
A30: 40878 | B30: 32.24 | C30: 57.98 | D30: 27.5 | E30: 22.85 | F30: 20.44 | G30: 43.86 | H30: 17.7 | I30: 18.88 | J30: 2.9 | K30: =(B30-B31)/B31 -> -0.014368695 | L30: =(C30-C31)/C31 -> -0.04212787 | M30: =(D30-D31)/D31 -> -0.032371569 | N30: =(E30-E31)/E31 -> 0.019634092 | O30: =(F30-F31)/F31 -> -0.001953125 | P30: =(G30-G31)/G31 -> 0.038352273 | Q30: =(H30-H31)/H31 -> -0.027472527 | R30: =(I30-I31)/I31 -> 0.031693989 | S30: =(J30-J31)/J31 -> 0.050724638
A31: 40848 | B31: 32.71 | C31: 60.53 | D31: 28.42 | E31: 22.41 | F31: 20.48 | G31: 42.24 | H31: 18.2 | I31: 18.3 | J31: 2.76 | K31: =(B31-B32)/B32 -> -0.076249647 | L31: =(C31-C32)/C32 -> -0.090458302 | M31: =(D31-D32)/D32 -> -0.060806345 | N31: =(E31-E32)/E32 -> 0.033671587 | O31: =(F31-F32)/F32 -> -0.057090239 | P31: =(G31-G32)/G32 -> -0.037813212 | Q31: =(H31-H32)/H32 -> -0.044117647 | R31: =(I31-I32)/I32 -> -0.048856549 | S31: =(J31-J32)/J32 -> 0.022222222
... A52: 40210 | B52: 36.72 | C52: 66.36 | D52: 27.06 | E52: 22.35 | F52: 19.57 | G52: 43.59 | H52: 20.34 | I52: 18.96 | J52: 2.24 | K52: =(B52-B53)/B53 -> 0.043181818 | L52: =(C52-C53)/C53 -> 0.044217152 | M52: =(D52-D53)/D53 -> 0.1505102 | N52: =(E52-E53)/E53 -> 0.037604457 | O52: =(F52-F53)/F53 -> -0.035485461 | P52: =(G52-G53)/G53 -> 0.036623068 | Q52: =(H52-H53)/H53 -> 0.094725511 | R52: =(I52-I53)/I53 -> 0.064570466 | S52: =(J52-J53)/J53 -> -0.070539419
A53: 40182 | B53: 35.2 | C53: 63.55 | D53: 23.52 | E53: 21.54 | F53: 20.29 | G53: 42.05 | H53: 18.58 | I53: 17.81 | J53: 2.41
K55: BHP | L55: RIO | M55: Wesfarmers | N55: Woolworth | O55: NAB | P55: CBA | Q55: Westpac | R55: ANZ | S55: Telstra
J56: Average Return over 48 months | K56: =AVERAGE(K5:K52) -> 0.0019785721 | L56: =AVERAGE(L5:L52) -> 0.0023362823 | M56: =AVERAGE(M5:M52) -> 0.014068687 | N56: =AVERAGE(N5:N52) -> 0.010566461 | O56: =AVERAGE(O5:O52) -> 0.012509884 | P56: =AVERAGE(P5:P52) -> 0.013562733 | Q56: =AVERAGE(Q5:Q52) -> 0.013059285 | R56: =AVERAGE(R5:R52) -> 0.013010327 | S56: =AVERAGE(S5:S52) -> 0.017118669

Sheet 1. Minimise risk
B1: PORTFOLIO OPTIMISATION MODELS
C3: INPUTS
C5: Stock | D5: 1 | E5: 2 | F5: 3 | G5: 4 | H5: 5 | I5: 6 | J5: 7 | K5: 8 | L5: 9
C6: Mean | D6: ='0. Data'!K56 -> 0.0019785721 | E6: ='0. Data'!L56 -> 0.0023362823 | F6: ='0. Data'!M56 -> 0.014068687 | G6: ='0. Data'!N56 -> 0.010566461 | H6: ='0. Data'!O56 -> 0.012509884 | I6: ='0. Data'!P56 -> 0.013562733 | J6: ='0. Data'!Q56 -> 0.013059285 | K6: ='0. Data'!R56 -> 0.013010327 | L6: ='0. Data'!S56 -> 0.017118669
C8: Cov | D8: 1 | E8: 2 | F8: 3 | G8: 4 | H8: 5 | I8: 6 | J8: 7 | K8: 8 | L8: 9
C9: 1 | D9: 0.0030746779 | E9: 0.0033155393 | F9: 0.00061220991 | G9: -0.00017213058 | H9: 0.0013224223 | I9: 0.001026195 | J9: 0.0015652824 | K9: 0.0014013364 | L9: 0.00012122474
C10: 2 | D10: 0.0033155393 | E10: 0.0046651225 | F10: 0.00070842477 | G10: 4.9754646e-05 | H10: 0.0017195254 | I10: 0.0012619543 | J10: 0.0017138759 | K10: 0.0017771976 | L10: -0.00025088371
C11: 3 | D11: 0.00061220991 | E11: 0.00070842477 | F11: 0.0024609128 | G11: 0.00085114121 | H11: 0.0012701524 | I11: 0.0011609457 | J11: 0.0020398319 | K11: 0.0017683433 | L11: -6.9123552e-05
C12: 4 | D12: -0.00017213058 | E12: 4.9754646e-05 | F12: 0.00085114121 | G12: 0.0015983073 | H12: 0.00073257556 | I12: 0.00043191191 | J12: 0.00080664985 | K12: 0.00089101512 | L12: 8.5979034e-05
C13: 5 | D13: 0.0013224223 | E13: 0.0017195254 | F13: 0.0012701524 | G13: 0.00073257556 | H13: 0.0031031979 | I13: 0.0020477872 | J13: 0.0028478908 | K13: 0.00241692 | L13: 0.0007454689
C14: 6 | D14: 0.001026195 | E14: 0.0012619543 | F14: 0.0011609457 | G14: 0.00043191191 | H14: 0.0020477872 | I14: 0.0021824376 | J14: 0.0023458031 | K14: 0.0018602274 | L14: 0.00057397731
C15: 7 | D15: 0.0015652824 | E15: 0.0017138759 | F15: 0.0020398319 | G15: 0.00080664985 | H15: 0.0028478908 | I15: 0.0023458031 | J15: 0.00367788 | K15: 0.0027340303 | L15: 0.00053933216
C16: 8 | D16: 0.0014013364 | E16: 0.0017771976 | F16: 0.0017683433 | G16: 0.00089101512 | H16: 0.00241692 | I16: 0.0018602274 | J16: 0.0027340303 | K16: 0.0028401712 | L16: 0.00040914466
C17: 9 | D17: 0.00012122474 | E17: -0.00025088371 | F17: -6.9123552e-05 | G17: 8.5979034e-05 | H17: 0.0007454689 | I17: 0.00057397731 | J17: 0.00053933216 | K17: 0.00040914466 | L17: 0.0017741515
B19: DECISION VARIABLES
D20: stock 1 | E20: stock 2 | F20: stock 3 | G20: stock 4 | H20: stock 5 | I20: stock 6 | J20: stock 7 | K20: stock 8 | L20: stock 9
C21: Investment weights | D21: 0.19882969 | E21: 0 | F21: 0.10203107 | G21: 0.35766269 | H21: 0 | I21: 0 | J21: 0 | K21: 0 | L21: 0.34147655
B23: CALCULATED VARIABLES
D25: =D21 -> 0.19882969 | E25: =E21 -> 0 | F25: =F21 -> 0.10203107 | G25: =G21 -> 0.35766269 | H25: =H21 -> 0 | I25: =I21 -> 0 | J25: =J21 -> 0 | K25: =K21 -> 0 | L25: =L21 -> 0.34147655
C26: Cov | D26: 1 | E26: 2 | F26: 3 | G26: 4 | H26: 5 | I26: 6 | J26: 7 | K26: 8 | L26: 9
B27: =D21 -> 0.19882969 | C27: 1 | D27: =D9 -> 0.0030746779 | E27: =E9 -> 0.0033155393 | F27: =F9 -> 0.00061220991 | G27: =G9 -> -0.00017213058 | H27: =H9 -> 0.0013224223 | I27: =I9 -> 0.001026195 | J27: =J9 -> 0.0015652824 | K27: =K9 -> 0.0014013364 | L27: =L9 -> 0.00012122474
B28: =E21 -> 0 | C28: 2 | D28: =D10 -> 0.0033155393 | E28: =E10 -> 0.0046651225 | F28: =F10 -> 0.00070842477 | G28: =G10 -> 4.9754646e-05 | H28: =H10 -> 0.0017195254 | I28: =I10 -> 0.0012619543 | J28: =J10 -> 0.0017138759 | K28: =K10 -> 0.0017771976 | L28: =L10 -> -0.00025088371
B29: =F21 -> 0.10203107 | C29: 3 | D29: =D11 -> 0.00061220991 | E29: =E11 -> 0.00070842477 | F29: =F11 -> 0.0024609128 | G29: =G11 -> 0.00085114121 | H29: =H11 -> 0.0012701524 | I29: =I11 -> 0.0011609457 | J29: =J11 -> 0.0020398319 | K29: =K11 -> 0.0017683433 | L29: =L11 -> -6.9123552e-05
B30: =G21 -> 0.35766269 | C30: 4 | D30: =D12 -> -0.00017213058 | E30: =E12 -> 4.9754646e-05 | F30: =F12 -> 0.00085114121 | G30: =G12 -> 0.0015983073 | H30: =H12 -> 0.00073257556 | I30: =I12 -> 0.00043191191 | J30: =J12 -> 0.00080664985 | K30: =K12 -> 0.00089101512 | L30: =L12 -> 8.5979034e-05
B31: =H21 -> 0 | C31: 5 | D31: =D13 -> 0.0013224223 | E31: =E13 -> 0.0017195254 | F31: =F13 -> 0.0012701524 | G31: =G13 -> 0.00073257556 | H31: =H13 -> 0.0031031979 | I31: =I13 -> 0.0020477872 | J31: =J13 -> 0.0028478908 | K31: =K13 -> 0.00241692 | L31: =L13 -> 0.0007454689
B32: =I21 -> 0 | C32: 6 | D32: =D14 -> 0.001026195 | E32: =E14 -> 0.0012619543 | F32: =F14 -> 0.0011609457 | G32: =G14 -> 0.00043191191 | H32: =H14 -> 0.0020477872 | I32: =I14 -> 0.0021824376 | J32: =J14 -> 0.0023458031 | K32: =K14 -> 0.0018602274 | L32: =L14 -> 0.00057397731
B33: =J21 -> 0 | C33: 7 | D33: =D15 -> 0.0015652824 | E33: =E15 -> 0.0017138759 | F33: =F15 -> 0.0020398319 | G33: =G15 -> 0.00080664985 | H33: =H15 -> 0.0028478908 | I33: =I15 -> 0.0023458031 | J33: =J15 -> 0.00367788 | K33: =K15 -> 0.0027340303 | L33: =L15 -> 0.00053933216
B34: =K21 -> 0 | C34: 8 | D34: =D16 -> 0.0014013364 | E34: =E16 -> 0.0017771976 | F34: =F16 -> 0.0017683433 | G34: =G16 -> 0.00089101512 | H34: =H16 -> 0.00241692 | I34: =I16 -> 0.0018602274 | J34: =J16 -> 0.0027340303 | K34: =K16 -> 0.0028401712 | L34: =L16 -> 0.00040914466
B35: =L21 -> 0.34147655 | C35: 9 | D35: =D17 -> 0.00012122474 | E35: =E17 -> -0.00025088371 | F35: =F17 -> -6.9123552e-05 | G35: =G17 -> 8.5979034e-05 | H35: =H17 -> 0.0007454689 | I35: =I17 -> 0.00057397731 | J35: =J17 -> 0.00053933216 | K35: =K17 -> 0.00040914466 | L35: =L17 -> 0.0017741515
C37: Portfolio variance terms | D37: 1 | E37: 2 | F37: 3 | G37: 4 | H37: 5 | I37: 6 | J37: 7 | K37: 8 | L37: 9
B38: Standard devioan of the portfolio | C38: 1 | D38: =$B27*D$25*D27 -> 0.000121552 | E38: =$B27*E$25*E27 -> 0 | F38: =$B27*F$25*F27 -> 1.2419784e-05 | G38: =$B27*G$25*G27 -> -1.2240887e-05 | H38: =$B27*H$25*H27 -> 0 | I38: =$B27*I$25*I27 -> 0 | J38: =$B27*J$25*J27 -> 0 | K38: =$B27*K$25*K27 -> 0 | L38: =$B27*L$25*L27 -> 8.2306357e-06
C39: 2 | D39: =$B28*D$25*D28 -> 0 | E39: =$B28*E$25*E28 -> 0 | F39: =$B28*F$25*F28 -> 0 | G39: =$B28*G$25*G28 -> 0 | H39: =$B28*H$25*H28 -> 0 | I39: =$B28*I$25*I28 -> 0 | J39: =$B28*J$25*J28 -> 0 | K39: =$B28*K$25*K28 -> 0 | L39: =$B28*L$25*L28 -> 0
C40: 3 | D40: =$B29*D$25*D29 -> 1.2419784e-05 | E40: =$B29*E$25*E29 -> 0 | F40: =$B29*F$25*F29 -> 2.5618938e-05 | G40: =$B29*G$25*G29 -> 3.1060447e-05 | H40: =$B29*H$25*H29 -> 0 | I40: =$B29*I$25*I29 -> 0 | J40: =$B29*J$25*J29 -> 0 | K40: =$B29*K$25*K29 -> 0 | L40: =$B29*L$25*L29 -> -2.4083488e-06
C41: 4 | D41: =$B30*D$25*D30 -> -1.2240887e-05 | E41: =$B30*E$25*E30 -> 0 | F41: =$B30*F$25*F30 -> 3.1060447e-05 | G41: =$B30*G$25*G30 -> 0.00020445962 | H41: =$B30*H$25*H30 -> 0 | I41: =$B30*I$25*I30 -> 0 | J41: =$B30*J$25*J30 -> 0 | K41: =$B30*K$25*K30 -> 0 | L41: =$B30*L$25*L30 -> 1.0500914e-05
C42: 5 | D42: =$B31*D$25*D31 -> 0 | E42: =$B31*E$25*E31 -> 0 | F42: =$B31*F$25*F31 -> 0 | G42: =$B31*G$25*G31 -> 0 | H42: =$B31*H$25*H31 -> 0 | I42: =$B31*I$25*I31 -> 0 | J42: =$B31*J$25*J31 -> 0 | K42: =$B31*K$25*K31 -> 0 | L42: =$B31*L$25*L31 -> 0
C43: 6 | D43: =$B32*D$25*D32 -> 0 | E43: =$B32*E$25*E32 -> 0 | F43: =$B32*F$25*F32 -> 0 | G43: =$B32*G$25*G32 -> 0 | H43: =$B32*H$25*H32 -> 0 | I43: =$B32*I$25*I32 -> 0 | J43: =$B32*J$25*J32 -> 0 | K43: =$B32*K$25*K32 -> 0 | L43: =$B32*L$25*L32 -> 0
C44: 7 | D44: =$B33*D$25*D33 -> 0 | E44: =$B33*E$25*E33 -> 0 | F44: =$B33*F$25*F33 -> 0 | G44: =$B33*G$25*G33 -> 0 | H44: =$B33*H$25*H33 -> 0 | I44: =$B33*I$25*I33 -> 0 | J44: =$B33*J$25*J33 -> 0 | K44: =$B33*K$25*K33 -> 0 | L44: =$B33*L$25*L33 -> 0
C45: 8 | D45: =$B34*D$25*D34 -> 0 | E45: =$B34*E$25*E34 -> 0 | F45: =$B34*F$25*F34 -> 0 | G45: =$B34*G$25*G34 -> 0 | H45: =$B34*H$25*H34 -> 0 | I45: =$B34*I$25*I34 -> 0 | J45: =$B34*J$25*J34 -> 0 | K45: =$B34*K$25*K34 -> 0 | L45: =$B34*L$25*L34 -> 0
C46: 9 | D46: =$B35*D$25*D35 -> 8.2306357e-06 | E46: =$B35*E$25*E35 -> 0 | F46: =$B35*F$25*F35 -> -2.4083488e-06 | G46: =$B35*G$25*G35 -> 1.0500914e-05 | H46: =$B35*H$25*H35 -> 0 | I46: =$B35*I$25*I35 -> 0 | J46: =$B35*J$25*J35 -> 0 | K46: =$B35*K$25*K35 -> 0 | L46: =$B35*L$25*L35 -> 0.00020687713
C48: Average portfolio return | D48: =SUMPRODUCT(D6:L6,D21:L21) -> 0.011453695
...

Sheet 2. Maximise return
B1: PORTFOLIO OPTIMISATION MODELS
C3: INPUTS
C5: Stock | D5: 1 | E5: 2 | F5: 3 | G5: 4 | H5: 5 | I5: 6 | J5: 7 | K5: 8 | L5: 9
C6: Mean | D6: ='0. Data'!K56 -> 0.0019785721 | E6: ='0. Data'!L56 -> 0.0023362823 | F6: ='0. Data'!M56 -> 0.014068687 | G6: ='0. Data'!N56 -> 0.010566461 | H6: ='0. Data'!O56 -> 0.012509884 | I6: ='0. Data'!P56 -> 0.013562733 | J6: ='0. Data'!Q56 -> 0.013059285 | K6: ='0. Data'!R56 -> 0.013010327 | L6: ='0. Data'!S56 -> 0.017118669
C8: Cov | D8: 1 | E8: 2 | F8: 3 | G8: 4 | H8: 5 | I8: 6 | J8: 7 | K8: 8 | L8: 9
C9: 1 | D9: 0.0030746779 | E9: 0.0033155393 | F9: 0.00061220991 | G9: -0.00017213058 | H9: 0.0013224223 | I9: 0.001026195 | J9: 0.0015652824 | K9: 0.0014013364 | L9: 0.00012122474
C10: 2 | D10: 0.0033155393 | E10: 0.0046651225 | F10: 0.00070842477 | G10: 4.9754646e-05 | H10: 0.0017195254 | I10: 0.0012619543 | J10: 0.0017138759 | K10: 0.0017771976 | L10: -0.00025088371
C11: 3 | D11: 0.00061220991 | E11: 0.00070842477 | F11: 0.0024609128 | G11: 0.00085114121 | H11: 0.0012701524 | I11: 0.0011609457 | J11: 0.0020398319 | K11: 0.0017683433 | L11: -6.9123552e-05
C12: 4 | D12: -0.00017213058 | E12: 4.9754646e-05 | F12: 0.00085114121 | G12: 0.0015983073 | H12: 0.00073257556 | I12: 0.00043191191 | J12: 0.00080664985 | K12: 0.00089101512 | L12: 8.5979034e-05
C13: 5 | D13: 0.0013224223 | E13: 0.0017195254 | F13: 0.0012701524 | G13: 0.00073257556 | H13: 0.0031031979 | I13: 0.0020477872 | J13: 0.0028478908 | K13: 0.00241692 | L13: 0.0007454689
C14: 6 | D14: 0.001026195 | E14: 0.0012619543 | F14: 0.0011609457 | G14: 0.00043191191 | H14: 0.0020477872 | I14: 0.0021824376 | J14: 0.0023458031 | K14: 0.0018602274 | L14: 0.00057397731
C15: 7 | D15: 0.0015652824 | E15: 0.0017138759 | F15: 0.0020398319 | G15: 0.00080664985 | H15: 0.0028478908 | I15: 0.0023458031 | J15: 0.00367788 | K15: 0.0027340303 | L15: 0.00053933216
C16: 8 | D16: 0.0014013364 | E16: 0.0017771976 | F16: 0.0017683433 | G16: 0.00089101512 | H16: 0.00241692 | I16: 0.0018602274 | J16: 0.0027340303 | K16: 0.0028401712 | L16: 0.00040914466
C17: 9 | D17: 0.00012122474 | E17: -0.00025088371 | F17: -6.9123552e-05 | G17: 8.5979034e-05 | H17: 0.0007454689 | I17: 0.00057397731 | J17: 0.00053933216 | K17: 0.00040914466 | L17: 0.0017741515
B19: DECISION VARIABLES
D20: stock 1 | E20: stock 2 | F20: stock 3 | G20: stock 4 | H20: stock 5 | I20: stock 6 | J20: stock 7 | K20: stock 8 | L20: stock 9
C21: Investment weights | D21: 0 | E21: 0 | F21: 0.28975286 | G21: 0.10963732 | H21: 0 | I21: 0.011532669 | J21: 0 | K21: 0 | L21: 0.58907715
B23: CALCULATED VARIABLES
D25: =D21 -> 0 | E25: =E21 -> 0 | F25: =F21 -> 0.28975286 | G25: =G21 -> 0.10963732 | H25: =H21 -> 0 | I25: =I21 -> 0.011532669 | J25: =J21 -> 0 | K25: =K21 -> 0 | L25: =L21 -> 0.58907715
C26: Cov | D26: 1 | E26: 2 | F26: 3 | G26: 4 | H26: 5 | I26: 6 | J26: 7 | K26: 8 | L26: 9
B27: =D21 -> 0 | C27: 1 | D27: =D9 -> 0.0030746779 | E27: =E9 -> 0.0033155393 | F27: =F9 -> 0.00061220991 | G27: =G9 -> -0.00017213058 | H27: =H9 -> 0.0013224223 | I27: =I9 -> 0.001026195 | J27: =J9 -> 0.0015652824 | K27: =K9 -> 0.0014013364 | L27: =L9 -> 0.00012122474
B28: =E21 -> 0 | C28: 2 | D28: =D10 -> 0.0033155393 | E28: =E10 -> 0.0046651225 | F28: =F10 -> 0.00070842477 | G28: =G10 -> 4.9754646e-05 | H28: =H10 -> 0.0017195254 | I28: =I10 -> 0.0012619543 | J28: =J10 -> 0.0017138759 | K28: =K10 -> 0.0017771976 | L28: =L10 -> -0.00025088371
B29: =F21 -> 0.28975286 | C29: 3 | D29: =D11 -> 0.00061220991 | E29: =E11 -> 0.00070842477 | F29: =F11 -> 0.0024609128 | G29: =G11 -> 0.00085114121 | H29: =H11 -> 0.0012701524 | I29: =I11 -> 0.0011609457 | J29: =J11 -> 0.0020398319 | K29: =K11 -> 0.0017683433 | L29: =L11 -> -6.9123552e-05
B30: =G21 -> 0.10963732 | C30: 4 | D30: =D12 -> -0.00017213058 | E30: =E12 -> 4.9754646e-05 | F30: =F12 -> 0.00085114121 | G30: =G12 -> 0.0015983073 | H30: =H12 -> 0.00073257556 | I30: =I12 -> 0.00043191191 | J30: =J12 -> 0.00080664985 | K30: =K12 -> 0.00089101512 | L30: =L12 -> 8.5979034e-05
B31: =H21 -> 0 | C31: 5 | D31: =D13 -> 0.0013224223 | E31: =E13 -> 0.0017195254 | F31: =F13 -> 0.0012701524 | G31: =G13 -> 0.00073257556 | H31: =H13 -> 0.0031031979 | I31: =I13 -> 0.0020477872 | J31: =J13 -> 0.0028478908 | K31: =K13 -> 0.00241692 | L31: =L13 -> 0.0007454689
B32: =I21 -> 0.011532669 | C32: 6 | D32: =D14 -> 0.001026195 | E32: =E14 -> 0.0012619543 | F32: =F14 -> 0.0011609457 | G32: =G14 -> 0.00043191191 | H32: =H14 -> 0.0020477872 | I32: =I14 -> 0.0021824376 | J32: =J14 -> 0.0023458031 | K32: =K14 -> 0.0018602274 | L32: =L14 -> 0.00057397731
B33: =J21 -> 0 | C33: 7 | D33: =D15 -> 0.0015652824 | E33: =E15 -> 0.0017138759 | F33: =F15 -> 0.0020398319 | G33: =G15 -> 0.00080664985 | H33: =H15 -> 0.0028478908 | I33: =I15 -> 0.0023458031 | J33: =J15 -> 0.00367788 | K33: =K15 -> 0.0027340303 | L33: =L15 -> 0.00053933216
B34: =K21 -> 0 | C34: 8 | D34: =D16 -> 0.0014013364 | E34: =E16 -> 0.0017771976 | F34: =F16 -> 0.0017683433 | G34: =G16 -> 0.00089101512 | H34: =H16 -> 0.00241692 | I34: =I16 -> 0.0018602274 | J34: =J16 -> 0.0027340303 | K34: =K16 -> 0.0028401712 | L34: =L16 -> 0.00040914466
B35: =L21 -> 0.58907715 | C35: 9 | D35: =D17 -> 0.00012122474 | E35: =E17 -> -0.00025088371 | F35: =F17 -> -6.9123552e-05 | G35: =G17 -> 8.5979034e-05 | H35: =H17 -> 0.0007454689 | I35: =I17 -> 0.00057397731 | J35: =J17 -> 0.00053933216 | K35: =K17 -> 0.00040914466 | L35: =L17 -> 0.0017741515
C37: Portfolio variance terms | D37: 1 | E37: 2 | F37: 3 | G37: 4 | H37: 5 | I37: 6 | J37: 7 | K37: 8 | L37: 9
B38: Standard devioan of the portfolio | C38: 1 | D38: =$B27*D$25*D27 -> 0 | E38: =$B27*E$25*E27 -> 0 | F38: =$B27*F$25*F27 -> 0 | G38: =$B27*G$25*G27 -> 0 | H38: =$B27*H$25*H27 -> 0 | I38: =$B27*I$25*I27 -> 0 | J38: =$B27*J$25*J27 -> 0 | K38: =$B27*K$25*K27 -> 0 | L38: =$B27*L$25*L27 -> 0
C39: 2 | D39: =$B28*D$25*D28 -> 0 | E39: =$B28*E$25*E28 -> 0 | F39: =$B28*F$25*F28 -> 0 | G39: =$B28*G$25*G28 -> 0 | H39: =$B28*H$25*H28 -> 0 | I39: =$B28*I$25*I28 -> 0 | J39: =$B28*J$25*J28 -> 0 | K39: =$B28*K$25*K28 -> 0 | L39: =$B28*L$25*L28 -> 0
C40: 3 | D40: =$B29*D$25*D29 -> 0 | E40: =$B29*E$25*E29 -> 0 | F40: =$B29*F$25*F29 -> 0.00020661017 | G40: =$B29*G$25*G29 -> 2.7038822e-05 | H40: =$B29*H$25*H29 -> 0 | I40: =$B29*I$25*I29 -> 3.8794439e-06 | J40: =$B29*J$25*J29 -> 0 | K40: =$B29*K$25*K29 -> 0 | L40: =$B29*L$25*L29 -> -1.1798477e-05
C41: 4 | D41: =$B30*D$25*D30 -> 0 | E41: =$B30*E$25*E30 -> 0 | F41: =$B30*F$25*F30 -> 2.7038822e-05 | G41: =$B30*G$25*G30 -> 1.92122e-05 | H41: =$B30*H$25*H30 -> 0 | I41: =$B30*I$25*I30 -> 5.4611416e-07 | J41: =$B30*J$25*J30 -> 0 | K41: =$B30*K$25*K30 -> 0 | L41: =$B30*L$25*L30 -> 5.5529422e-06
C42: 5 | D42: =$B31*D$25*D31 -> 0 | E42: =$B31*E$25*E31 -> 0 | F42: =$B31*F$25*F31 -> 0 | G42: =$B31*G$25*G31 -> 0 | H42: =$B31*H$25*H31 -> 0 | I42: =$B31*I$25*I31 -> 0 | J42: =$B31*J$25*J31 -> 0 | K42: =$B31*K$25*K31 -> 0 | L42: =$B31*L$25*L31 -> 0
C43: 6 | D43: =$B32*D$25*D32 -> 0 | E43: =$B32*E$25*E32 -> 0 | F43: =$B32*F$25*F32 -> 3.8794439e-06 | G43: =$B32*G$25*G32 -> 5.4611416e-07 | H43: =$B32*H$25*H32 -> 0 | I43: =$B32*I$25*I32 -> 2.9026958e-07 | J43: =$B32*J$25*J32 -> 0 | K43: =$B32*K$25*K32 -> 0 | L43: =$B32*L$25*L32 -> 3.8993906e-06
C44: 7 | D44: =$B33*D$25*D33 -> 0 | E44: =$B33*E$25*E33 -> 0 | F44: =$B33*F$25*F33 -> 0 | G44: =$B33*G$25*G33 -> 0 | H44: =$B33*H$25*H33 -> 0 | I44: =$B33*I$25*I33 -> 0 | J44: =$B33*J$25*J33 -> 0 | K44: =$B33*K$25*K33 -> 0 | L44: =$B33*L$25*L33 -> 0
C45: 8 | D45: =$B34*D$25*D34 -> 0 | E45: =$B34*E$25*E34 -> 0 | F45: =$B34*F$25*F34 -> 0 | G45: =$B34*G$25*G34 -> 0 | H45: =$B34*H$25*H34 -> 0 | I45: =$B34*I$25*I34 -> 0 | J45: =$B34*J$25*J34 -> 0 | K45: =$B34*K$25*K34 -> 0 | L45: =$B34*L$25*L34 -> 0
C46: 9 | D46: =$B35*D$25*D35 -> 0 | E46: =$B35*E$25*E35 -> 0 | F46: =$B35*F$25*F35 -> -1.1798477e-05 | G46: =$B35*G$25*G35 -> 5.5529422e-06 | H46: =$B35*H$25*H35 -> 0 | I46: =$B35*I$25*I35 -> 3.8993906e-06 | J46: =$B35*J$25*J35 -> 0 | K46: =$B35*K$25*K35 -> 0 | L46: =$B35*L$25*L35 -> 0.00061565166
B48: Standard deviation of portfolio return | D48: =SQRT(SUM(D38:L46)) -> 0.030000013
...

Sheet 3. Maximise Sharpe
B1: PORTFOLIO OPTIMISATION MODELS
C3: INPUTS
C5: Stock | D5: 1 | E5: 2 | F5: 3 | G5: 4 | H5: 5 | I5: 6 | J5: 7 | K5: 8 | L5: 9
C6: Mean | D6: ='0. Data'!K56 -> 0.0019785721 | E6: ='0. Data'!L56 -> 0.0023362823 | F6: ='0. Data'!M56 -> 0.014068687 | G6: ='0. Data'!N56 -> 0.010566461 | H6: ='0. Data'!O56 -> 0.012509884 | I6: ='0. Data'!P56 -> 0.013562733 | J6: ='0. Data'!Q56 -> 0.013059285 | K6: ='0. Data'!R56 -> 0.013010327 | L6: ='0. Data'!S56 -> 0.017118669
C8: Cov | D8: 1 | E8: 2 | F8: 3 | G8: 4 | H8: 5 | I8: 6 | J8: 7 | K8: 8 | L8: 9
C9: 1 | D9: 0.0030746779 | E9: 0.0033155393 | F9: 0.00061220991 | G9: -0.00017213058 | H9: 0.0013224223 | I9: 0.001026195 | J9: 0.0015652824 | K9: 0.0014013364 | L9: 0.00012122474
C10: 2 | D10: 0.0033155393 | E10: 0.0046651225 | F10: 0.00070842477 | G10: 4.9754646e-05 | H10: 0.0017195254 | I10: 0.0012619543 | J10: 0.0017138759 | K10: 0.0017771976 | L10: -0.00025088371
C11: 3 | D11: 0.00061220991 | E11: 0.00070842477 | F11: 0.0024609128 | G11: 0.00085114121 | H11: 0.0012701524 | I11: 0.0011609457 | J11: 0.0020398319 | K11: 0.0017683433 | L11: -6.9123552e-05
C12: 4 | D12: -0.00017213058 | E12: 4.9754646e-05 | F12: 0.00085114121 | G12: 0.0015983073 | H12: 0.00073257556 | I12: 0.00043191191 | J12: 0.00080664985 | K12: 0.00089101512 | L12: 8.5979034e-05
C13: 5 | D13: 0.0013224223 | E13: 0.0017195254 | F13: 0.0012701524 | G13: 0.00073257556 | H13: 0.0031031979 | I13: 0.0020477872 | J13: 0.0028478908 | K13: 0.00241692 | L13: 0.0007454689
C14: 6 | D14: 0.001026195 | E14: 0.0012619543 | F14: 0.0011609457 | G14: 0.00043191191 | H14: 0.0020477872 | I14: 0.0021824376 | J14: 0.0023458031 | K14: 0.0018602274 | L14: 0.00057397731
C15: 7 | D15: 0.0015652824 | E15: 0.0017138759 | F15: 0.0020398319 | G15: 0.00080664985 | H15: 0.0028478908 | I15: 0.0023458031 | J15: 0.00367788 | K15: 0.0027340303 | L15: 0.00053933216
C16: 8 | D16: 0.0014013364 | E16: 0.0017771976 | F16: 0.0017683433 | G16: 0.00089101512 | H16: 0.00241692 | I16: 0.0018602274 | J16: 0.0027340303 | K16: 0.0028401712 | L16: 0.00040914466
C17: 9 | D17: 0.00012122474 | E17: -0.00025088371 | F17: -6.9123552e-05 | G17: 8.5979034e-05 | H17: 0.0007454689 | I17: 0.00057397731 | J17: 0.00053933216 | K17: 0.00040914466 | L17: 0.0017741515
B19: DECISION VARIABLES
D20: stock 1 | E20: stock 2 | F20: stock 3 | G20: stock 4 | H20: stock 5 | I20: stock 6 | J20: stock 7 | K20: stock 8 | L20: stock 9
C21: Investment weights | D21: 0 | E21: 0 | F21: 0 | G21: 0 | H21: 0 | I21: 0 | J21: 0 | K21: 0 | L21: 0.99999998
B23: CALCULATED VARIABLES
D25: =D21 -> 0 | E25: =E21 -> 0 | F25: =F21 -> 0 | G25: =G21 -> 0 | H25: =H21 -> 0 | I25: =I21 -> 0 | J25: =J21 -> 0 | K25: =K21 -> 0 | L25: =L21 -> 0.99999998
C26: Cov | D26: 1 | E26: 2 | F26: 3 | G26: 4 | H26: 5 | I26: 6 | J26: 7 | K26: 8 | L26: 9
B27: =D21 -> 0 | C27: 1 | D27: =D9 -> 0.0030746779 | E27: =E9 -> 0.0033155393 | F27: =F9 -> 0.00061220991 | G27: =G9 -> -0.00017213058 | H27: =H9 -> 0.0013224223 | I27: =I9 -> 0.001026195 | J27: =J9 -> 0.0015652824 | K27: =K9 -> 0.0014013364 | L27: =L9 -> 0.00012122474
B28: =E21 -> 0 | C28: 2 | D28: =D10 -> 0.0033155393 | E28: =E10 -> 0.0046651225 | F28: =F10 -> 0.00070842477 | G28: =G10 -> 4.9754646e-05 | H28: =H10 -> 0.0017195254 | I28: =I10 -> 0.0012619543 | J28: =J10 -> 0.0017138759 | K28: =K10 -> 0.0017771976 | L28: =L10 -> -0.00025088371
B29: =F21 -> 0 | C29: 3 | D29: =D11 -> 0.00061220991 | E29: =E11 -> 0.00070842477 | F29: =F11 -> 0.0024609128 | G29: =G11 -> 0.00085114121 | H29: =H11 -> 0.0012701524 | I29: =I11 -> 0.0011609457 | J29: =J11 -> 0.0020398319 | K29: =K11 -> 0.0017683433 | L29: =L11 -> -6.9123552e-05
B30: =G21 -> 0 | C30: 4 | D30: =D12 -> -0.00017213058 | E30: =E12 -> 4.9754646e-05 | F30: =F12 -> 0.00085114121 | G30: =G12 -> 0.0015983073 | H30: =H12 -> 0.00073257556 | I30: =I12 -> 0.00043191191 | J30: =J12 -> 0.00080664985 | K30: =K12 -> 0.00089101512 | L30: =L12 -> 8.5979034e-05
B31: =H21 -> 0 | C31: 5 | D31: =D13 -> 0.0013224223 | E31: =E13 -> 0.0017195254 | F31: =F13 -> 0.0012701524 | G31: =G13 -> 0.00073257556 | H31: =H13 -> 0.0031031979 | I31: =I13 -> 0.0020477872 | J31: =J13 -> 0.0028478908 | K31: =K13 -> 0.00241692 | L31: =L13 -> 0.0007454689
B32: =I21 -> 0 | C32: 6 | D32: =D14 -> 0.001026195 | E32: =E14 -> 0.0012619543 | F32: =F14 -> 0.0011609457 | G32: =G14 -> 0.00043191191 | H32: =H14 -> 0.0020477872 | I32: =I14 -> 0.0021824376 | J32: =J14 -> 0.0023458031 | K32: =K14 -> 0.0018602274 | L32: =L14 -> 0.00057397731
B33: =J21 -> 0 | C33: 7 | D33: =D15 -> 0.0015652824 | E33: =E15 -> 0.0017138759 | F33: =F15 -> 0.0020398319 | G33: =G15 -> 0.00080664985 | H33: =H15 -> 0.0028478908 | I33: =I15 -> 0.0023458031 | J33: =J15 -> 0.00367788 | K33: =K15 -> 0.0027340303 | L33: =L15 -> 0.00053933216
B34: =K21 -> 0 | C34: 8 | D34: =D16 -> 0.0014013364 | E34: =E16 -> 0.0017771976 | F34: =F16 -> 0.0017683433 | G34: =G16 -> 0.00089101512 | H34: =H16 -> 0.00241692 | I34: =I16 -> 0.0018602274 | J34: =J16 -> 0.0027340303 | K34: =K16 -> 0.0028401712 | L34: =L16 -> 0.00040914466
B35: =L21 -> 0.99999998 | C35: 9 | D35: =D17 -> 0.00012122474 | E35: =E17 -> -0.00025088371 | F35: =F17 -> -6.9123552e-05 | G35: =G17 -> 8.5979034e-05 | H35: =H17 -> 0.0007454689 | I35: =I17 -> 0.00057397731 | J35: =J17 -> 0.00053933216 | K35: =K17 -> 0.00040914466 | L35: =L17 -> 0.0017741515
C37: Portfolio variance terms | D37: 1 | E37: 2 | F37: 3 | G37: 4 | H37: 5 | I37: 6 | J37: 7 | K37: 8 | L37: 9
B38: Standard devioan of the portfolio | C38: 1 | D38: =$B27*D$25*D27 -> 0 | E38: =$B27*E$25*E27 -> 0 | F38: =$B27*F$25*F27 -> 0 | G38: =$B27*G$25*G27 -> 0 | H38: =$B27*H$25*H27 -> 0 | I38: =$B27*I$25*I27 -> 0 | J38: =$B27*J$25*J27 -> 0 | K38: =$B27*K$25*K27 -> 0 | L38: =$B27*L$25*L27 -> 0
C39: 2 | D39: =$B28*D$25*D28 -> 0 | E39: =$B28*E$25*E28 -> 0 | F39: =$B28*F$25*F28 -> 0 | G39: =$B28*G$25*G28 -> 0 | H39: =$B28*H$25*H28 -> 0 | I39: =$B28*I$25*I28 -> 0 | J39: =$B28*J$25*J28 -> 0 | K39: =$B28*K$25*K28 -> 0 | L39: =$B28*L$25*L28 -> 0
C40: 3 | D40: =$B29*D$25*D29 -> 0 | E40: =$B29*E$25*E29 -> 0 | F40: =$B29*F$25*F29 -> 0 | G40: =$B29*G$25*G29 -> 0 | H40: =$B29*H$25*H29 -> 0 | I40: =$B29*I$25*I29 -> 0 | J40: =$B29*J$25*J29 -> 0 | K40: =$B29*K$25*K29 -> 0 | L40: =$B29*L$25*L29 -> 0
C41: 4 | D41: =$B30*D$25*D30 -> 0 | E41: =$B30*E$25*E30 -> 0 | F41: =$B30*F$25*F30 -> 0 | G41: =$B30*G$25*G30 -> 0 | H41: =$B30*H$25*H30 -> 0 | I41: =$B30*I$25*I30 -> 0 | J41: =$B30*J$25*J30 -> 0 | K41: =$B30*K$25*K30 -> 0 | L41: =$B30*L$25*L30 -> 0
C42: 5 | D42: =$B31*D$25*D31 -> 0 | E42: =$B31*E$25*E31 -> 0 | F42: =$B31*F$25*F31 -> 0 | G42: =$B31*G$25*G31 -> 0 | H42: =$B31*H$25*H31 -> 0 | I42: =$B31*I$25*I31 -> 0 | J42: =$B31*J$25*J31 -> 0 | K42: =$B31*K$25*K31 -> 0 | L42: =$B31*L$25*L31 -> 0
C43: 6 | D43: =$B32*D$25*D32 -> 0 | E43: =$B32*E$25*E32 -> 0 | F43: =$B32*F$25*F32 -> 0 | G43: =$B32*G$25*G32 -> 0 | H43: =$B32*H$25*H32 -> 0 | I43: =$B32*I$25*I32 -> 0 | J43: =$B32*J$25*J32 -> 0 | K43: =$B32*K$25*K32 -> 0 | L43: =$B32*L$25*L32 -> 0
C44: 7 | D44: =$B33*D$25*D33 -> 0 | E44: =$B33*E$25*E33 -> 0 | F44: =$B33*F$25*F33 -> 0 | G44: =$B33*G$25*G33 -> 0 | H44: =$B33*H$25*H33 -> 0 | I44: =$B33*I$25*I33 -> 0 | J44: =$B33*J$25*J33 -> 0 | K44: =$B33*K$25*K33 -> 0 | L44: =$B33*L$25*L33 -> 0
C45: 8 | D45: =$B34*D$25*D34 -> 0 | E45: =$B34*E$25*E34 -> 0 | F45: =$B34*F$25*F34 -> 0 | G45: =$B34*G$25*G34 -> 0 | H45: =$B34*H$25*H34 -> 0 | I45: =$B34*I$25*I34 -> 0 | J45: =$B34*J$25*J34 -> 0 | K45: =$B34*K$25*K34 -> 0 | L45: =$B34*L$25*L34 -> 0
C46: 9 | D46: =$B35*D$25*D35 -> 0 | E46: =$B35*E$25*E35 -> 0 | F46: =$B35*F$25*F35 -> 0 | G46: =$B35*G$25*G35 -> 0 | H46: =$B35*H$25*H35 -> 0 | I46: =$B35*I$25*I35 -> 0 | J46: =$B35*J$25*J35 -> 0 | K46: =$B35*K$25*K35 -> 0 | L46: =$B35*L$25*L35 -> 0.0017741514
B48: Standard deviation of portfolio return | D48: =SQRT(SUM(D38:L46)) -> 0.042120677
...

Sheet Class Ex1.a Constant elasticity
B1: FINDING PARAMETERS IN A CONSTANT ELASTICITY DEMAND FUNCTION
B3: INPUT
C5: Price | D5: Demand
C6: 70 | D6: 400
C7: 80 | D7: 300 | J7: Price | K7: Demand
J8: 70 | K8: =$C$11*J8^$C$12 -> 399.99762
B9: DECISION VARIABLES | J9: 72 | K9: =$C$11*J9^$C$12 -> 376.44316
J10: 74 | K10: =$C$11*J10^$C$12 -> 354.86539
B11: a | C11: 3777017.5 | J11: 76 | K11: =$C$11*J11^$C$12 -> 335.05151
B12: b | C12: -2.1544067 | J12: 78 | K12: =$C$11*J12^$C$12 -> 316.81643
J13: 80 | K13: =$C$11*J13^$C$12 -> 299.99856
B14: CALCULATED VARIABLE | J14: 82 | K14: =$C$11*J14^$C$12 -> 284.45633
J15: 84 | K15: =$C$11*J15^$C$12 -> 270.06531
D16: Given Demand (X) | E16: Predicted demand (Y) | J16: 86 | K16: =$C$11*J16^$C$12 -> 256.71578
C17: Price | J17: 88 | K17: =$C$11*J17^$C$12 -> 244.3107
C18: =C6 -> 70 | D18: =D6 -> 400 | E18: =C$11*C18^C12 -> 399.99762 | J18: 90 | K18: =$C$11*J18^$C$12 -> 232.76401
C19: =C7 -> 80 | D19: =D7 -> 300 | E19: =C$11*C19^C$12 -> 299.99856
B21: OBJECTIVE FUNCTION
C23: Minimise the sum of squared differences | E23: =SUMXMY2(D18:D19,E18:E19) -> 7.7698098e-06

Sheet Class Ex1.b Pricing model
B1: PRICING MODELS
B3: INPUT
B5: Cost per unit | D5: 50
B6: Parameter values
C7: a | D7: ='Class Ex1.a Constant elasticity'!C11 -> 3777017.5
C8: b | D8: ='Class Ex1.a Constant elasticity'!C12 -> -2.1544067
B10: DECISION VARIABLE
C12: Price | D12: 93.31229
B14: OBJECTIVE FUNCTION
C16: Maximise profit | D16: =(D12-D5)*D7*D12^D8 -> 9326.3278
B18: CONSTRAINT
D19: LHS | F19: RHS
D20: =D16 -> 9326.3278 | E20: ≥ | F20: 0 | H20: (non-zero profit constraint)

Sheet Class Ex2. aModified Exp
B1: FINDING PARAMETERS VALUES IN A MODIFIED EXPONENTIAL RESPONSE FUNCTION
B3: INPUT
K4: Predicted
C5: # ads | D5: # exposures | J5: # ads | K5: # exposures
C6: 1 | D6: 4.7 | J6: 0 | K6: =$C$14*(1-EXP(-$C$15*J6)) -> 0
C7: 8 | D7: 22.1 | J7: 20 | K7: =$C$14*(1-EXP(-$C$15*J7)) -> 47.174356
C8: 20 | D8: 48.7 | J8: 40 | K8: =$C$14*(1-EXP(-$C$15*J8)) -> 79.992777
C9: 50 | D9: 90.3 | J9: 60 | K9: =$C$14*(1-EXP(-$C$15*J9)) -> 102.82401
C10: 100 | D10: 130.5 | J10: 80 | K10: =$C$14*(1-EXP(-$C$15*J10)) -> 118.70732
J11: 100 | K11: =$C$14*(1-EXP(-$C$15*J11)) -> 129.75708
B12: DECISION VARIABLES | J12: 120 | K12: =$C$14*(1-EXP(-$C$15*J12)) -> 137.44422
J13: 140 | K13: =$C$14*(1-EXP(-$C$15*J13)) -> 142.79203
B14: a | C14: 155.01741 | J14: 160 | K14: =$C$14*(1-EXP(-$C$15*J14)) -> 146.51242
B15: b | C15: 0.018143023 | J15: 180 | K15: =$C$14*(1-EXP(-$C$15*J15)) -> 149.10063
J16: 200 | K16: =$C$14*(1-EXP(-$C$15*J16)) -> 150.9012
B18: CALCULATED VARIABLE
C19: # ads | D19: # exposures | E19: Predicted # exposures
C21: =C6 -> 1 | D21: =D6 -> 4.7 | E21: =$C$14*(1-EXP(-$C$15*C21)) -> 2.7871246
C22: =C7 -> 8 | D22: =D7 -> 22.1 | E22: =$C$14*(1-EXP(-$C$15*C22)) -> 20.943227
C23: =C8 -> 20 | D23: =D8 -> 48.7 | E23: =$C$14*(1-EXP(-$C$15*C23)) -> 47.174356
C24: =C9 -> 50 | D24: =D9 -> 90.3 | E24: =$C$14*(1-EXP(-$C$15*C24)) -> 92.441131
C25: =C10 -> 100 | D25: =D10 -> 130.5 | E25: =$C$14*(1-EXP(-$C$15*C25)) -> 129.75708
B27: OBJECTIVE FUNCTION
B29: Minimise the sum of squared differences | D29: =SUMXMY2(D21:D25,E21:E25) -> 12.461176
B32: CONSTRAINTS
D33: LHS | F33: RHS
D34: =C14 -> 155.01741 | E34: ≥ | F34: 130 | H34: Lower bound on a
D35: =C14 -> 155.01741 | E35: ≤ | F35: 260 | H35: Upper bound on a
D36: =C15 -> 0.018143023 | E36: ≥ | F36: 0.001 | H36: Lower bound on b
D37: =C15 -> 0.018143023 | E37: ≤ | F37: 1 | H37: Upper bound on b

Sheet Class Ex 2.b Ad model
B1: ADVERTISING SELECTION WITH NONLINEAR CONSTRAINTS
B3: INPUTS
B4: Constant (a) in response function
B6: Segments | C6: A | D6: B | E6: C | G6: Min exposures
B7: Women 18-35 | C7: 105.803 | D7: 40.113 | E7: 66.998 | G7: 60
B8: Women 36-55 | C8: 71.784 | D8: 26.534 | E8: 46.146 | G8: 60
B9: Women >55 | C9: 56.828 | D9: 17.209 | E9: 8.887 | G9: 28
B11: Coefficient (b) of exponent in response function
B12: Segments | C12: A | D12: B | E12: C
B13: Women 18-35 | C13: 0.035 | D13: 0.063 | E13: 0.069
B14: Women 36-55 | C14: 0.089 | D14: 0.057 | E14: 0.061
B15: Women >55 | C15: 0.01 | D15: 0.033 | E15: 0.078
B17: Cost per ad | C17: 140 | D17: 100 | E17: 80
B19: DECISION VARIABLES
C20: A | D20: B | E20: C
B21: No. ads | C21: 28 | D21: 20 | E21: 14
B23: CALCULATED VARIABLES
B25: Exposures to each group from each show Yij
B26: Segments | C26: A | D26: B | E26: C
B27: Women 18-35 | C27: =C7*(1-EXP(-C13*C$21)) -> 66.09396 | D27: =D7*(1-EXP(-D13*D$21)) -> 28.734786 | E27: =E7*(1-EXP(-E13*E$21)) -> 41.4984
B28: Women 36-55 | C28: =C8*(1-EXP(-C14*C$21)) -> 65.844282 | D28: =D8*(1-EXP(-D14*D$21)) -> 18.047922 | E28: =E8*(1-EXP(-E14*E$21)) -> 26.501247
B29: Women >55 | C29: =C9*(1-EXP(-C15*C$21)) -> 13.878322 | D29: =D9*(1-EXP(-D15*D$21)) -> 8.3145054 | E29: =E9*(1-EXP(-E15*E$21)) -> 5.905014
B31: OBJECTIVE FUNCTION
B32: Total cost ($'000) | C32: =SUMPRODUCT(C17:E17,C21:E21) -> 7040
B34: CONSTRAINTS
B35: Segments | C35: LHS | E35: RHS
B36: Women 18-35 | C36: =SUM(C27:E27) -> 136.32715 | D36: ≥ | E36: =G7 -> 60
B37: Women 36-55 | C37: =SUM(C28:E28) -> 110.39345 | D37: ≥ | E37: =G8 -> 60
B38: Women >55 | C38: =SUM(C29:E29) -> 28.097841 | D38: ≥ | E38: =G9 -> 28

Sheet Class Ex3. Location model
B1: FACILITY LOCATION MODELS
B3: INPUTS
B5: Customer | C5: X-coordinate | D5: Y-coordinate | E5: Shipments per year | M5: x-coordinate | N5: y-coordinate
B6: 1 | C6: 5 | D6: 10 | E6: 200 | L6: Customer 1 | M6: =C6 -> 5 | N6: =D6 -> 10
B7: 2 | C7: 10 | D7: 5 | E7: 150 | L7: Customer 2 | M7: =C7 -> 10 | N7: =D7 -> 5
B8: 3 | C8: 0 | D8: 12 | E8: 200 | L8: Customer 3 | M8: =C8 -> 0 | N8: =D8 -> 12
B9: 4 | C9: 12 | D9: 0 | E9: 300 | L9: Customer 4 | M9: =C9 -> 12 | N9: =D9 -> 0
L10: Warehouse | M10: =C14 -> 9.3141669 | N10: =D14 -> 5.0287041
B11: DECISION VARIABLES
C13: X-coordinate | D13: Y-coordinate
B14: Warehouse | C14: 9.3141669 | D14: 5.0287041
B16: CALCULATED VARIABLES
B18: Customer | C18: Distance from warehouse
B19: 1 | C19: =SQRT(SUMXMY2(C6:D6,C$14:D$14)) -> 6.5822351
B20: 2 | C20: =SQRT(SUMXMY2(C7:D7,C$14:D$14)) -> 0.68643353
B21: 3 | C21: =SQRT(SUMXMY2(C8:D8,C$14:D$14)) -> 11.634117
B22: 4 | C22: =SQRT(SUMXMY2(C9:D9,C$14:D$14)) -> 5.7010144
B24: OBJECTIVE FUNCTION
B26: Annual distance | C26: =SUMPRODUCT(C19:C22,E6:E9) -> 5456.5397

Sheet Class Ex4.1 Portfolio model
B1: PORTFOLIO OPTIMISATION MODELS
B3: INPUTS
B5: Stock | C5: 1 | D5: 2 | E5: 3
B6: Mean | C6: 0.14 | D6: 0.11 | E6: 0.1
B8: Cov | C8: 1 | D8: 2 | E8: 3
B9: 1 | C9: 0.04 | D9: 0.018 | E9: 0.0064
B10: 2 | C10: 0.018 | D10: 0.0225 | E10: 0.0084
B11: 3 | C11: 0.0064 | D11: 0.0084 | E11: 0.0064
B13: DECISION VARIABLES
C14: stock 1 | D14: stock 2 | E14: stock 3
B15: Investment weights | C15: 0.49999999 | D15: 0 | E15: 0.50000001
B17: CALCULATED VARIABLES
D19: =C15 -> 0.49999999 | E19: =D15 -> 0 | F19: =E15 -> 0.50000001
C20: Cov | D20: 1 | E20: 2 | F20: 3
B21: =C15 -> 0.49999999 | C21: 1 | D21: 0.04 | E21: 0.018 | F21: 0.0064
B22: =D15 -> 0 | C22: 2 | D22: 0.018 | E22: 0.0225 | F22: 0.0084
B23: =E15 -> 0.50000001 | C23: 3 | D23: 0.0064 | E23: 0.0084 | F23: 0.0064
C25: Portfolio variance terms | D25: 1 | E25: 2 | F25: 3
C26: 1 | D26: =$B21*D$19*D21 -> 0.0099999995 | E26: =$B21*E$19*E21 -> 0 | F26: =$B21*F$19*F21 -> 0.0016
C27: 2 | D27: =$B22*D$19*D22 -> 0 | E27: =$B22*E$19*E22 -> 0 | F27: =$B22*F$19*F22 -> 0
C28: 3 | D28: =$B23*D$19*D23 -> 0.0016 | E28: =$B23*E$19*E23 -> 0 | F28: =$B23*F$19*F23 -> 0.0016000001
C30: Average portfolio return | D30: =SUMPRODUCT(C6:E6,C15:E15) -> 0.12
L31: Return | M31: Risk
L32: 10 | M32: 8
B33: OBJECTIVE FUNCTION | L33: 11 | M33: 9.22 | N33: =M33-M32 -> 1.22
B34: Standard deviation of portfolio return | D34: =SQRT(SUM(D26:F28)) -> 0.12165525 | L34: 12 | M34: 12.17 | N34: =M34-M33 -> 2.95
L35: 13 | M35: 15.91 | N35: =M35-M34 -> 3.74
L36: 14 | M36: 20 | N36: =M36-M35 -> 4.09
B37: CONSTRAINTS
B38: LHS | D38: RHS
B39: =D30 -> 0.12 | C39: ≥ | D39: 0.1 | E39: (Minimum expected return of 12%)
B41: =SUM(C15:E15) -> 1 | C41: = | D41: 1 | E41: (Portfolio = 100% of total investment)

Sheet Class Ex4.2 Portfolio model
B1: PORTFOLIO OPTIMISATION MODELS
B3: INPUTS
B5: Stock | C5: 1 | D5: 2 | E5: 3
B6: Mean | C6: 0.14 | D6: 0.11 | E6: 0.1
B8: Cov | C8: 1 | D8: 2 | E8: 3
B9: 1 | C9: 0.04 | D9: 0.018 | E9: 0.0064
B10: 2 | C10: 0.018 | D10: 0.0225 | E10: 0.0084
B11: 3 | C11: 0.0064 | D11: 0.0084 | E11: 0.0064
B13: DECISION VARIABLES
C14: stock 1 | D14: stock 2 | E14: stock 3
B15: Investment weights | C15: 0.3273281 | D15: 0 | E15: 0.6726719
B17: CALCULATED VARIABLES
D19: =C15 -> 0.3273281 | E19: =D15 -> 0 | F19: =E15 -> 0.6726719
C20: Cov | D20: 1 | E20: 2 | F20: 3
B21: =C15 -> 0.3273281 | C21: 1 | D21: 0.04 | E21: 0.018 | F21: 0.0064
B22: =D15 -> 0 | C22: 2 | D22: 0.018 | E22: 0.0225 | F22: 0.0084
B23: =E15 -> 0.6726719 | C23: 3 | D23: 0.0064 | E23: 0.0084 | F23: 0.0064
C25: Portfolio variance terms | D25: 1 | E25: 2 | F25: 3
C26: 1 | D26: =$B21*D$19*D21 -> 0.0042857473 | E26: =$B21*E$19*E21 -> 0 | F26: =$B21*F$19*F21 -> 0.0014091802
C27: 2 | D27: =$B22*D$19*D22 -> 0 | E27: =$B22*E$19*E22 -> 0 | F27: =$B22*F$19*F22 -> 0
C28: 3 | D28: =$B23*D$19*D23 -> 0.0014091802 | E28: =$B23*E$19*E23 -> 0 | F28: =$B23*F$19*F23 -> 0.0028959199
B30: OBJECTIVE FUNCTION
C31: Average portfolio return | D31: =SUMPRODUCT(C6:E6,C15:E15) -> 0.11309312
K32: Risk | L32: Return
K33: 9 | L33: 10.9
K34: 10 | L34: 11.31
B35: Standard deviation of portfolio return | D35: =SQRT(SUM(D26:F28)) -> 0.10000014 | K35: 11 | L35: 11.65
K36: 12 | L36: 11.95
K37: 13 | L37: 12.24
B38: CONSTRAINTS
B39: LHS | D39: RHS
B40: =D35 -> 0.10000014 | C40: <= | D40: 0.1 | E40: (Minimum expected return of 12%)
B42: =SUM(C15:E15) -> 1 | C42: = | D42: 1 | E42: (Portfolio = 100% of total investment)
