Workbook

Sheet 1.a Compute rate of return
B2: Using the closing stock prices of 49 monthly data calculate the monthly rate of returns for 48 months commencing from 1st of January 2021 to 1st of January 2025
B3: Table 1.a.1 | D3: Complete the following Table
B4: monthly return of 1.Pro Medicus Limited (ASX.PME) | F4: monthly retun of your chosen company in health care | J4: monthly return of Xero Limited (ASX:XRO) | N4: your chosen company in Technology | R4: monthly retun of Telstra Group Limited (ASX:TLS | V4: your chosen company in Communication | Z4: monthly return of Commonwealth Bank (ASX:CBA) | AD4: your chosen company in Financial services
B5: {=_xlfn.STOCKHISTORY("XASX:PME","01-01-2021","01-01-2025",2,1,0,1)} -> Date | C5: Close | D5: monthly rate of return | F5: {=_xlfn.STOCKHISTORY("xxx","01-01-2021","01-01-2025",2,1,0,1)} -> #VALUE! | N5: {=_xlfn.STOCKHISTORY("xxx","01-01-2021","01-01-2025",2,1,0,1)} -> #VALUE! | R5: {=_xlfn.STOCKHISTORY("xxx","01-01-2021","01-01-2025",2,1,0,1)} -> #VALUE! | V5: {=_xlfn.STOCKHISTORY("xxx","01-01-2021","01-01-2025",2,1,0,1)} -> #VALUE! | Z5: {=_xlfn.STOCKHISTORY("xxx","01-01-2021","01-01-2025",2,1,0,1)} -> #VALUE! | AD5: {=_xlfn.STOCKHISTORY("xxx","01-01-2021","01-01-2025",B5:D5,1,0,1)} -> #VALUE! | AE5: #VALUE! | AF5: #VALUE! | AI5: STOCKHISTORY("XASX:PME","01-01-2021","01-01-2025",2,1,0,1) | AK5: Symbol | AL5: Company | AM5: Category | AN5: Category code | AO5: Category code for chosen assests
A6: 0 | B6: 44197 | C6: 42.84 | AK6: (ASX:PME) | AL6: Pro Medicus Limited | AM6: Healthcare | AN6: S1 | AO6: S11
A7: 1 | B7: 44228 | C7: 44.35 | D7: =(C7-C6)/C6 -> 0.035247432 | AI7: TFC-symbal of the company- get it from Yahoo finance while looking for th category | AL7: Your choice of investments | AO7: S12
A8: 2 | B8: 44256 | C8: 41.33 | D8: =(C8-C7)/C7 -> -0.068094701 | AI8: 01-01-2021-starting month -given in UA format (MM/DD/YYYY) | AK8: (ASX:XRO) | AL8: Xero Limited | AM8: Technology | AN8: S2 | AO8: S21
A9: 3 | B9: 44287 | C9: 47.21 | D9: =(C9-C8)/C8 -> 0.14226954 | AI9: 01-01-2025 -ending date -(MM-DD-YYYY) 49 months | AL9: Your choice of investments | AO9: S22
A10: 4 | B10: 44317 | C10: 46.11 | D10: =(C10-C9)/C9 -> -0.023300148 | AI10: 2 -frequency for monthly data (interval:0 daily, 1 weekly, 2 monthly) | AK10: (ASX:TLS) | AL10: Telstra Group Limited | AM10: Communication services | AN10: S3 | AO10: S31
A11: 5 | B11: 44348 | C11: 58.72 | D11: =(C11-C10)/C10 -> 0.27347647 | AI11: 1 -show the header | AL11: Your choice of investments | AO11: S32
A12: 6 | B12: 44378 | C12: 57.98 | D12: =(C12-C11)/C11 -> -0.01260218 | AI12: 0-date | AK12: (ASX:CBA) | AL12: Commonwealth Bank | AM12: Financial Services | AN12: S4 | AO12: S41
A13: 7 | B13: 44409 | C13: 63.07 | D13: =(C13-C12)/C12 -> 0.087788893 | AI13: 1-closing price | AL13: Your choice of investments | AO13: S42
A14: 8 | B14: 44440 | C14: 54.61 | D14: =(C14-C13)/C13 -> -0.13413667
A15: 9 | B15: 44470 | C15: 53.28 | D15: =(C15-C14)/C14 -> -0.024354514 | AI15: Calculate the monthly rate of return shown in D column
A16: 10 | B16: 44501 | C16: 62.48 | D16: =(C16-C15)/C15 -> 0.17267267
A17: 11 | B17: 44531 | C17: 62.44 | D17: =(C17-C16)/C16 -> -0.00064020487 | AI17: column F,J,N…... should be completed by students
A18: 12 | B18: 44562 | C18: 45.1 | D18: =(C18-C17)/C17 -> -0.2777066
A19: 13 | B19: 44593 | C19: 46.73 | D19: =(C19-C18)/C18 -> 0.036141907
A20: 14 | B20: 44621 | C20: 48.99 | D20: =(C20-C19)/C19 -> 0.048362936
A21: 15 | B21: 44652 | C21: 47.48 | D21: =(C21-C20)/C20 -> -0.030822617
A22: 16 | B22: 44682 | C22: 42.13 | D22: =(C22-C21)/C21 -> -0.11267902
A23: 17 | B23: 44713 | C23: 42.25 | D23: =(C23-C22)/C22 -> 0.0028483266
A24: 18 | B24: 44743 | C24: 49.54 | D24: =(C24-C23)/C23 -> 0.17254438
A25: 19 | B25: 44774 | C25: 54.48 | D25: =(C25-C24)/C24 -> 0.0997174
A26: 20 | B26: 44805 | C26: 50.19 | D26: =(C26-C25)/C25 -> -0.078744493
A27: 21 | B27: 44835 | C27: 55.82 | D27: =(C27-C26)/C26 -> 0.11217374
A28: 22 | B28: 44866 | C28: 59.44 | D28: =(C28-C27)/C27 -> 0.064851308
A29: 23 | B29: 44896 | C29: 55.26 | D29: =(C29-C28)/C28 -> -0.070323015
... A54: 48 | B54: 45658 | C54: 278.4 | D54: =(C54-C53)/C53 -> 0.11306573
D55: =AVERAGE(D7:D54) -> 0.045530186 | L55: =AVERAGE(L7:L54) -> #DIV/0!

Sheet 1.b Sample  (Return and Risk)
C2: Table 1.b.1 | Q2: Complete all three tables
B3: monthly rate of return | C3: S11 | D3: S12 | E3: S21 | F3: S22 | G3: S31 | H3: S32 | I3: S41 | J3: S42
C4: 1 | D4: 2 | E4: 3 | F4: 4 | G4: 5 | H4: 6 | I4: 7 | J4: 8 | Q4: Table 1.b.2
B5: Date | C5: Monthly rate of return of Pro Medicus Limited | D5: ? | E5: Monthly rate of return of Xero Limited | F5: ? | G5: Monthly rate of return of Telstra Group Limited | H5: ? | I5: Monthly rate of return of Commonwealth Bank | P5: Symbol | Q5: Company | R5: Category | S5: Category code | T5: Category sub code for chosen assests | U5: Average 4 year return | V5: Stnd Deviation of 4 years | W5: Risk Category (R1 / R2 /R3)
B6: Code | C6: (ASX.PME) | E6: (ASX:XRO) | G6: (ASX:TLS) | I6: (ASX:CBA) | P6: (ASX:PME) | Q6: Pro Medicus Limited | R6: Healthcare | S6: S1 | T6: S11 | W6: ?? R#
A7: 0 | B7: 44197 | Q7: Your choice of investments | T7: S12 | W7: ?? R#
A8: 1 | B8: 44228 | C8: ='1.a Compute rate of return'!D7 -> 0.035247432 | P8: (ASX:XRO) | Q8: Xero Limited | R8: Technology | S8: S2 | T8: S21 | W8: ?? R#
A9: 2 | B9: 44256 | C9: ='1.a Compute rate of return'!D8 -> -0.068094701 | Q9: Your choice of investments | T9: S22 | W9: ?? R#
A10: 3 | B10: 44287 | C10: ='1.a Compute rate of return'!D9 -> 0.14226954 | P10: (ASX:TLS) | Q10: Telstra Group Limited | R10: Communication services | S10: S3 | T10: S31 | W10: ?? R#
A11: 4 | B11: 44317 | C11: ='1.a Compute rate of return'!D10 -> -0.023300148 | Q11: Your choice of investments | T11: S32 | W11: ?? R#
A12: 5 | B12: 44348 | C12: ='1.a Compute rate of return'!D11 -> 0.27347647 | P12: (ASX:CBA) | Q12: Commonwealth Bank | R12: Financial Services | S12: S4 | T12: S41 | W12: ?? R#
A13: 6 | B13: 44378 | C13: ='1.a Compute rate of return'!D12 -> -0.01260218 | Q13: Your choice of investments | T13: S42 | W13: ?? R#
A14: 7 | B14: 44409 | C14: ='1.a Compute rate of return'!D13 -> 0.087788893
A15: 8 | B15: 44440 | C15: ='1.a Compute rate of return'!D14 -> -0.13413667
A16: 9 | B16: 44470 | C16: ='1.a Compute rate of return'!D15 -> -0.024354514 | Q16: Table 1.b.3
A17: 10 | B17: 44501 | C17: ='1.a Compute rate of return'!D16 -> 0.17267267 | Q17: Health Care S1 | S17: Technology S2 | U17: Communi. Services S3 | W17: Financial. Ser S4
A18: 11 | B18: 44531 | C18: ='1.a Compute rate of return'!D17 -> -0.00064020487 | Q18: S11 | R18: S12 | S18: S21 | T18: S22 | U18: S31 | V18: S32 | W18: S41 | X18: S42 | Y18: Total
A19: 12 | B19: 44562 | C19: ='1.a Compute rate of return'!D18 -> -0.2777066 | P19: R1 | Y19: at least two investments
A20: 13 | B20: 44593 | C20: ='1.a Compute rate of return'!D19 -> 0.036141907 | P20: R2 | Y20: at least two investments
A21: 14 | B21: 44621 | C21: ='1.a Compute rate of return'!D20 -> 0.048362936 | P21: R3 | Y21: at least two investments
A22: 15 | B22: 44652 | C22: ='1.a Compute rate of return'!D21 -> -0.030822617
A23: 16 | B23: 44682 | C23: ='1.a Compute rate of return'!D22 -> -0.11267902
A24: 17 | B24: 44713 | C24: ='1.a Compute rate of return'!D23 -> 0.0028483266
A25: 18 | B25: 44743 | C25: ='1.a Compute rate of return'!D24 -> 0.17254438
A26: 19 | B26: 44774 | C26: ='1.a Compute rate of return'!D25 -> 0.0997174
A27: 20 | B27: 44805 | C27: ='1.a Compute rate of return'!D26 -> -0.078744493
A28: 21 | B28: 44835 | C28: ='1.a Compute rate of return'!D27 -> 0.11217374
A29: 22 | B29: 44866 | C29: ='1.a Compute rate of return'!D28 -> 0.064851308
A30: 23 | B30: 44896 | C30: ='1.a Compute rate of return'!D29 -> -0.070323015
A31: 24 | B31: 44927 | C31: ='1.a Compute rate of return'!D30 -> 0.20973579
A32: 25 | B32: 44958 | C32: ='1.a Compute rate of return'!D31 -> -0.087359761
A33: 26 | B33: 44986 | C33: ='1.a Compute rate of return'!D32 -> 0.046877561
... A55: 48 | B55: 45658 | C55: ='1.a Compute rate of return'!D54 -> 0.11306573
B56: Ave. Annual Return Rate (48 mths) | C56: =AVERAGE(C8:C55) -> 0.045530186 | E56: =AVERAGE(E8:E55) -> #DIV/0!
B57: std deviation | C57: =_xlfn.STDEV.S(C8:C55) -> 0.10936386 | E57: =_xlfn.STDEV.S(E8:E55) -> #DIV/0!
C58: C1 | D58: C1 | E58: C2 | F58: C2 | G58: C3 | H58: C3 | I58: C4 | J58: C4
C59: ?? R# | D59: ?? R# | E59: ?? R# | F59: ?? R# | G59: ?? R# | H59: ?? R# | I59: ?? R# | J59: ?? R#
C61: min | D61: max
E62: <= | F62: R1
E63: <= | F63: R2
...

Sheet 2.a. LP Modelling 
C1: LP model | D1: LP model
C3: DECISION VARIABLES
C4: Risk | D4: ?? R# | E4: ?? R# | F4: ?? R# | G4: ?? R# | H4: ?? R# | I4: ?? R# | J4: ?? R# | K4: ?? R#
C5: Sector | D5: S11 | E5: S12 | F5: S21 | G5: S22 | H5: S31 | I5: S32 | J5: S41 | K5: S42
C9: OBJECTIVE FUNCTION | D9: ?? R# | E9: ?? R# | F9: ?? R# | G9: ?? R# | H9: ?? R# | I9: ?? R# | J9: ?? R# | K9: ?? R#
D10: S11 | E10: S12 | F10: S21 | G10: S22 | H10: S31 | I10: S32 | J10: S41 | K10: S42
C15: CONSTRAINTS
D16: ?? R# | E16: ?? R# | F16: ?? R# | G16: ?? R# | H16: ?? R# | I16: ?? R# | J16: ?? R# | K16: ?? R# | M16: choose correct symbol
C17: write here the condition or constraint requirments in word | D17: S11 | E17: S12 | F17: S21 | G17: S22 | H17: S31 | I17: S32 | J17: S41 | K17: S42 | M17: Function
B18: 1 | C18: high-risk assets shouldn’t exceed 15% of the portfolio; | M18: >= , =, <=
B19: 2 | M19: >= , =, <=
B20: 3 | M20: >= , =, <=
B21: .
B22: .
B23: .
B24: .

Sheet 2.b LP Sensitivity Report 1

Sheet 3.a ILP modelling
A1: ILP model
A3: DECISION VARIABLES
A4: Risk | B4: ?? R# | C4: ?? R# | D4: ?? R# | E4: ?? R# | F4: ?? R# | G4: ?? R# | H4: ?? R# | I4: ?? R#
A5: Sector | B5: S11 | C5: S12 | D5: S21 | E5: S22 | F5: S31 | G5: S32 | H5: S41 | I5: S42
A8: OBJECTIVE FUNCTION | B8: ?? R# | C8: ?? R# | D8: ?? R# | E8: ?? R# | F8: ?? R# | G8: ?? R# | H8: ?? R# | I8: ?? R#
B9: S11 | C9: S12 | D9: S21 | E9: S22 | F9: S31 | G9: S32 | H9: S41 | I9: S42
A14: CONSTRAINTS
B15: ?? R# | C15: ?? R# | D15: ?? R# | E15: ?? R# | F15: ?? R# | G15: ?? R# | H15: ?? R# | I15: ?? R# | K15: choose correct symbol
A16: write here the condition or constraint requirments in word | B16: S11 | C16: S12 | D16: S21 | E16: S22 | F16: S31 | G16: S32 | H16: S41 | I16: S42 | K16: Function
A17: high-risk assets shouldn’t exceed 15% of the portfolio; | K17: >= , =, <=
K18: >= , =, <=
K19: >= , =, <=

Sheet Summary Sheet
D2: LP Model summary sheet
C3: Symbol | D3: Company | E3: Sector code | F3: sub sector code for chosen assests | G3: Average 4 year return | H3: Stnd Deviation | I3: Risk Category (R1 / R2 /R3) | J3: Proportion of investment
C4: (ASX:PME) | D4: Pro Medicus Limited | E4: S1 | F4: S11
D5: Your choice of investments | F5: S12
C6: (ASX:XRO) | D6: Xero Limited | E6: S2 | F6: S21
D7: Your choice of investments | F7: S22
C8: (ASX:TLS) | D8: Telstra Group Limited | E8: S3 | F8: S31
D9: Your choice of investments | F9: S32
C10: (ASX:CBA) | D10: Commonwealth Bank | E10: S4 | F10: S41
D11: Your choice of investments | F11: S42
D13: optimal Value
D17: ILP Model summary sheet
C18: Symbol | D18: Company | E18: Sector code | F18: sub sector code for chosen assests | G18: Average 4 year return | H18: Stnd Deviation | I18: Risk Category (R1 / R2 /R3) | J18: investment
C19: (ASX:PME) | D19: Pro Medicus Limited | E19: S1 | F19: S11
D20: Your choice of investments | F20: S12
C21: (ASX:XRO) | D21: Xero Limited | E21: S2 | F21: S21
D22: Your choice of investments | F22: S22
C23: (ASX:TLS) | D23: Telstra Group Limited | E23: S3 | F23: S31
D24: Your choice of investments | F24: S32
C25: (ASX:CBA) | D25: Commonwealth Bank | E25: S4 | F25: S41
D26: Your choice of investments | F26: S42
D28: optimal Value
